Workbook

Sheet Payslip
A1: PAYROLL SLIP | D1: PAYROLL SLIP
A2: =Kent!A24 -> Name: | B2: =Kent!B24 -> Kent | D2: ='Jay Anne'!A24 -> Name: | E2: ='Jay Anne'!B24 -> Jay Anne
A3: =Kent!A25 -> Job Title: | B3: =Kent!B25 -> Cook | D3: ='Jay Anne'!A25 -> Job Title: | E3: ='Jay Anne'!B25 -> Cashier
A4: =Kent!A26 -> Payment Date: | B4: =Kent!B26 -> 46139 | D4: ='Jay Anne'!A26 -> Payment Date: | E4: ='Jay Anne'!B26 -> 46139
A5: =Kent!A27 -> Cut Off Period: | B5: =Kent!B27 -> Apr-20 to Apr-26, 2026 | D5: ='Jay Anne'!A27 -> Cut Off Period: | E5: ='Jay Anne'!B27 -> Apr-20 to Apr-26, 2026
A6: =Kent!A28 -> Days Worked | B6: =Kent!B28 -> 2 | D6: ='Jay Anne'!A28 -> Days Worked | E6: ='Jay Anne'!B28 -> 3
A7: =Kent!A29 -> Adjustments | D7: ='Jay Anne'!A29 -> Adjustments
A8: =Kent!A30 -> Basic Pay | B8: =Kent!B30 -> 579.52 | D8: ='Jay Anne'!A30 -> Basic Pay | E8: ='Jay Anne'!B30 -> 899.91
A9: =Kent!A31 -> Bonus/Incentives | B9: =Kent!B31 -> 0 | D9: ='Jay Anne'!A31 -> Bonus/Incentives | E9: ='Jay Anne'!B31 -> 0
A10: =Kent!A32 -> Overtime Pay | B10: =Kent!B32 -> 304.248 | D10: ='Jay Anne'!A32 -> Overtime Pay | E10: ='Jay Anne'!B32 -> 239.976
A11: =Kent!A33 -> Other Income | B11: =Kent!B33 -> 0 | D11: ='Jay Anne'!A33 -> Other Income | E11: ='Jay Anne'!B33 -> 0
A14: =Kent!A36 -> Gross Pay | B14: =Kent!B36 -> 883.768 | D14: ='Jay Anne'!A36 -> Gross Pay | E14: ='Jay Anne'!B36 -> 1139.886
A15: =Kent!A37 -> Deductions | B15: =Kent!B37 -> 0 | D15: ='Jay Anne'!A37 -> Deductions | E15: ='Jay Anne'!B37 -> 0
A16: =Kent!A38 -> WH Tax | B16: =Kent!B38 -> 0 | D16: ='Jay Anne'!A38 -> WH Tax | E16: ='Jay Anne'!B38 -> 0
A18: =Kent!A40 -> Net Pay | B18: =Kent!B40 -> 883.768 | D18: ='Jay Anne'!A40 -> Net Pay | E18: ='Jay Anne'!B40 -> 1139.886
A21: PAYROLL SLIP | D21: PAYROLL SLIP
A22: =Kris!A24 -> Name: | B22: =Kris!B24 -> Kris Naynayan | D22: =Pepito!A24 -> Name: | E22: =Pepito!B24 -> Pepito
A23: =Kris!A25 -> Job Title: | B23: =Kris!B25 -> Staff | D23: =Pepito!A25 -> Job Title: | E23: =Pepito!B25 -> Staff
A24: =Kris!A26 -> Payment Date: | B24: =Kris!B26 -> 46139 | D24: =Pepito!A26 -> Payment Date: | E24: =Pepito!B26 -> 46139
A25: =Kris!A27 -> Cut Off Period: | B25: =Kris!B27 -> Apr-20 to Apr-26, 2026 | D25: =Pepito!A27 -> Cut Off Period: | E25: =Pepito!B27 -> Apr-20 to Apr-26, 2026
A26: =Kris!A28 -> Days Worked | B26: =Kris!B28 -> 4 | D26: =Pepito!A28 -> Days Worked | E26: =Pepito!B28 -> 5
A27: =Kris!A29 -> Adjustments | D27: =Pepito!A29 -> Adjustments
A28: =Kris!A30 -> Basic Pay | B28: =Kris!B30 -> 1104.582 | D28: =Pepito!A30 -> Basic Pay | E28: =Pepito!B30 -> 1249.72
A29: =Kris!A31 -> Bonus/Incentives | B29: =Kris!B31 -> 0 | D29: =Pepito!A31 -> Bonus/Incentives | E29: =Pepito!B31 -> 0
A30: =Kris!A32 -> Overtime Pay | B30: =Kris!B32 -> 130.752 | D30: =Pepito!A32 -> Overtime Pay | E30: =Pepito!B32 -> 512.388
A31: =Kris!A33 -> Other Income | B31: =Kris!B33 -> 0 | D31: =Pepito!A33 -> Other Income | E31: =Pepito!B33 -> 0
A34: =Kris!A36 -> Gross Pay | B34: =Kris!B36 -> 1235.334 | D34: =Pepito!A36 -> Gross Pay | E34: =Pepito!B36 -> 1762.108
A35: =Kris!A37 -> Deductions | B35: =Kris!B37 -> 0 | D35: =Pepito!A37 -> Deductions | E35: =Pepito!B37 -> 0
A36: =Kris!A38 -> WH Tax | B36: =Kris!B38 -> 0 | D36: =Pepito!A38 -> WH Tax | E36: =Pepito!B38 -> 0
A38: =Kris!A40 -> Net Pay | B38: =Kris!B40 -> 1235.334 | D38: =Pepito!A40 -> Net Pay | E38: =Pepito!B40 -> 1762.108
A42: PAYROLL SLIP | D42: PAYROLL SLIP
A43: =Cherry!A24 -> Name: | B43: =Cherry!B24 -> Cherry | D43: =Kim!A24 -> Name: | E43: =Kim!B24 -> Kim
A44: =Cherry!A25 -> Job Title: | B44: =Cherry!B25 -> Staff | D44: =Kim!A25 -> Job Title: | E44: =Kim!B25 -> Staff
A45: =Cherry!A26 -> Payment Date: | B45: =Cherry!B26 -> 46139 | D45: =Kim!A26 -> Payment Date: | E45: =Kim!B26 -> 46125
A46: =Cherry!A27 -> Cut Off Period: | B46: =Cherry!B27 -> Apr-20 to Apr-26, 2026 | D46: =Kim!A27 -> Cut Off Period: | E46: =Kim!B27 -> Apr-20 to Apr-26, 2026
A47: =Cherry!A28 -> Days Worked | B47: =Cherry!B28 -> 6 | D47: =Kim!A28 -> Days Worked | E47: =Kim!B28 -> 0
A48: =Cherry!A29 -> Adjustments | D48: =Kim!A29 -> Adjustments
A49: =Cherry!A30 -> Basic Pay | B49: =Cherry!B30 -> 2019 | D49: =Kim!A30 -> Basic Pay | E49: =Kim!B30 -> 0
A50: =Cherry!A31 -> Bonus/Incentives | B50: =Cherry!B31 -> 0 | D50: =Kim!A31 -> Bonus/Incentives | E50: =Kim!B31 -> 0
A51: =Cherry!A32 -> Overtime Pay | B51: =Cherry!B32 -> 1172.136 | D51: =Kim!A32 -> Overtime Pay | E51: =Kim!B32 -> 0
...

Sheet Summary
A1: micky harabi | B1: Not Set1 | C1: 2026-04-22 | D1: 08:41 | E1: 18:18 | F1: Missed | G1: Missed
A2: micky harabi | B2: Not Set1 | C2: 2026-04-23 | D2: 08:20 | E2: 18:07 | F2: Missed | G2: Missed
A3: micky harabi | B3: Not Set1 | C3: 2026-04-24 | D3: 08:58 | E3: 21:40 | F3: Missed | G3: Missed
A4: micky harabi | B4: Not Set1 | C4: 2026-04-25 | D4: 08:54 | E4: 22:03 | F4: Missed | G4: Missed
A5: micky harabi | B5: Not Set1 | C5: 2026-04-26 | D5: Missed | E5: 21:51 | F5: Missed | G5: Missed
A6: kent | B6: Not Set1 | C6: 2026-04-20 | D6: Missed | E6: Missed | F6: Missed | G6: Missed
A7: kent | B7: Not Set1 | C7: 2026-04-21 | D7: Missed | E7: Missed | F7: Missed | G7: Missed
A8: kent | B8: Not Set1 | C8: 2026-04-22 | D8: Missed | E8: Missed | F8: Missed | G8: Missed
A9: kent | B9: Not Set1 | C9: 2026-04-23 | D9: Missed | E9: Missed | F9: Missed | G9: Missed
A10: kent | B10: Not Set1 | C10: 2026-04-24 | D10: Missed | E10: Missed | F10: Missed | G10: Missed
A11: kent | B11: Not Set1 | C11: 2026-04-25 | D11: 08:55 | E11: 21:30 | F11: Missed | G11: Missed
A12: kent | B12: Not Set1 | C12: 2026-04-26 | D12: 08:12 | E12: 21:39 | F12: Missed | G12: Missed
... A61: mark agire | B61: Not Set1 | C61: 2026-04-26 | D61: 09:58 | E61: 21:51 | F61: Missed | G61: Missed

Sheet Micky
A1: Employee | B1: Shift | C1: Date | D1: Time In | E1: Time Out | F1: Hourly Rate | G1: Total Hours | H1: Regular Hours | I1: Overtime Hours | J1: Regular Pay | K1: Overtime Pay | L1: Total Pay
A2: Micky | B2: 10:00AM-9:00PM | C2: 2026-04-20 | D2: 08:30 | E2: 21:00 | F2: 22.22 | G2: =(E2-D2)*24 -> 12.5 | H2: =MIN(G2,9) -> 9 | I2: =IF(MAX(G2-9,0) - 1 < 0, 0, MAX(G2-9,0) - 1) -> 2.5 | J2: =H2*F2 -> 199.98 | K2: =I2*F2*1.2 -> 66.66 | L2: =J2+K2 -> 266.64
A3: Micky | B3: 10:00AM-9:00PM | C3: 2026-04-21 | D3: 08:30 | E3: 21:30 | F3: 22.22 | G3: =(E3-D3)*24 -> 13 | H3: =MIN(G3,9) -> 9 | I3: =IF(MAX(G3-9,0) - 1 < 0, 0, MAX(G3-9,0) - 1) -> 3 | J3: =H3*F3 -> 199.98 | K3: =I3*F3*1.2 -> 79.992 | L3: =J3+K3 -> 279.972
A4: Micky | B4: 10:00AM-9:00PM | C4: 2026-04-22 | D4: 08:30 | E4: 18:00 | F4: 22.22 | G4: =(E4-D4)*24 -> 9.5 | H4: =MIN(G4,9) -> 9 | I4: =IF(MAX(G4-9,0) - 1 < 0, 0, MAX(G4-9,0) - 1) -> 0 | J4: =H4*F4 -> 199.98 | K4: =I4*F4*1.2 -> 0 | L4: =J4+K4 -> 199.98
A5: Micky | B5: 10:00AM-9:00PM | C5: 2026-04-23 | D5: 08:30 | E5: 18:00 | F5: 22.22 | G5: =(E5-D5)*24 -> 9.5 | H5: =MIN(G5,9) -> 9 | I5: =IF(MAX(G5-9,0) - 1 < 0, 0, MAX(G5-9,0) - 1) -> 0 | J5: =H5*F5 -> 199.98 | K5: =I5*F5*1.2 -> 0 | L5: =J5+K5 -> 199.98
A6: Micky | B6: 10:00AM-9:00PM | C6: 2026-04-24 | D6: 09:00 | E6: 21:30 | F6: 22.22 | G6: =(E6-D6)*24 -> 12.5 | H6: =MIN(G6,9) -> 9 | I6: =IF(MAX(G6-9,0) - 1 < 0, 0, MAX(G6-9,0) - 1) -> 2.5 | J6: =H6*F6 -> 199.98 | K6: =I6*F6*1.2 -> 66.66 | L6: =J6+K6 -> 266.64
A7: Micky | B7: 10:00AM-9:00PM | C7: 2026-04-25 | D7: 09:00 | E7: 21:00 | F7: 25 | G7: =(E7-D7)*24 -> 12 | H7: =MIN(G7,8) -> 8 | I7: =IF(MAX(G7-8,0) - 1 < 0, 0, MAX(G7-8,0) - 1) -> 3 | J7: =H7*F7 -> 200 | K7: =I7*F7*1.2 -> 90 | L7: =J7+K7 -> 290
A8: Micky | B8: 10:00AM-9:00PM | C8: 2026-04-26 | D8: 09:00 | E8: 21:30 | F8: 25 | G8: =(E8-D8)*24 -> 12.5 | H8: =MIN(G8,8) -> 8 | I8: =IF(MAX(G8-8,0) - 1 < 0, 0, MAX(G8-8,0) - 1) -> 3.5 | J8: =H8*F8 -> 200 | K8: =I8*F8*1.2 -> 105 | L8: =J8+K8 -> 305
A14: SUMMARY | B14: REGULAR PAY | C14: OVER TIME PAY | D14: TOTAL PAY
A15: Micky | B15: =SUM(J2:J13) -> 1399.9 | C15: =SUM(K2:K13) -> 408.312 | D15: =SUM(L2:L13) -> 1808.212
A23: PAYROLL SLIP
A24: Name: | B24: =A2 -> Micky
A25: Job Title: | B25: Cashier
A26: Payment Date: | B26: =C8+1 -> 46139
A27: Cut Off Period: | B27: =Kent!B27 -> Apr-20 to Apr-26, 2026
A28: Days Worked | B28: =COUNTIF(D2:D8, "*:*") -> 7
A29: Adjustments
A30: Basic Pay | B30: =B15 -> 1399.9
A31: Bonus/Incentives | B31: 0
A32: Overtime Pay | B32: =C15 -> 408.312
A33: Other Income | B33: 0
A36: Gross Pay | B36: =D15 -> 1808.212
A37: Deductions | B37: 0
A38: WH Tax | B38: 0
A40: Net Pay | B40: =SUM(B36:B38) -> 1808.212

Sheet Kent
A1: Employee | B1: Shift | C1: Date | D1: Time In | E1: Time Out | F1: Hourly Rate | G1: Total Hours | H1: Regular Hours | I1: Overtime Hours | J1: Regular Pay | K1: Overtime Pay | L1: Total Pay
A2: Kent | B2: 8:30AM-9:00PM | C2: 2026-04-20 | D2: 0 | E2: 0 | F2: 36.22 | G2: =(E2-D2)*24 -> 0 | H2: =MIN(G2,9) -> 0 | I2: =IF(MAX(G2-9,0) - 1 < 0, 0, MAX(G2-9,0) - 1) -> 0 | J2: =H2*F2 -> 0 | K2: =I2*F2*1.2 -> 0 | L2: =J2+K2 -> 0
A3: Kent | B3: 8:30AM-9:00PM | C3: 2026-04-21 | D3: 0 | E3: 0 | F3: 36.22 | G3: =(E3-D3)*24 -> 0 | H3: =MIN(G3,9) -> 0 | I3: =IF(MAX(G3-9,0) - 1 < 0, 0, MAX(G3-9,0) - 1) -> 0 | J3: =H3*F3 -> 0 | K3: =I3*F3*1.2 -> 0 | L3: =J3+K3 -> 0
A4: Kent | B4: 8:30AM-9:00PM | C4: 2026-04-22 | D4: 0 | E4: 0 | F4: 36.22 | G4: =(E4-D4)*24 -> 0 | H4: =MIN(G4,9) -> 0 | I4: =IF(MAX(G4-9,0) - 1 < 0, 0, MAX(G4-9,0) - 1) -> 0 | J4: =H4*F4 -> 0 | K4: =I4*F4*1.2 -> 0 | L4: =J4+K4 -> 0
A5: Kent | B5: 8:30AM-9:00PM | C5: 2026-04-23 | D5: 0 | E5: 0 | F5: 36.22 | G5: =(E5-D5)*24 -> 0 | H5: =MIN(G5,9) -> 0 | I5: =IF(MAX(G5-9,0) - 1 < 0, 0, MAX(G5-9,0) - 1) -> 0 | J5: =H5*F5 -> 0 | K5: =I5*F5*1.2 -> 0 | L5: =J5+K5 -> 0
A6: Kent | B6: 8:30AM-9:00PM | C6: 2026-04-24 | D6: 0 | E6: 0 | F6: 36.22 | G6: =(E6-D6)*24 -> 0 | H6: =MIN(G6,9) -> 0 | I6: =IF(MAX(G6-9,0) - 1 < 0, 0, MAX(G6-9,0) - 1) -> 0 | J6: =H6*F6 -> 0 | K6: =I6*F6*1.2 -> 0 | L6: =J6+K6 -> 0
A7: Kent | B7: 8:30AM-9:00PM | C7: 2026-04-25 | D7: 09:00 | E7: 21:00 | F7: 36.22 | G7: =(E7-D7)*24 -> 12 | H7: =MIN(G7,8) -> 8 | I7: =IF(MAX(G7-8,0) - 1 < 0, 0, MAX(G7-8,0) - 1) -> 3 | J7: =H7*F7 -> 289.76 | K7: =I7*F7*1.2 -> 130.392 | L7: =J7+K7 -> 420.152
A8: Kent | B8: 8:30AM-9:00PM | C8: 2026-04-26 | D8: 08:00 | E8: 21:00 | F8: 36.22 | G8: =(E8-D8)*24 -> 13 | H8: =MIN(G8,8) -> 8 | I8: =IF(MAX(G8-8,0) - 1 < 0, 0, MAX(G8-8,0) - 1) -> 4 | J8: =H8*F8 -> 289.76 | K8: =I8*F8*1.2 -> 173.856 | L8: =J8+K8 -> 463.616
A14: SUMMARY | B14: REGULAR PAY | C14: OVER TIME PAY | D14: TOTAL PAY
A15: Kent | B15: =SUM(J2:J13) -> 579.52 | C15: =SUM(K2:K13) -> 304.248 | D15: =SUM(L2:L13) -> 883.768
A23: PAYROLL SLIP
A24: Name: | B24: Kent
A25: Job Title: | B25: Cook
A26: Payment Date: | B26: =C8+1 -> 46139
A27: Cut Off Period: | B27: Apr-20 to Apr-26, 2026
A28: Days Worked | B28: =COUNTIF(D2:D8, "*:*") -> 2
A29: Adjustments
A30: Basic Pay | B30: =B15 -> 579.52
A31: Bonus/Incentives | B31: 0
A32: Overtime Pay | B32: =C15 -> 304.248
A33: Other Income | B33: 0
A36: Gross Pay | B36: =D15 -> 883.768
A37: Deductions | B37: 0
A38: WH Tax | B38: 0
A40: Net Pay | B40: =SUM(B36:B38) -> 883.768

Sheet Jay Anne
A1: Employee | B1: Shift | C1: Date | D1: Time In | E1: Time Out | F1: Hourly Rate | G1: Total Hours | H1: Regular Hours | I1: Overtime Hours | J1: Regular Pay | K1: Overtime Pay | L1: Total Pay
A2: Jay Anne | B2: 10:00AM-9:00PM | C2: 2026-04-20 | D2: 0 | E2: 0 | F2: 33.33 | G2: =(E2-D2)*24 -> 0 | H2: =MIN(G2,9) -> 0 | I2: =IF(MAX(G2-9,0) - 1 < 0, 0, MAX(G2-9,0) - 1) -> 0 | J2: =H2*F2 -> 0 | K2: =I2*F2*1.2 -> 0 | L2: =J2+K2 -> 0
A3: Jay Anne | B3: 10:00AM-9:00PM | C3: 2026-04-21 | D3: 0 | E3: 0 | F3: 33.33 | G3: =(E3-D3)*24 -> 0 | H3: =MIN(G3,9) -> 0 | I3: =IF(MAX(G3-9,0) - 1 < 0, 0, MAX(G3-9,0) - 1) -> 0 | J3: =H3*F3 -> 0 | K3: =I3*F3*1.2 -> 0 | L3: =J3+K3 -> 0
A4: Jay Anne | B4: 10:00AM-9:00PM | C4: 2026-04-22 | D4: 09:00 | E4: 21:00 | F4: 33.33 | G4: =(E4-D4)*24 -> 12 | H4: =MIN(G4,9) -> 9 | I4: =IF(MAX(G4-9,0) - 1 < 0, 0, MAX(G4-9,0) - 1) -> 2 | J4: =H4*F4 -> 299.97 | K4: =I4*F4*1.2 -> 79.992 | L4: =J4+K4 -> 379.962
A5: Jay Anne | B5: 10:00AM-9:00PM | C5: 2026-04-23 | D5: 09:00 | E5: 21:00 | F5: 33.33 | G5: =(E5-D5)*24 -> 12 | H5: =MIN(G5,9) -> 9 | I5: =IF(MAX(G5-9,0) - 1 < 0, 0, MAX(G5-9,0) - 1) -> 2 | J5: =H5*F5 -> 299.97 | K5: =I5*F5*1.2 -> 79.992 | L5: =J5+K5 -> 379.962
A6: Jay Anne | B6: 10:00AM-9:00PM | C6: 2026-04-24 | D6: 09:00 | E6: 21:00 | F6: 33.33 | G6: =(E6-D6)*24 -> 12 | H6: =MIN(G6,9) -> 9 | I6: =IF(MAX(G6-9,0) - 1 < 0, 0, MAX(G6-9,0) - 1) -> 2 | J6: =H6*F6 -> 299.97 | K6: =I6*F6*1.2 -> 79.992 | L6: =J6+K6 -> 379.962
A7: Jay Anne | B7: 10:00AM-9:00PM | C7: 2026-04-25 | D7: 0 | E7: 0 | F7: 33.33 | G7: =(E7-D7)*24 -> 0 | H7: =MIN(G7,8) -> 0 | I7: =IF(MAX(G7-8,0) - 1 < 0, 0, MAX(G7-8,0) - 1) -> 0 | J7: =H7*F7 -> 0 | K7: =I7*F7*1.2 -> 0 | L7: =J7+K7 -> 0
A8: Jay Anne | B8: 10:00AM-9:00PM | C8: 2026-04-26 | D8: 0 | E8: 0 | F8: 33.33 | G8: =(E8-D8)*24 -> 0 | H8: =MIN(G8,8) -> 0 | I8: =IF(MAX(G8-8,0) - 1 < 0, 0, MAX(G8-8,0) - 1) -> 0 | J8: =H8*F8 -> 0 | K8: =I8*F8*1.2 -> 0 | L8: =J8+K8 -> 0
A14: SUMMARY | B14: REGULAR PAY | C14: OVER TIME PAY | D14: TOTAL PAY
A15: Jay Anne | B15: =SUM(J2:J13) -> 899.91 | C15: =SUM(K2:K13) -> 239.976 | D15: =SUM(L2:L13) -> 1139.886
A23: PAYROLL SLIP
A24: Name: | B24: =A2 -> Jay Anne
A25: Job Title: | B25: Cashier
A26: Payment Date: | B26: =C8+1 -> 46139
A27: Cut Off Period: | B27: =Kent!B27 -> Apr-20 to Apr-26, 2026
A28: Days Worked | B28: =COUNTIF(D2:D8, "*:*") -> 3
A29: Adjustments
A30: Basic Pay | B30: =B15 -> 899.91
A31: Bonus/Incentives | B31: 0
A32: Overtime Pay | B32: =C15 -> 239.976
A33: Other Income | B33: 0
A36: Gross Pay | B36: =D15 -> 1139.886
A37: Deductions | B37: 0
A38: WH Tax | B38: 0
A40: Net Pay | B40: =SUM(B36:B38) -> 1139.886

Sheet Kris
A1: Employee | B1: Shift | C1: Date | D1: Time In | E1: Time Out | F1: Hourly Rate | G1: Total Hours | H1: Regular Hours | I1: Overtime Hours | J1: Regular Pay | K1: Overtime Pay | L1: Total Pay
A2: Kris Naynayan | B2: 8:30AM-9:00PM | C2: 2026-04-20 | D2: 0 | E2: 0 | F2: 36.32 | G2: =(E2-D2)*24 -> 0 | H2: =MIN(G2,9) -> 0 | I2: =IF(MAX(G2-9,0) - 1 < 0, 0, MAX(G2-9,0) - 1) -> 0 | J2: =H2*F2 -> 0 | K2: =I2*F2*1.2 -> 0 | L2: =J2+K2 -> 0
A3: Kris Naynayan | B3: 8:30AM-9:00PM | C3: 2026-04-21 | D3: 0 | E3: 0 | F3: 36.32 | G3: =(E3-D3)*24 -> 0 | H3: =MIN(G3,9) -> 0 | I3: =IF(MAX(G3-9,0) - 1 < 0, 0, MAX(G3-9,0) - 1) -> 0 | J3: =H3*F3 -> 0 | K3: =I3*F3*1.2 -> 0 | L3: =J3+K3 -> 0
A4: Kris Naynayan | B4: 8:30AM-9:00PM | C4: 2026-04-22 | D4: 0 | E4: 0 | F4: 36.32 | G4: =(E4-D4)*24 -> 0 | H4: =MIN(G4,9) -> 0 | I4: =IF(MAX(G4-9,0) - 1 < 0, 0, MAX(G4-9,0) - 1) -> 0 | J4: =H4*F4 -> 0 | K4: =I4*F4*1.2 -> 0 | L4: =J4+K4 -> 0
A5: Kris Naynayan | B5: 8:30AM-9:00PM | C5: 2026-04-23 | D5: 09:00 | E5: 18:07 | F5: 36.32 | G5: =(E5-D5)*24 -> 9.1166667 | H5: =MIN(G5,9) -> 9 | I5: =IF(MAX(G5-9,0) - 1 < 0, 0, MAX(G5-9,0) - 1) -> 0 | J5: =H5*F5 -> 326.88 | K5: =I5*F5*1.2 -> 0 | L5: =J5+K5 -> 326.88
A6: Kris Naynayan | B6: 8:30AM-9:00PM | C6: 2026-04-24 | D6: 08:00 | E6: 21:00 | F6: 36.32 | G6: =(E6-D6)*24 -> 13 | H6: =MIN(G6,9) -> 9 | I6: =IF(MAX(G6-9,0) - 1 < 0, 0, MAX(G6-9,0) - 1) -> 3 | J6: =H6*F6 -> 326.88 | K6: =I6*F6*1.2 -> 130.752 | L6: =J6+K6 -> 457.632
A7: Kris Naynayan | B7: 8:30AM-9:00PM | C7: 2026-04-25 | D7: 09:00 | E7: 13:00 | F7: 40.86 | G7: =(E7-D7)*24 -> 4 | H7: =MIN(G7,8) -> 4 | I7: =IF(MAX(G7-8,0) - 1 < 0, 0, MAX(G7-8,0) - 1) -> 0 | J7: =H7*F7 -> 163.44 | K7: =I7*F7*1.2 -> 0 | L7: =J7+K7 -> 163.44
A8: Kris Naynayan | B8: 8:30AM-9:00PM | C8: 2026-04-26 | D8: 09:58 | E8: 17:00 | F8: 40.86 | G8: =(E8-D8)*24 -> 7.0333333 | H8: =MIN(G8,8) -> 7.0333333 | I8: =IF(MAX(G8-8,0) - 1 < 0, 0, MAX(G8-8,0) - 1) -> 0 | J8: =H8*F8 -> 287.382 | K8: =I8*F8*1.2 -> 0 | L8: =J8+K8 -> 287.382
A14: SUMMARY | B14: REGULAR PAY | C14: OVER TIME PAY | D14: TOTAL PAY
A15: Kris Naynayan | B15: =SUM(J2:J13) -> 1104.582 | C15: =SUM(K2:K13) -> 130.752 | D15: =SUM(L2:L13) -> 1235.334
A23: PAYROLL SLIP
A24: Name: | B24: =A2 -> Kris Naynayan
A25: Job Title: | B25: Staff
A26: Payment Date: | B26: =C8+1 -> 46139
A27: Cut Off Period: | B27: =Kent!B27 -> Apr-20 to Apr-26, 2026
A28: Days Worked | B28: =COUNTIF(D2:D8, "*:*") -> 4
A29: Adjustments
A30: Basic Pay | B30: =B15 -> 1104.582
A31: Bonus/Incentives | B31: 0
A32: Overtime Pay | B32: =C15 -> 130.752
A33: Other Income | B33: 0
A36: Gross Pay | B36: =D15 -> 1235.334
A37: Deductions | B37: 0
A38: WH Tax | B38: 0
A40: Net Pay | B40: =SUM(B36:B38) -> 1235.334

Sheet Cherry
A1: Employee | B1: Shift | C1: Date | D1: Time In | E1: Time Out | F1: Hourly Rate | G1: Total Hours | H1: Regular Hours | I1: Overtime Hours | J1: Regular Pay | K1: Overtime Pay | L1: Total Pay
A2: Cherry | B2: 8:30AM-9:00PM | C2: 2026-04-20 | D2: 08:00 | E2: 22:00 | F2: 37.39 | G2: =(E2-D2)*24 -> 14 | H2: =MIN(G2,9) -> 9 | I2: =IF(MAX(G2-9,0) - 1 < 0, 0, MAX(G2-9,0) - 1) -> 4 | J2: =H2*F2 -> 336.51 | K2: =I2*F2*1.2 -> 179.472 | L2: =J2+K2 -> 515.982
A3: Cherry | B3: 8:30AM-9:00PM | C3: 2026-04-21 | D3: 08:00 | E3: 22:00 | F3: 37.39 | G3: =(E3-D3)*24 -> 14 | H3: =MIN(G3,9) -> 9 | I3: =IF(MAX(G3-9,0) - 1 < 0, 0, MAX(G3-9,0) - 1) -> 4 | J3: =H3*F3 -> 336.51 | K3: =I3*F3*1.2 -> 179.472 | L3: =J3+K3 -> 515.982
A4: Cherry | B4: 8:30AM-9:00PM | C4: 2026-04-22 | D4: 08:00 | E4: 22:00 | F4: 37.39 | G4: =(E4-D4)*24 -> 14 | H4: =MIN(G4,9) -> 9 | I4: =IF(MAX(G4-9,0) - 1 < 0, 0, MAX(G4-9,0) - 1) -> 4 | J4: =H4*F4 -> 336.51 | K4: =I4*F4*1.2 -> 179.472 | L4: =J4+K4 -> 515.982
A5: Cherry | B5: 8:30AM-9:00PM | C5: 2026-04-23 | D5: 08:00 | E5: 22:00 | F5: 37.39 | G5: =(E5-D5)*24 -> 14 | H5: =MIN(G5,9) -> 9 | I5: =IF(MAX(G5-9,0) - 1 < 0, 0, MAX(G5-9,0) - 1) -> 4 | J5: =H5*F5 -> 336.51 | K5: =I5*F5*1.2 -> 179.472 | L5: =J5+K5 -> 515.982
A6: Cherry | B6: 8:30AM-9:00PM | C6: 2026-04-24 | D6: 0 | E6: 0 | F6: 37.39 | G6: =(E6-D6)*24 -> 0 | H6: =MIN(G6,9) -> 0 | I6: =IF(MAX(G6-9,0) - 1 < 0, 0, MAX(G6-9,0) - 1) -> 0 | J6: =H6*F6 -> 0 | K6: =I6*F6*1.2 -> 0 | L6: =J6+K6 -> 0
A7: Cherry | B7: 8:30AM-9:00PM | C7: 2026-04-25 | D7: 09:00 | E7: 22:00 | F7: 42.06 | G7: =(E7-D7)*24 -> 13 | H7: =MIN(G7,8) -> 8 | I7: =IF(MAX(G7-8,0) - 1 < 0, 0, MAX(G7-8,0) - 1) -> 4 | J7: =H7*F7 -> 336.48 | K7: =I7*F7*1.2 -> 201.888 | L7: =J7+K7 -> 538.368
A8: Cherry | B8: 8:30AM-9:00PM | C8: 2026-04-26 | D8: 08:00 | E8: 22:00 | F8: 42.06 | G8: =(E8-D8)*24 -> 14 | H8: =MIN(G8,8) -> 8 | I8: =IF(MAX(G8-8,0) - 1 < 0, 0, MAX(G8-8,0) - 1) -> 5 | J8: =H8*F8 -> 336.48 | K8: =I8*F8*1.2 -> 252.36 | L8: =J8+K8 -> 588.84
A14: SUMMARY | B14: REGULAR PAY | C14: OVER TIME PAY | D14: TOTAL PAY
A15: Cherry | B15: =SUM(J2:J13) -> 2019 | C15: =SUM(K2:K13) -> 1172.136 | D15: =SUM(L2:L13) -> 3191.136
A23: PAYROLL SLIP
A24: Name: | B24: =A2 -> Cherry
A25: Job Title: | B25: Staff
A26: Payment Date: | B26: =C8+1 -> 46139
A27: Cut Off Period: | B27: =Kent!B27 -> Apr-20 to Apr-26, 2026
A28: Days Worked | B28: =COUNTIF(D2:D8, "*:*") -> 6
A29: Adjustments
A30: Basic Pay | B30: =B15 -> 2019
A31: Bonus/Incentives | B31: 0
A32: Overtime Pay | B32: =C15 -> 1172.136
A33: Other Income | B33: 0
A36: Gross Pay | B36: =D15 -> 3191.136
A37: Deductions | B37: 0
A38: WH Tax | B38: 0
A40: Net Pay | B40: =SUM(B36:B38) -> 3191.136

Sheet Pepito
A1: Employee | B1: Shift | C1: Date | D1: Time In | E1: Time Out | F1: Hourly Rate | G1: Total Hours | H1: Regular Hours | I1: Overtime Hours | J1: Regular Pay | K1: Overtime Pay | L1: Total Pay
A2: Pepito | B2: 8:30AM-9:00PM | C2: 2026-04-20 | D2: 0 | E2: 0 | F2: 27.77 | G2: =(E2-D2)*24 -> 0 | H2: =MIN(G2,9) -> 0 | I2: =IF(MAX(G2-9,0) - 1 < 0, 0, MAX(G2-9,0) - 1) -> 0 | J2: =H2*F2 -> 0 | K2: =I2*F2*1.2 -> 0 | L2: =J2+K2 -> 0
A3: Pepito | B3: 8:30AM-9:00PM | C3: 2026-04-21 | D3: 08:00 | E3: 21:00 | F3: 27.77 | G3: =(E3-D3)*24 -> 13 | H3: =MIN(G3,9) -> 9 | I3: =IF(MAX(G3-9,0) - 1 < 0, 0, MAX(G3-9,0) - 1) -> 3 | J3: =H3*F3 -> 249.93 | K3: =I3*F3*1.2 -> 99.972 | L3: =J3+K3 -> 349.902
A4: Pepito | B4: 8:30AM-9:00PM | C4: 2026-04-22 | D4: 08:00 | E4: 21:00 | F4: 27.77 | G4: =(E4-D4)*24 -> 13 | H4: =MIN(G4,9) -> 9 | I4: =IF(MAX(G4-9,0) - 1 < 0, 0, MAX(G4-9,0) - 1) -> 3 | J4: =H4*F4 -> 249.93 | K4: =I4*F4*1.2 -> 99.972 | L4: =J4+K4 -> 349.902
A5: Pepito | B5: 8:30AM-9:00PM | C5: 2026-04-23 | D5: 08:00 | E5: 21:00 | F5: 27.77 | G5: =(E5-D5)*24 -> 13 | H5: =MIN(G5,9) -> 9 | I5: =IF(MAX(G5-9,0) - 1 < 0, 0, MAX(G5-9,0) - 1) -> 3 | J5: =H5*F5 -> 249.93 | K5: =I5*F5*1.2 -> 99.972 | L5: =J5+K5 -> 349.902
A6: Pepito | B6: 8:30AM-9:00PM | C6: 2026-04-24 | D6: 08:00 | E6: 21:00 | F6: 27.77 | G6: =(E6-D6)*24 -> 13 | H6: =MIN(G6,9) -> 9 | I6: =IF(MAX(G6-9,0) - 1 < 0, 0, MAX(G6-9,0) - 1) -> 3 | J6: =H6*F6 -> 249.93 | K6: =I6*F6*1.2 -> 99.972 | L6: =J6+K6 -> 349.902
A7: Pepito | B7: 8:30AM-9:00PM | C7: 2026-04-25 | D7: 09:00 | E7: 21:00 | F7: 31.25 | G7: =(E7-D7)*24 -> 12 | H7: =MIN(G7,8) -> 8 | I7: =IF(MAX(G7-8,0) - 1 < 0, 0, MAX(G7-8,0) - 1) -> 3 | J7: =H7*F7 -> 250 | K7: =I7*F7*1.2 -> 112.5 | L7: =J7+K7 -> 362.5
A8: Pepito | B8: 8:30AM-9:00PM | C8: 2026-04-26 | D8: 0 | E8: 0 | F8: 31.25 | G8: =(E8-D8)*24 -> 0 | H8: =MIN(G8,8) -> 0 | I8: =IF(MAX(G8-8,0) - 1 < 0, 0, MAX(G8-8,0) - 1) -> 0 | J8: =H8*F8 -> 0 | K8: =I8*F8*1.2 -> 0 | L8: =J8+K8 -> 0
A14: SUMMARY | B14: REGULAR PAY | C14: OVER TIME PAY | D14: TOTAL PAY
A15: Ruela | B15: =SUM(J2:J13) -> 1249.72 | C15: =SUM(K2:K13) -> 512.388 | D15: =SUM(L2:L13) -> 1762.108
A23: PAYROLL SLIP
A24: Name: | B24: Pepito
A25: Job Title: | B25: Staff
A26: Payment Date: | B26: =C8+1 -> 46139
A27: Cut Off Period: | B27: =Kent!B27 -> Apr-20 to Apr-26, 2026
A28: Days Worked | B28: =COUNTIF(D2:D8, "*:*") -> 5
A29: Adjustments
A30: Basic Pay | B30: =B15 -> 1249.72
A31: Bonus/Incentives | B31: 0
A32: Overtime Pay | B32: =C15 -> 512.388
A33: Other Income | B33: 0
A36: Gross Pay | B36: =D15 -> 1762.108
A37: Deductions | B37: 0
A38: WH Tax | B38: 0
A40: Net Pay | B40: =SUM(B36:B38) -> 1762.108

Sheet Mark
A1: Employee | B1: Shift | C1: Date | D1: Time In | E1: Time Out | F1: Hourly Rate | G1: Total Hours | H1: Regular Hours | I1: Overtime Hours | J1: Regular Pay | K1: Overtime Pay | L1: Total Pay
A2: Mark | B2: 9:00AM-9:00PM | C2: 2026-04-20 | D2: 09:00 | E2: 22:00 | F2: 30 | G2: =(E2-D2)*24 -> 13 | H2: =MIN(G2,9) -> 9 | I2: =IF(MAX(G2-9,0) - 1 < 0, 0, MAX(G2-9,0) - 1) -> 3 | J2: =H2*F2 -> 270 | K2: =I2*F2*1.2 -> 108 | L2: =J2+K2 -> 378
A3: Mark | B3: 9:00AM-9:00PM | C3: 2026-04-21 | D3: 09:00 | E3: 22:00 | F3: 30 | G3: =(E3-D3)*24 -> 13 | H3: =MIN(G3,9) -> 9 | I3: =IF(MAX(G3-9,0) - 1 < 0, 0, MAX(G3-9,0) - 1) -> 3 | J3: =H3*F3 -> 270 | K3: =I3*F3*1.2 -> 108 | L3: =J3+K3 -> 378
A4: Mark | B4: 9:00AM-9:00PM | C4: 2026-04-22 | D4: 09:00 | E4: 22:00 | F4: 30 | G4: =(E4-D4)*24 -> 13 | H4: =MIN(G4,9) -> 9 | I4: =IF(MAX(G4-9,0) - 1 < 0, 0, MAX(G4-9,0) - 1) -> 3 | J4: =H4*F4 -> 270 | K4: =I4*F4*1.2 -> 108 | L4: =J4+K4 -> 378
A5: Mark | B5: 9:00AM-9:00PM | C5: 2026-04-23 | D5: 0 | E5: 0 | F5: 30 | G5: =(E5-D5)*24 -> 0 | H5: =MIN(G5,9) -> 0 | I5: =IF(MAX(G5-9,0) - 1 < 0, 0, MAX(G5-9,0) - 1) -> 0 | J5: =H5*F5 -> 0 | K5: =I5*F5*1.2 -> 0 | L5: =J5+K5 -> 0
A6: Mark | B6: 9:00AM-9:00PM | C6: 2026-04-24 | D6: 09:00 | E6: 21:30 | F6: 30 | G6: =(E6-D6)*24 -> 12.5 | H6: =MIN(G6,9) -> 9 | I6: =IF(MAX(G6-9,0) - 1 < 0, 0, MAX(G6-9,0) - 1) -> 2.5 | J6: =H6*F6 -> 270 | K6: =I6*F6*1.2 -> 90 | L6: =J6+K6 -> 360
A7: Mark | B7: 9:00AM-9:00PM | C7: 2026-04-25 | D7: 13:00 | E7: 22:00 | F7: 33.75 | G7: =(E7-D7)*24 -> 9 | H7: =MIN(G7,8) -> 8 | I7: =IF(MAX(G7-8,0) - 1 < 0, 0, MAX(G7-8,0) - 1) -> 0 | J7: =H7*F7 -> 270 | K7: =I7*F7*1.2 -> 0 | L7: =J7+K7 -> 270
A8: Mark | B8: 9:00AM-9:00PM | C8: 2026-04-26 | D8: 10:00 | E8: 22:00 | F8: 33.75 | G8: =(E8-D8)*24 -> 12 | H8: =MIN(G8,8) -> 8 | I8: =IF(MAX(G8-8,0) - 1 < 0, 0, MAX(G8-8,0) - 1) -> 3 | J8: =H8*F8 -> 270 | K8: =I8*F8*1.2 -> 121.5 | L8: =J8+K8 -> 391.5
A14: SUMMARY | B14: REGULAR PAY | C14: OVER TIME PAY | D14: TOTAL PAY
A15: Mark | B15: =SUM(J2:J13) -> 1620 | C15: =SUM(K2:K13) -> 535.5 | D15: =SUM(L2:L13) -> 2155.5
A23: PAYROLL SLIP
A24: Name: | B24: =A2 -> Mark
A25: Job Title: | B25: Staff
A26: Payment Date: | B26: =C8+1 -> 46139
A27: Cut Off Period: | B27: =Kent!B27 -> Apr-20 to Apr-26, 2026
A28: Days Worked | B28: =COUNTIF(D2:D8, "*:*") -> 6
A29: Adjustments
A30: Basic Pay | B30: =B15 -> 1620
A31: Bonus/Incentives | B31: 0
A32: Overtime Pay | B32: =C15 -> 535.5
A33: Other Income | B33: 0
A36: Gross Pay | B36: =D15 -> 2155.5
A37: Deductions | B37: 0
A38: WH Tax | B38: 0
A40: Net Pay | B40: =SUM(B36:B38) -> 2155.5

Sheet Kim
A1: Employee | B1: Shift | C1: Date | D1: Time In | E1: Time Out | F1: Hourly Rate | G1: Total Hours | H1: Regular Hours | I1: Overtime Hours | J1: Regular Pay | K1: Overtime Pay | L1: Total Pay
A2: Kim | B2: 10:00AM-9:00PM | C2: 2026-04-06 | D2: 0 | E2: 0 | F2: 27.77 | G2: =(E2-D2)*24 -> 0 | H2: =MIN(G2,8) -> 0 | I2: =IF(MAX(G2-9,0) - 1 < 0, 0, MAX(G2-9,0) - 1) -> 0 | J2: =H2*F2 -> 0 | K2: =I2*F2*1.2 -> 0 | L2: =J2+K2 -> 0
A3: Kim | B3: 10:00AM-9:00PM | C3: 2026-04-07 | D3: 0 | E3: 0 | F3: 27.77 | G3: =(E3-D3)*24 -> 0 | H3: =MIN(G3,8) -> 0 | I3: =IF(MAX(G3-9,0) - 1 < 0, 0, MAX(G3-9,0) - 1) -> 0 | J3: =H3*F3 -> 0 | K3: =I3*F3*1.2 -> 0 | L3: =J3+K3 -> 0
A4: Kim | B4: 10:00AM-9:00PM | C4: 2026-04-08 | D4: 0 | E4: 0 | F4: 27.77 | G4: =(E4-D4)*24 -> 0 | H4: =MIN(G4,8) -> 0 | I4: =IF(MAX(G4-9,0) - 1 < 0, 0, MAX(G4-9,0) - 1) -> 0 | J4: =H4*F4 -> 0 | K4: =I4*F4*1.2 -> 0 | L4: =J4+K4 -> 0
A5: Kim | B5: 10:00AM-9:00PM | C5: 2026-04-09 | D5: 0 | E5: 0 | F5: 27.77 | G5: =(E5-D5)*24 -> 0 | H5: =MIN(G5,8) -> 0 | I5: =IF(MAX(G5-9,0) - 1 < 0, 0, MAX(G5-9,0) - 1) -> 0 | J5: =H5*F5 -> 0 | K5: =I5*F5*1.2 -> 0 | L5: =J5+K5 -> 0
A6: Kim | B6: 10:00AM-9:00PM | C6: 2026-04-10 | D6: 0 | E6: 0 | F6: 27.77 | G6: =(E6-D6)*24 -> 0 | H6: =MIN(G6,8) -> 0 | I6: =IF(MAX(G6-9,0) - 1 < 0, 0, MAX(G6-9,0) - 1) -> 0 | J6: =H6*F6 -> 0 | K6: =I6*F6*1.2 -> 0 | L6: =J6+K6 -> 0
A7: Kim | B7: 10:00AM-9:00PM | C7: 2026-04-11 | D7: 0 | E7: 0 | F7: 27.77 | G7: =(E7-D7)*24 -> 0 | H7: =MIN(G7,9) -> 0 | I7: =IF(MAX(G7-9,0) - 1 < 0, 0, MAX(G7-9,0) - 1) -> 0 | J7: =H7*F7 -> 0 | K7: =I7*F7*1.2 -> 0 | L7: =J7+K7 -> 0
A8: Kim | B8: 10:00AM-9:00PM | C8: 2026-04-12 | D8: 0 | E8: 0 | F8: 27.77 | G8: =(E8-D8)*24 -> 0 | H8: =MIN(G8,9) -> 0 | I8: =IF(MAX(G8-9,0) - 1 < 0, 0, MAX(G8-9,0) - 1) -> 0 | J8: =H8*F8 -> 0 | K8: =I8*F8*1.2 -> 0 | L8: =J8+K8 -> 0
A14: SUMMARY | B14: REGULAR PAY | C14: OVER TIME PAY | D14: TOTAL PAY
A15: Aldrin | B15: =SUM(J2:J13) -> 0 | C15: =SUM(K2:K13) -> 0 | D15: =SUM(L2:L13) -> 0
A23: PAYROLL SLIP
A24: Name: | B24: =A2 -> Kim
A25: Job Title: | B25: Staff
A26: Payment Date: | B26: =C8+1 -> 46125
A27: Cut Off Period: | B27: =Kent!B27 -> Apr-20 to Apr-26, 2026
A28: Days Worked | B28: =COUNTIF(D2:D8, "*:*") -> 0
A29: Adjustments
A30: Basic Pay | B30: =B15 -> 0
A31: Bonus/Incentives | B31: 0
A32: Overtime Pay | B32: =C15 -> 0
A33: Other Income | B33: 0
A36: Gross Pay | B36: =D15 -> 0
A37: Deductions | B37: 0
A38: WH Tax | B38: 0
A40: Net Pay | B40: =SUM(B36:B38) -> 0

Sheet David
A1: Employee | B1: Shift | C1: Date | D1: Time In | E1: Time Out | F1: Hourly Rate | G1: Total Hours | H1: Regular Hours | I1: Overtime Hours | J1: Regular Pay | K1: Overtime Pay | L1: Total Pay
A2: David | B2: 5:00PM-10:00PM | C2: 2026-02-09 | D2: 09:00 | E2: 0 | L2: 420
A3: David | B3: 5:00PM-10:00PM | C3: 2026-02-10 | D3: 09:01 | E3: 0 | L3: 520
A4: David | B4: 5:00PM-10:00PM | C4: 2026-02-11 | D4: 09:02 | E4: 0 | L4: 400
A5: David | B5: 5:00PM-10:00PM | C5: 2026-02-12 | D5: 09:03 | E5: 0 | L5: 400
A6: David | B6: 5:00PM-10:00PM | C6: 2026-02-13 | D6: 09:04 | E6: 0 | L6: 400
A7: David | B7: 9:30AM-10:00PM | C7: 2026-02-14 | D7: 09:05 | E7: 0 | L7: 430
A8: David | B8: 9:30AM-10:00PM | C8: 2026-02-15 | D8: 0 | E8: 0 | L8: 0
A14: SUMMARY | B14: REGULAR PAY | C14: OVER TIME PAY | D14: TOTAL PAY
A15: Lenard | B15: =SUM(J2:J13) -> 0 | C15: =SUM(K2:K13) -> 0 | D15: =SUM(L2:L13) -> 2570
A23: PAYROLL SLIP
A24: Name: | B24: =A2 -> David
A25: Job Title: | B25: Staff
A26: Payment Date: | B26: =C8+1 -> 46069
A27: Cut Off Period: | B27: =Kent!B27 -> Apr-20 to Apr-26, 2026
A28: Days Worked | B28: =COUNTIF(D2:D8, "*:*") -> 6
A29: Adjustments
A30: Basic Pay | B30: =B15 -> 0
A31: Bonus/Incentives | B31: 0
A32: Overtime Pay | B32: =C15 -> 0
A33: Other Income | B33: 0
A36: Gross Pay | B36: =D15 -> 2570
A37: Deductions | B37: 0
A38: WH Tax | B38: 0
A40: Net Pay | B40: =SUM(B36:B38) -> 2570

Sheet Chardiya
A1: Employee | B1: Shift | C1: Date | D1: Time In | E1: Time Out | F1: Hourly Rate | G1: Total Hours | H1: Regular Hours | I1: Overtime Hours | J1: Regular Pay | K1: Overtime Pay | L1: Total Pay
A2: Chadiyah | B2: 8:30AM-9:00PM | C2: 2026-02-23 | D2: 08:30 | E2: 19:00 | F2: 34.18 | G2: =(E2-D2)*24 -> 10.5 | H2: =MIN(G2,9) -> 9 | I2: =IF(MAX(G2-9,0) - 1 < 0, 0, MAX(G2-9,0) - 1) -> 0.5 | J2: =H2*F2 -> 307.62 | K2: =I2*F2*1.2 -> 20.508 | L2: =J2+K2 -> 328.128
A3: Chadiyah | B3: 8:30AM-9:00PM | C3: 2026-02-24 | D3: 08:30 | E3: 17:00 | F3: 34.18 | G3: =(E3-D3)*24 -> 8.5 | H3: =MIN(G3,9) -> 8.5 | I3: =IF(MAX(G3-9,0) - 1 < 0, 0, MAX(G3-9,0) - 1) -> 0 | J3: =H3*F3 -> 290.53 | K3: =I3*F3*1.2 -> 0 | L3: =J3+K3 -> 290.53
A4: Chadiyah | B4: 8:30AM-9:00PM | C4: 2026-02-25 | D4: 08:30 | E4: 16:00 | F4: 34.18 | G4: =(E4-D4)*24 -> 7.5 | H4: =MIN(G4,9) -> 7.5 | I4: =IF(MAX(G4-9,0) - 1 < 0, 0, MAX(G4-9,0) - 1) -> 0 | J4: =H4*F4 -> 256.35 | K4: =I4*F4*1.2 -> 0 | L4: =J4+K4 -> 256.35
A5: Chadiyah | B5: 8:30AM-9:00PM | C5: 2026-02-26 | D5: 08:30 | E5: 21:30 | F5: 34.18 | G5: =(E5-D5)*24 -> 13 | H5: =MIN(G5,9) -> 9 | I5: =IF(MAX(G5-9,0) - 1 < 0, 0, MAX(G5-9,0) - 1) -> 3 | J5: =H5*F5 -> 307.62 | K5: =I5*F5*1.2 -> 123.048 | L5: =J5+K5 -> 430.668
A6: Chadiyah | B6: 8:30AM-9:00PM | C6: 2026-02-27 | D6: 0 | E6: 0 | F6: 34.18 | G6: =(E6-D6)*24 -> 0 | H6: =MIN(G6,9) -> 0 | I6: =IF(MAX(G6-9,0) - 1 < 0, 0, MAX(G6-9,0) - 1) -> 0 | J6: =H6*F6 -> 0 | K6: =I6*F6*1.2 -> 0 | L6: =J6+K6 -> 0
A7: Chadiyah | B7: 8:30AM-9:00PM | C7: 2026-02-28 | D7: 0 | E7: 0 | F7: 34.18 | G7: =(E7-D7)*24 -> 0 | H7: =MIN(G7,9) -> 0 | I7: =IF(MAX(G7-9,0) - 1 < 0, 0, MAX(G7-9,0) - 1) -> 0 | J7: =H7*F7 -> 0 | K7: =I7*F7*1.2 -> 0 | L7: =J7+K7 -> 0
A8: Chadiyah | B8: 8:30AM-9:00PM | C8: 2026-03-01 | D8: 0 | E8: 0 | F8: 34.18 | G8: =(E8-D8)*24 -> 0 | H8: =MIN(G8,9) -> 0 | I8: =IF(MAX(G8-9,0) - 1 < 0, 0, MAX(G8-9,0) - 1) -> 0 | J8: =H8*F8 -> 0 | K8: =I8*F8*1.2 -> 0 | L8: =J8+K8 -> 0
A14: SUMMARY | B14: REGULAR PAY | C14: OVER TIME PAY | D14: TOTAL PAY
A15: Chadiyah | B15: =SUM(J2:J13) -> 1162.12 | C15: =SUM(K2:K13) -> 143.556 | D15: =SUM(L2:L13) -> 1305.676
A23: PAYROLL SLIP
A24: Name: | B24: =A2 -> Chadiyah
A25: Job Title: | B25: Staff
A26: Payment Date: | B26: =C8+1 -> 46083
A27: Cut Off Period: | B27: =Kent!B27 -> Apr-20 to Apr-26, 2026
A28: Days Worked | B28: =COUNTIF(D2:D8, "*:*") -> 4
A29: Adjustments
A30: Basic Pay | B30: =B15 -> 1162.12
A31: Bonus/Incentives | B31: 0
A32: Overtime Pay | B32: =C15 -> 143.556
A33: Other Income | B33: 0
A36: Gross Pay | B36: =D15 -> 1305.676
A37: Deductions | B37: 0
A38: WH Tax | B38: 0
A40: Net Pay | B40: =SUM(B36:B38) -> 1305.676
B41: -367
B42: =SUM(B40:B41) -> 938.676

Sheet Lenard
A1: Employee | B1: Shift | C1: Date | D1: Time In | E1: Time Out | F1: Hourly Rate | G1: Total Hours | H1: Regular Hours | I1: Overtime Hours | J1: Regular Pay | K1: Overtime Pay | L1: Total Pay
A2: Lenard | B2: 5:00PM-10:00PM | C2: 2026-02-16 | D2: 0 | E2: 0 | F2: 22.22 | G2: =(E2-D2)*24 -> 0 | H2: =MIN(G2,9) -> 0 | I2: =IF(MAX(G2-9,0) - 1 < 0, 0, MAX(G2-9,0) - 1) -> 0 | J2: =H2*F2 -> 0 | K2: =I2*F2*1.2 -> 0 | L2: =J2+K2 -> 0
A3: Lenard | B3: 5:00PM-10:00PM | C3: 2026-02-17 | D3: 0 | E3: 0 | F3: 22.22 | G3: =(E3-D3)*24 -> 0 | H3: =MIN(G3,9) -> 0 | I3: =IF(MAX(G3-9,0) - 1 < 0, 0, MAX(G3-9,0) - 1) -> 0 | J3: =H3*F3 -> 0 | K3: =I3*F3*1.2 -> 0 | L3: =J3+K3 -> 0
A4: Lenard | B4: 5:00PM-10:00PM | C4: 2026-02-18 | D4: 17:00 | E4: 21:00 | F4: 22.22 | G4: =(E4-D4)*24 -> 4 | H4: =MIN(G4,9) -> 4 | I4: =IF(MAX(G4-9,0) - 1 < 0, 0, MAX(G4-9,0) - 1) -> 0 | J4: =H4*F4 -> 88.88 | K4: =I4*F4*1.2 -> 0 | L4: 100
A5: Lenard | B5: 5:00PM-10:00PM | C5: 2026-02-19 | D5: 17:00 | E5: 21:00 | F5: 22.22 | G5: =(E5-D5)*24 -> 4 | H5: =MIN(G5,9) -> 4 | I5: =IF(MAX(G5-9,0) - 1 < 0, 0, MAX(G5-9,0) - 1) -> 0 | J5: =H5*F5 -> 88.88 | K5: =I5*F5*1.2 -> 0 | L5: 100
A6: Lenard | B6: 5:00PM-10:00PM | C6: 2026-02-20 | D6: 17:00 | E6: 21:00 | F6: 22.22 | G6: =(E6-D6)*24 -> 4 | H6: =MIN(G6,9) -> 4 | I6: =IF(MAX(G6-9,0) - 1 < 0, 0, MAX(G6-9,0) - 1) -> 0 | J6: =H6*F6 -> 88.88 | K6: =I6*F6*1.2 -> 0 | L6: 100
A7: Lenard | B7: 9:30AM-10:00PM | C7: 2026-02-21 | D7: 08:57 | E7: 21:00 | F7: 22.22 | G7: =(E7-D7)*24 -> 12.05 | H7: =MIN(G7,9) -> 9 | I7: =IF(MAX(G7-9,0) - 1 < 0, 0, MAX(G7-9,0) - 1) -> 2.05 | J7: =H7*F7 -> 199.98 | K7: =I7*F7*1.2 -> 54.6612 | L7: =J7+K7 -> 254.6412
A8: Lenard | B8: 9:30AM-10:00PM | C8: 2026-02-22 | D8: 12:23 | E8: 21:00 | F8: 22.22 | G8: =(E8-D8)*24 -> 8.6166667 | H8: =MIN(G8,9) -> 8.6166667 | I8: =IF(MAX(G8-9,0) - 1 < 0, 0, MAX(G8-9,0) - 1) -> 0 | J8: =H8*F8 -> 191.46233 | K8: =I8*F8*1.2 -> 0 | L8: =J8+K8 -> 191.46233
A14: SUMMARY | B14: REGULAR PAY | C14: OVER TIME PAY | D14: TOTAL PAY
A15: Lenard | B15: =SUM(J2:J13) -> 658.08233 | C15: =SUM(K2:K13) -> 54.6612 | D15: =SUM(L2:L13) -> 746.10353
A23: PAYROLL SLIP
A24: Name: | B24: =A2 -> Lenard
A25: Job Title: | B25: Staff
A26: Payment Date: | B26: =C8+1 -> 46076
A27: Cut Off Period: | B27: =Kent!B27 -> Apr-20 to Apr-26, 2026
A28: Days Worked | B28: =COUNTIF(D2:D8, "*:*") -> 5
A29: Adjustments
A30: Basic Pay | B30: =B15 -> 658.08233
A31: Bonus/Incentives | B31: 0
A32: Overtime Pay | B32: =C15 -> 54.6612
A33: Other Income | B33: 0
A36: Gross Pay | B36: =D15 -> 746.10353
A37: Deductions | B37: 0
A38: WH Tax | B38: 0
A40: Net Pay | B40: =SUM(B36:B38) -> 746.10353

Sheet Template
A1: Employee | B1: Shift | C1: Date | D1: Time In | E1: Time Out | F1: Hourly Rate | G1: Total Hours | H1: Regular Hours | I1: Overtime Hours | J1: Regular Pay | K1: Overtime Pay | L1: Total Pay
A2: Name | B2: 8:30AM-9:00PM | C2: 2026-01-12 | D2: 08:30 | E2: 22:00 | F2: 38.46 | G2: =(E2-D2)*24 -> 13.5 | H2: =MIN(G2,10) -> 10 | I2: =MAX(G2-10,0) - 1 -> 2.5 | J2: =H2*F2 -> 384.6 | K2: =I2*F2*1.2 -> 115.38 | L2: =J2+K2 -> 499.98
A3: Name | B3: 8:30AM-9:00PM | C3: 2026-01-13 | D3: 08:30 | E3: 22:00 | F3: 38.46 | G3: =(E3-D3)*24 -> 13.5 | H3: =MIN(G3,10) -> 10 | I3: =MAX(G3-10,0) - 1 -> 2.5 | J3: =H3*F3 -> 384.6 | K3: =I3*F3*1.2 -> 115.38 | L3: =J3+K3 -> 499.98
A4: Name | B4: 8:30AM-9:00PM | C4: 2026-01-14 | D4: 08:30 | E4: 22:00 | F4: 38.46 | G4: =(E4-D4)*24 -> 13.5 | H4: =MIN(G4,10) -> 10 | I4: =MAX(G4-10,0) - 1 -> 2.5 | J4: =H4*F4 -> 384.6 | K4: =I4*F4*1.2 -> 115.38 | L4: =J4+K4 -> 499.98
A5: Name | B5: 8:30AM-9:00PM | C5: 2026-01-15 | D5: 08:30 | E5: 22:00 | F5: 38.46 | G5: =(E5-D5)*24 -> 13.5 | H5: =MIN(G5,10) -> 10 | I5: =MAX(G5-10,0) - 1 -> 2.5 | J5: =H5*F5 -> 384.6 | K5: =I5*F5*1.2 -> 115.38 | L5: =J5+K5 -> 499.98
A6: Name | B6: 8:30AM-9:00PM | C6: 2026-01-16 | D6: 08:30 | E6: 22:00 | F6: 38.46 | G6: =(E6-D6)*24 -> 13.5 | H6: =MIN(G6,10) -> 10 | I6: =MAX(G6-10,0) - 1 -> 2.5 | J6: =H6*F6 -> 384.6 | K6: =I6*F6*1.2 -> 115.38 | L6: =J6+K6 -> 499.98
A7: Name | B7: 8:30AM-9:00PM | C7: 2026-01-17 | D7: 08:30 | E7: 22:00 | F7: 38.46 | G7: =(E7-D7)*24 -> 13.5 | H7: =MIN(G7,10) -> 10 | I7: =MAX(G7-10,0) - 1 -> 2.5 | J7: =H7*F7 -> 384.6 | K7: =I7*F7*1.2 -> 115.38 | L7: =J7+K7 -> 499.98
A8: Name | B8: 8:30AM-9:00PM | C8: 2026-01-18 | D8: 08:30 | E8: 22:00 | F8: 38.46 | G8: =(E8-D8)*24 -> 13.5 | H8: =MIN(G8,10) -> 10 | I8: =MAX(G8-10,0) - 1 -> 2.5 | J8: =H8*F8 -> 384.6 | K8: =I8*F8*1.2 -> 115.38 | L8: =J8+K8 -> 499.98
A14: SUMMARY | B14: REGULAR PAY | C14: OVER TIME PAY | D14: TOTAL PAY
A15: Rhea Mae | B15: =SUM(J2:J13) -> 2692.2 | C15: =SUM(K2:K13) -> 807.66 | D15: =SUM(L2:L13) -> 3499.86
A23: PAYROLL SLIP
A24: Name: | B24: =A2 -> Name
A25: Job Title: | B25: Store Manager
A26: Payment Date: | B26: 46041
A27: Cut Off Period: | B27: Jan-12 to Jan-28, 2026
A29: Adjustments
A30: Basic Pay | B30: =B15 -> 2692.2
A31: Bonus/Incentives | B31: 0
A32: Overtime Pay | B32: =C15 -> 807.66
A33: Other Income | B33: 0
A36: Gross Pay | B36: =D15 -> 3499.86
A37: Deductions | B37: 0
A38: WH Tax | B38: 0
A40: Net Pay | B40: =SUM(B36:B38) -> 3499.86

Sheet Rhoda
A1: Employee | B1: Date | C1: Shift | D1: Time In | E1: Time Out | F1: Hourly Rate | G1: Total Hours | H1: Regular Hours | I1: Overtime Hours | J1: Regular Pay | K1: Overtime Pay | L1: Total Pay
A2: Rhoda | B2: 46021 | C2: 9:00AM-7:00PM | D2: 0.45833333 | E2: 0.99930556 | F2: 29.91 | G2: 15 | H2: =MIN(G2,9) -> 9 | I2: =MAX(G2-9,0) - 1 -> 5 | J2: =H2*F2 -> 269.19 | K2: =I2*F2*1.2 -> 179.46 | L2: =J2+K2 -> 448.65
A3: Rhoda | B3: 46022 | C3: 9:00AM-7:00PM | D3: 0.41666667 | E3: 0.8125 | F3: 29.91 | G3: =(E3-D3)*24 -> 9.5 | H3: =MIN(G3,9) -> 9 | I3: =MAX(G3-9,0) - 1 -> -0.5 | J3: =H3*F3 -> 269.19 | L3: 538 | M3: doublepay
A4: Rhoda | B4: 46027 | C4: 9:00AM-7:00PM | D4: 0.375 | E4: 0.91666667 | F4: 29.91 | G4: =(E4-D4)*24 -> 13 | H4: =MIN(G4,9) -> 9 | I4: =MAX(G4-9,0) - 1 -> 3 | J4: =H4*F4 -> 269.19 | K4: =I4*F4*1.2 -> 107.676 | L4: =J4+K4 -> 376.866
A5: Rhoda | B5: 46028 | C5: 9:00AM-7:00PM | D5: 0.375 | E5: 0.875 | F5: 29.91 | G5: =(E5-D5)*24 -> 12 | H5: =MIN(G5,9) -> 9 | I5: =MAX(G5-9,0) - 1 -> 2 | J5: =H5*F5 -> 269.19 | K5: =I5*F5*1.2 -> 71.784 | L5: =J5+K5 -> 340.974
A6: Rhoda | B6: 46029 | C6: 9:00AM-7:00PM | D6: 0.375 | E6: 0.9375 | F6: 29.91 | G6: =(E6-D6)*24 -> 13.5 | H6: =MIN(G6,9) -> 9 | I6: =MAX(G6-9,0) - 1 -> 3.5 | J6: =H6*F6 -> 269.19 | K6: =I6*F6*1.2 -> 125.622 | L6: =J6+K6 -> 394.812
A7: Rhoda | B7: 46030 | C7: 9:00AM-7:00PM | D7: 0.375 | E7: 0.99930556 | F7: 29.91 | G7: 15 | H7: =MIN(G7,9) -> 9 | I7: =MAX(G7-9,0) - 1 -> 5 | J7: =H7*F7 -> 269.19 | K7: =I7*F7*1.2 -> 179.46 | L7: =J7+K7 -> 448.65
A8: Rhoda | B8: 46031 | C8: 9:00AM-7:00PM | D8: 0.51041667 | E8: 0.91805556 | F8: 29.91 | G8: =(E8-D8)*24 -> 9.7833333 | H8: =MIN(G8,9) -> 9 | I8: =MAX(G8-9,0) - 1 -> -0.21666667 | J8: =H8*F8 -> 269.19 | L8: =J8+K8 -> 269.19
A9: Rhoda | B9: 46032 | C9: 9:00AM-7:00PM | D9: 0.43402778 | E9: 0.90625 | F9: 29.91 | G9: =(E9-D9)*24 -> 11.333333 | H9: =MIN(G9,9) -> 9 | I9: =MAX(G9-9,0) - 1 -> 1.3333333 | J9: =H9*F9 -> 269.19 | K9: =I9*F9*1.2 -> 47.856 | L9: =J9+K9 -> 317.046
J10: =SUM(J2:J9) -> 2153.52 | K10: =SUM(K2:K9) -> 711.858 | L10: =SUM(L2:L9) -> 3134.188

Sheet Kenneth
A1: Employee | B1: Date | C1: Shift | D1: Time In | E1: Time Out | F1: Hourly Rate | G1: Total Hours | H1: Regular Hours | I1: Overtime Hours | J1: Regular Pay | K1: Overtime Pay | L1: Total Pay
A2: Kenneth | B2: 46027
A3: Kenneth | B3: 46028
A4: Kenneth | B4: 46029
A5: Kenneth | B5: 46030
A6: Kenneth | B6: 46031 | D6: 0.70833333 | E6: 0.9375 | F6: 22.22 | G6: =(E6-D6)*24 -> 5.5 | H6: =MIN(G6,9) -> 5.5 | I6: =MAX(G6-9,0) - 1 -> -1 | J6: =H6*F6 -> 122.21 | L6: =J6+K6 -> 122.21
A7: Kenneth | B7: 46032 | D7: 0.70833333 | E7: 0.91666667 | F7: 22.22 | G7: =(E7-D7)*24 -> 5 | H7: =MIN(G7,9) -> 5 | I7: =MAX(G7-9,0) - 1 -> -1 | J7: =H7*F7 -> 111.1 | L7: =J7+K7 -> 111.1
A8: Kenneth | B8: 46033 | D8: 0.72986111 | E8: 0.91666667 | F8: 22.22 | G8: =(E8-D8)*24 -> 4.4833333 | H8: =MIN(G8,9) -> 4.4833333 | I8: =MAX(G8-9,0) - 1 -> -1 | J8: =H8*F8 -> 99.619667 | L8: =J8+K8 -> 99.619667
L9: =SUM(L6:L8) -> 332.92967
