Workbook

Sheet Payslip
A1: PAYROLL SLIP | D1: PAYROLL SLIP
A2: =Kent!A32 -> Name: | B2: =Kent!B32 -> Kent | D2: ='Jay Anne'!A24 -> Name: | E2: =Micky!B31 -> Micky
A3: =Kent!A33 -> Job Title: | B3: =Kent!B33 -> Cook | D3: ='Jay Anne'!A25 -> Job Title: | E3: =Micky!B32 -> Staff
A4: =Kent!A34 -> Payment Date: | B4: =Kent!B34 -> 46150 | D4: ='Jay Anne'!A26 -> Payment Date: | E4: =Micky!B33 -> 46150
A5: =Kent!A35 -> Cut Off Period: | B5: =Kent!B35 -> May-04 to May-15, 2026 | D5: ='Jay Anne'!A27 -> Cut Off Period: | E5: =Micky!B34 -> May-04 to May-15, 2026
A6: =Kent!A36 -> Days Worked | B6: =Kent!B36 -> 7 | D6: ='Jay Anne'!A28 -> Days Worked | E6: =Micky!B35 -> 8
A7: =Kent!A37 -> Adjustments | D7: ='Jay Anne'!A29 -> Adjustments
A8: =Kent!A38 -> Basic Pay | B8: =Kent!B38 -> 2450 | D8: ='Jay Anne'!A30 -> Basic Pay | E8: =Micky!B37 -> 1931.25
A9: =Kent!A39 -> Bonus/Incentives | B9: =Kent!B39 -> 0 | D9: ='Jay Anne'!A31 -> Bonus/Incentives | E9: =Micky!B38 -> 0
A10: =Kent!A40 -> Overtime Pay | B10: =Kent!B40 -> 1181.25 | D10: ='Jay Anne'!A32 -> Overtime Pay | E10: =Micky!B39 -> 652.5
A11: =Kent!A41 -> Other Income | B11: =Kent!B41 -> 0 | D11: ='Jay Anne'!A33 -> Other Income | E11: =Micky!B40 -> 0
A14: =Kent!A44 -> Gross Pay | B14: =Kent!B44 -> 3631.25 | D14: ='Jay Anne'!A36 -> Gross Pay | E14: =Micky!B43 -> 2583.75
A15: =Kent!A45 -> Deductions | B15: =Kent!B45 -> 0 | D15: ='Jay Anne'!A37 -> Deductions | E15: =Micky!B44 -> 0
A16: =Kent!A46 -> WH Tax | B16: =Kent!B46 -> 0 | D16: ='Jay Anne'!A38 -> WH Tax | E16: =Micky!B45 -> 0
A18: =Kent!A48 -> Net Pay | B18: =Kent!B48 -> 3631.25 | D18: ='Jay Anne'!A40 -> Net Pay | E18: =Micky!B47 -> 2583.75
A21: PAYROLL SLIP | D21: PAYROLL SLIP
A22: =Kris!A31 -> Name: | B22: =Sheen!B32 -> Sheen Valles | D22: =Pepito!A32 -> Name: | E22: =Pepito!B32 -> Pepito
A23: =Kris!A32 -> Job Title: | B23: =Sheen!B33 -> Staff | D23: =Pepito!A33 -> Job Title: | E23: =Pepito!B33 -> Staff
A24: =Kris!A33 -> Payment Date: | B24: =Sheen!B34 -> 46150 | D24: =Pepito!A34 -> Payment Date: | E24: =Pepito!B34 -> 46150
A25: =Kris!A34 -> Cut Off Period: | B25: =Sheen!B35 -> May-04 to May-15, 2026 | D25: =Pepito!A35 -> Cut Off Period: | E25: =Pepito!B35 -> May-04 to May-15, 2026
A26: =Kris!A35 -> Days Worked | B26: =Sheen!B36 -> 8 | D26: =Pepito!A36 -> Days Worked | E26: =Pepito!B36 -> 9
A27: =Kris!A36 -> Adjustments | D27: =Pepito!A37 -> Adjustments
A28: =Kris!A37 -> Basic Pay | B28: =Sheen!B38 -> 1900 | D28: =Pepito!A38 -> Basic Pay | E28: =Pepito!B38 -> 2865.625
A29: =Kris!A38 -> Bonus/Incentives | B29: =Sheen!B39 -> 0 | D29: =Pepito!A39 -> Bonus/Incentives | E29: =Pepito!B39 -> 0
A30: =Kris!A39 -> Overtime Pay | B30: =Sheen!B40 -> 922.5 | D30: =Pepito!A40 -> Overtime Pay | E30: =Pepito!B40 -> 1102.5
A31: =Kris!A40 -> Other Income | B31: =Sheen!B41 -> 0 | D31: =Pepito!A41 -> Other Income | E31: =Pepito!B41 -> 0
A34: =Kris!A43 -> Gross Pay | B34: =Sheen!B44 -> 2822.5 | D34: =Pepito!A44 -> Gross Pay | E34: =Pepito!B44 -> 3968.125
A35: =Kris!A44 -> Deductions | B35: =Sheen!B45 -> 0 | D35: =Pepito!A45 -> Deductions | E35: =Pepito!B45 -> 0
A36: =Kris!A45 -> WH Tax | B36: =Sheen!B46 -> 0 | D36: =Pepito!A46 -> WH Tax | E36: =Pepito!B46 -> 0
A38: =Kris!A47 -> Net Pay | B38: =Sheen!B48 -> 2822.5 | D38: =Pepito!A48 -> Net Pay | E38: =Pepito!B48 -> 3968.125
A42: PAYROLL SLIP | D42: PAYROLL SLIP
A43: =Cherry!A31 -> Name: | B43: =Cherry!B31 -> Cherry | D43: =Kim!A28 -> Name: | E43: =Kim!B28 -> Kim
A44: =Cherry!A32 -> Job Title: | B44: =Cherry!B32 -> Staff | D44: =Kim!A29 -> Job Title: | E44: =Kim!B29 -> Staff
A45: =Cherry!A33 -> Payment Date: | B45: =Cherry!B33 -> 46150 | D45: =Kim!A30 -> Payment Date: | E45: =Kim!B30 -> 46150
A46: =Cherry!A34 -> Cut Off Period: | B46: =Cherry!B34 -> May-04 to May-15, 2026 | D46: =Kim!A31 -> Cut Off Period: | E46: =Kim!B31 -> May-04 to May-15, 2026
A47: =Cherry!A35 -> Days Worked | B47: =Cherry!B35 -> 10 | D47: =Kim!A32 -> Days Worked | E47: =Kim!B32 -> 6
A48: =Cherry!A36 -> Adjustments | D48: =Kim!A33 -> Adjustments
A49: =Cherry!A37 -> Basic Pay | B49: =Cherry!B37 -> 3562.5 | D49: =Kim!A34 -> Basic Pay | E49: =Kim!B34 -> 1859.375
A50: =Cherry!A38 -> Bonus/Incentives | B50: =Cherry!B38 -> 0 | D50: =Kim!A35 -> Bonus/Incentives | E50: =Kim!B35 -> 0
A51: =Cherry!A39 -> Overtime Pay | B51: =Cherry!B39 -> 1828.125 | D51: =Kim!A36 -> Overtime Pay | E51: =Kim!B36 -> 630
...

Sheet Summary
A1: micky harabi | B1: Not Set1 | C1: 2026-05-04 | D1: Missed | E1: Missed
A2: micky harabi | B2: Not Set1 | C2: 2026-05-05 | D2: 08:39 | E2: Missed
A3: micky harabi | B3: Not Set1 | C3: 2026-05-06 | D3: Missed | E3: Missed
A4: micky harabi | B4: Not Set1 | C4: 2026-05-07 | D4: 15:43 | E4: 21:56
A5: micky harabi | B5: Not Set1 | C5: 2026-05-08 | D5: 08:56 | E5: 22:30
A6: micky harabi | B6: Not Set1 | C6: 2026-05-09 | D6: 08:56 | E6: 22:03
A7: micky harabi | B7: Not Set1 | C7: 2026-05-10 | D7: 08:25 | E7: Missed
A8: micky harabi | B8: Not Set1 | C8: 2026-05-11 | D8: 08:59 | E8: 21:52
A9: micky harabi | B9: Not Set1 | C9: 2026-05-12 | D9: 15:20 | E9: 21:47
A10: micky harabi | B10: Not Set1 | C10: 2026-05-13 | D10: 08:31 | E10: Missed
A11: micky harabi | B11: Not Set1 | C11: 2026-05-14 | D11: Missed | E11: Missed
A12: micky harabi | B12: Not Set1 | C12: 2026-05-15 | D12: Missed | E12: Missed
... A108: mark agire | B108: Not Set1 | C108: 2026-05-15 | D108: Missed | E108: 22:07

Sheet Micky
A1: Employee | B1: Shift | C1: Date | D1: Time In | E1: Time Out | F1: Hourly Rate | G1: Total Hours | H1: Regular Hours | I1: Overtime Hours | J1: Regular Pay | K1: Overtime Pay | L1: Total Pay
A2: Micky | B2: 10:00AM-9:00PM | C2: 2026-05-01 | D2: 0 | E2: 0 | F2: 37.5 | G2: =(E2-D2)*24 -> 0 | H2: =MIN(G2,8) -> 0 | I2: =IF(MAX(G2-8,0) - 1 < 0, 0, MAX(G2-8,0) - 1) -> 0 | J2: =H2*F2 -> 0 | K2: =I2*F2*1.2 -> 0 | L2: =J2+K2 -> 0
A3: Micky | B3: 10:00AM-9:00PM | C3: 2026-05-02 | D3: 0 | E3: 0 | F3: 37.5 | G3: =(E3-D3)*24 -> 0 | H3: =MIN(G3,8) -> 0 | I3: =IF(MAX(G3-8,0) - 1 < 0, 0, MAX(G3-8,0) - 1) -> 0 | J3: =H3*F3 -> 0 | K3: =I3*F3*1.2 -> 0 | L3: =J3+K3 -> 0
A4: Micky | B4: 10:00AM-9:00PM | C4: 2026-05-03 | D4: 0 | E4: 0 | F4: 37.5 | G4: =(E4-D4)*24 -> 0 | H4: =MIN(G4,8) -> 0 | I4: =IF(MAX(G4-8,0) - 1 < 0, 0, MAX(G4-8,0) - 1) -> 0 | J4: =H4*F4 -> 0 | K4: =I4*F4*1.2 -> 0 | L4: =J4+K4 -> 0
A5: Micky | B5: 10:00AM-9:00PM | C5: 2026-05-04 | D5: 0 | E5: 0 | F5: 37.5 | G5: =(E5-D5)*24 -> 0 | H5: =MIN(G5,8) -> 0 | I5: =IF(MAX(G5-8,0) - 1 < 0, 0, MAX(G5-8,0) - 1) -> 0 | J5: =H5*F5 -> 0 | K5: =I5*F5*1.2 -> 0 | L5: =J5+K5 -> 0
A6: Micky | B6: 10:00AM-9:00PM | C6: 2026-05-05 | D6: 09:00 | E6: 13:00 | F6: 37.5 | G6: =(E6-D6)*24 -> 4 | H6: =MIN(G6,8) -> 4 | I6: =IF(MAX(G6-8,0) - 1 < 0, 0, MAX(G6-8,0) - 1) -> 0 | J6: =H6*F6 -> 150 | K6: =I6*F6*1.2 -> 0 | L6: =J6+K6 -> 150
A7: Micky | B7: 10:00AM-9:00PM | C7: 2026-05-06 | D7: 0 | E7: 0 | F7: 37.5 | G7: =(E7-D7)*24 -> 0 | H7: =MIN(G7,8) -> 0 | I7: =IF(MAX(G7-8,0) - 1 < 0, 0, MAX(G7-8,0) - 1) -> 0 | J7: =H7*F7 -> 0 | K7: =I7*F7*1.2 -> 0 | L7: =J7+K7 -> 0
A8: Micky | B8: 10:00AM-9:00PM | C8: 2026-05-07 | D8: 17:00 | E8: 21:30 | F8: 37.5 | G8: =(E8-D8)*24 -> 4.5 | H8: =MIN(G8,8) -> 4.5 | I8: =IF(MAX(G8-8,0) - 1 < 0, 0, MAX(G8-8,0) - 1) -> 0 | J8: =H8*F8 -> 168.75 | K8: =I8*F8*1.2 -> 0 | L8: =J8+K8 -> 168.75
A9: Micky | B9: 10:00AM-9:00PM | C9: 2026-05-08 | D9: 09:00 | E9: 22:00 | F9: 37.5 | G9: =(E9-D9)*24 -> 13 | H9: =MIN(G9,8) -> 8 | I9: =IF(MAX(G9-8,0) - 1 < 0, 0, MAX(G9-8,0) - 1) -> 4 | J9: =H9*F9 -> 300 | K9: =I9*F9*1.2 -> 180 | L9: =J9+K9 -> 480
A10: Micky | B10: 10:00AM-9:00PM | C10: 2026-05-09 | D10: 09:00 | E10: 21:30 | F10: 37.5 | G10: =(E10-D10)*24 -> 12.5 | H10: =MIN(G10,8) -> 8 | I10: =IF(MAX(G10-8,0) - 1 < 0, 0, MAX(G10-8,0) - 1) -> 3.5 | J10: =H10*F10 -> 300 | K10: =I10*F10*1.2 -> 157.5 | L10: =J10+K10 -> 457.5
A11: Micky | B11: 10:00AM-9:00PM | C11: 2026-05-10 | D11: 09:00 | E11: 21:30 | F11: 37.5 | G11: =(E11-D11)*24 -> 12.5 | H11: =MIN(G11,8) -> 8 | I11: =IF(MAX(G11-8,0) - 1 < 0, 0, MAX(G11-8,0) - 1) -> 3.5 | J11: =H11*F11 -> 300 | K11: =I11*F11*1.2 -> 157.5 | L11: =J11+K11 -> 457.5
A12: Micky | B12: 10:00AM-9:00PM | C12: 2026-05-11 | D12: 09:00 | E12: 21:30 | F12: 37.5 | G12: =(E12-D12)*24 -> 12.5 | H12: =MIN(G12,8) -> 8 | I12: =IF(MAX(G12-8,0) - 1 < 0, 0, MAX(G12-8,0) - 1) -> 3.5 | J12: =H12*F12 -> 300 | K12: =I12*F12*1.2 -> 157.5 | L12: =J12+K12 -> 457.5
A13: Micky | B13: 10:00AM-9:00PM | C13: 2026-05-12 | D13: 17:00 | E13: 21:30 | F13: 37.5 | G13: =(E13-D13)*24 -> 4.5 | H13: =MIN(G13,8) -> 4.5 | I13: =IF(MAX(G13-8,0) - 1 < 0, 0, MAX(G13-8,0) - 1) -> 0 | J13: =H13*F13 -> 168.75 | K13: =I13*F13*1.2 -> 0 | L13: =J13+K13 -> 168.75
... A16: Micky | B16: 10:00AM-9:00PM | C16: 2026-05-15 | D16: 0 | E16: 0 | F16: 37.5 | G16: =(E16-D16)*24 -> 0 | H16: =MIN(G16,8) -> 0 | I16: =IF(MAX(G16-8,0) - 1 < 0, 0, MAX(G16-8,0) - 1) -> 0 | J16: =H16*F16 -> 0 | K16: =I16*F16*1.2 -> 0 | L16: =J16+K16 -> 0
A21: SUMMARY | B21: REGULAR PAY | C21: OVER TIME PAY | D21: TOTAL PAY
A22: Micky | B22: =SUM(J2:J20) -> 1931.25 | C22: =SUM(K2:K20) -> 652.5 | D22: =SUM(L2:L20) -> 2583.75
A30: PAYROLL SLIP
A31: Name: | B31: =A2 -> Micky
A32: Job Title: | B32: Staff
A33: Payment Date: | B33: =C8+1 -> 46150
A34: Cut Off Period: | B34: =Kent!B35 -> May-04 to May-15, 2026
A35: Days Worked | B35: =COUNTIF(D2:D16, "*:*") -> 8
A36: Adjustments
A37: Basic Pay | B37: =B22 -> 1931.25
A38: Bonus/Incentives | B38: 0
A39: Overtime Pay | B39: =C22 -> 652.5
A40: Other Income | B40: 0
A43: Gross Pay | B43: =D22 -> 2583.75
A44: Deductions | B44: 0
A45: WH Tax | B45: 0
A47: Net Pay | B47: =SUM(B43:B45) -> 2583.75

Sheet Kent
A1: Employee | B1: Shift | C1: Date | D1: Time In | E1: Time Out | F1: Hourly Rate | G1: Total Hours | H1: Regular Hours | I1: Overtime Hours | J1: Regular Pay | K1: Overtime Pay | L1: Total Pay
A2: Kent | B2: 8:30AM-9:00PM | C2: 2026-05-01 | D2: 0 | E2: 0 | F2: 43.75 | G2: =(E2-D2)*24 -> 0 | H2: =MIN(G2,8) -> 0 | I2: =IF(MAX(G2-8,0) - 1 < 0, 0, MAX(G2-8,0) - 1) -> 0 | J2: =H2*F2 -> 0 | K2: =I2*F2*1.2 -> 0 | L2: =J2+K2 -> 0
A3: Kent | B3: 8:30AM-9:00PM | C3: 2026-05-02 | D3: 0 | E3: 0 | F3: 43.75 | G3: =(E3-D3)*24 -> 0 | H3: =MIN(G3,8) -> 0 | I3: =IF(MAX(G3-8,0) - 1 < 0, 0, MAX(G3-8,0) - 1) -> 0 | J3: =H3*F3 -> 0 | K3: =I3*F3*1.2 -> 0 | L3: =J3+K3 -> 0
A4: Kent | B4: 8:30AM-9:00PM | C4: 2026-05-03 | D4: 0 | E4: 0 | F4: 43.75 | G4: =(E4-D4)*24 -> 0 | H4: =MIN(G4,8) -> 0 | I4: =IF(MAX(G4-8,0) - 1 < 0, 0, MAX(G4-8,0) - 1) -> 0 | J4: =H4*F4 -> 0 | K4: =I4*F4*1.2 -> 0 | L4: =J4+K4 -> 0
A5: Kent | B5: 8:30AM-9:00PM | C5: 2026-05-04 | D5: 0 | E5: 0 | F5: 43.75 | G5: =(E5-D5)*24 -> 0 | H5: =MIN(G5,8) -> 0 | I5: =IF(MAX(G5-8,0) - 1 < 0, 0, MAX(G5-8,0) - 1) -> 0 | J5: =H5*F5 -> 0 | K5: =I5*F5*1.2 -> 0 | L5: =J5+K5 -> 0
A6: Kent | B6: 8:30AM-9:00PM | C6: 2026-05-05 | D6: 09:00 | E6: 21:00 | F6: 43.75 | G6: =(E6-D6)*24 -> 12 | H6: =MIN(G6,8) -> 8 | I6: =IF(MAX(G6-8,0) - 1 < 0, 0, MAX(G6-8,0) - 1) -> 3 | J6: =H6*F6 -> 350 | K6: =I6*F6*1.2 -> 157.5 | L6: =J6+K6 -> 507.5
A7: Kent | B7: 8:30AM-9:00PM | C7: 2026-05-06 | D7: 0 | E7: 0 | F7: 43.75 | G7: =(E7-D7)*24 -> 0 | H7: =MIN(G7,8) -> 0 | I7: =IF(MAX(G7-8,0) - 1 < 0, 0, MAX(G7-8,0) - 1) -> 0 | J7: =H7*F7 -> 0 | K7: =I7*F7*1.2 -> 0 | L7: =J7+K7 -> 0
A8: Kent | B8: 8:30AM-9:00PM | C8: 2026-05-07 | D8: 09:00 | E8: 21:00 | F8: 43.75 | G8: =(E8-D8)*24 -> 12 | H8: =MIN(G8,8) -> 8 | I8: =IF(MAX(G8-8,0) - 1 < 0, 0, MAX(G8-8,0) - 1) -> 3 | J8: =H8*F8 -> 350 | K8: =I8*F8*1.2 -> 157.5 | L8: =J8+K8 -> 507.5
A9: Kent | B9: 8:30AM-9:00PM | C9: 2026-05-08 | D9: 0 | E9: 0 | F9: 43.75 | G9: =(E9-D9)*24 -> 0 | H9: =MIN(G9,8) -> 0 | I9: =IF(MAX(G9-8,0) - 1 < 0, 0, MAX(G9-8,0) - 1) -> 0 | J9: =H9*F9 -> 0 | K9: =I9*F9*1.2 -> 0 | L9: =J9+K9 -> 0
A10: Kent | B10: 8:30AM-9:00PM | C10: 2026-05-09 | D10: 09:00 | E10: 21:00 | F10: 43.75 | G10: =(E10-D10)*24 -> 12 | H10: =MIN(G10,8) -> 8 | I10: =IF(MAX(G10-8,0) - 1 < 0, 0, MAX(G10-8,0) - 1) -> 3 | J10: =H10*F10 -> 350 | K10: =I10*F10*1.2 -> 157.5 | L10: =J10+K10 -> 507.5
A11: Kent | B11: 8:30AM-9:00PM | C11: 2026-05-10 | D11: 09:00 | E11: 22:30 | F11: 43.75 | G11: =(E11-D11)*24 -> 13.5 | H11: =MIN(G11,8) -> 8 | I11: =IF(MAX(G11-8,0) - 1 < 0, 0, MAX(G11-8,0) - 1) -> 4.5 | J11: =H11*F11 -> 350 | K11: =I11*F11*1.2 -> 236.25 | L11: =J11+K11 -> 586.25
A12: Kent | B12: 8:30AM-9:00PM | C12: 2026-05-11 | D12: 09:00 | E12: 21:00 | F12: 43.75 | G12: =(E12-D12)*24 -> 12 | H12: =MIN(G12,8) -> 8 | I12: =IF(MAX(G12-8,0) - 1 < 0, 0, MAX(G12-8,0) - 1) -> 3 | J12: =H12*F12 -> 350 | K12: =I12*F12*1.2 -> 157.5 | L12: =J12+K12 -> 507.5
A13: Kent | B13: 8:30AM-9:00PM | C13: 2026-05-12 | D13: 09:00 | E13: 21:00 | F13: 43.75 | G13: =(E13-D13)*24 -> 12 | H13: =MIN(G13,8) -> 8 | I13: =IF(MAX(G13-8,0) - 1 < 0, 0, MAX(G13-8,0) - 1) -> 3 | J13: =H13*F13 -> 350 | K13: =I13*F13*1.2 -> 157.5 | L13: =J13+K13 -> 507.5
... A16: Kent | B16: 8:30AM-9:00PM | C16: 2026-05-15 | D16: 0 | E16: 0 | F16: 43.75 | G16: =(E16-D16)*24 -> 0 | H16: =MIN(G16,8) -> 0 | I16: =IF(MAX(G16-8,0) - 1 < 0, 0, MAX(G16-8,0) - 1) -> 0 | J16: =H16*F16 -> 0 | K16: =I16*F16*1.2 -> 0 | L16: =J16+K16 -> 0
A22: SUMMARY | B22: REGULAR PAY | C22: OVER TIME PAY | D22: TOTAL PAY
A23: Kent | B23: =SUM(J2:J21) -> 2450 | C23: =SUM(K2:K21) -> 1181.25 | D23: =SUM(L2:L21) -> 3631.25
A31: PAYROLL SLIP
A32: Name: | B32: Kent
A33: Job Title: | B33: Cook
A34: Payment Date: | B34: =C8+1 -> 46150
A35: Cut Off Period: | B35: May-04 to May-15, 2026
A36: Days Worked | B36: =COUNTIF(D2:D16, "*:*") -> 7
A37: Adjustments
A38: Basic Pay | B38: =B23 -> 2450
A39: Bonus/Incentives | B39: 0
A40: Overtime Pay | B40: =C23 -> 1181.25
A41: Other Income | B41: 0
A44: Gross Pay | B44: =D23 -> 3631.25
A45: Deductions | B45: 0
A46: WH Tax | B46: 0
A48: Net Pay | B48: =SUM(B44:B46) -> 3631.25

Sheet Sheen
A1: Employee | B1: Shift | C1: Date | D1: Time In | E1: Time Out | F1: Hourly Rate | G1: Total Hours | H1: Regular Hours | I1: Overtime Hours | J1: Regular Pay | K1: Overtime Pay | L1: Total Pay
A2: Sheen Valles | B2: 8:30AM-9:00PM | C2: 2026-05-01 | D2: 0 | E2: 0 | F2: 25 | G2: =(E2-D2)*24 -> 0 | H2: =MIN(G2,8) -> 0 | I2: =IF(MAX(G2-8,0) - 1 < 0, 0, MAX(G2-8,0) - 1) -> 0 | J2: =H2*F2 -> 0 | K2: =I2*F2*1.2 -> 0 | L2: =J2+K2 -> 0
A3: Sheen Valles | B3: 8:30AM-9:00PM | C3: 2026-05-02 | D3: 0 | E3: 0 | F3: 25 | G3: =(E3-D3)*24 -> 0 | H3: =MIN(G3,8) -> 0 | I3: =IF(MAX(G3-8,0) - 1 < 0, 0, MAX(G3-8,0) - 1) -> 0 | J3: =H3*F3 -> 0 | K3: =I3*F3*1.2 -> 0 | L3: =J3+K3 -> 0
A4: Sheen Valles | B4: 8:30AM-9:00PM | C4: 2026-05-03 | D4: 0 | E4: 0 | F4: 25 | G4: =(E4-D4)*24 -> 0 | H4: =MIN(G4,8) -> 0 | I4: =IF(MAX(G4-8,0) - 1 < 0, 0, MAX(G4-8,0) - 1) -> 0 | J4: =H4*F4 -> 0 | K4: =I4*F4*1.2 -> 0 | L4: =J4+K4 -> 0
A5: Sheen Valles | B5: 8:30AM-9:00PM | C5: 2026-05-04 | D5: 09:00 | E5: 21:30 | F5: 25 | G5: =(E5-D5)*24 -> 12.5 | H5: =MIN(G5,8) -> 8 | I5: =IF(MAX(G5-8,0) - 1 < 0, 0, MAX(G5-8,0) - 1) -> 3.5 | J5: =H5*F5 -> 200 | K5: =I5*F5*1.2 -> 105 | L5: =J5+K5 -> 305
A6: Sheen Valles | B6: 8:30AM-9:00PM | C6: 2026-05-05 | D6: 0 | E6: 0 | F6: 25 | G6: =(E6-D6)*24 -> 0 | H6: =MIN(G6,8) -> 0 | I6: =IF(MAX(G6-8,0) - 1 < 0, 0, MAX(G6-8,0) - 1) -> 0 | J6: =H6*F6 -> 0 | K6: =I6*F6*1.2 -> 0 | L6: =J6+K6 -> 0
A7: Sheen Valles | B7: 8:30AM-9:00PM | C7: 2026-05-06 | D7: 0 | E7: 0 | F7: 25 | G7: =(E7-D7)*24 -> 0 | H7: =MIN(G7,8) -> 0 | I7: =IF(MAX(G7-8,0) - 1 < 0, 0, MAX(G7-8,0) - 1) -> 0 | J7: =H7*F7 -> 0 | K7: =I7*F7*1.2 -> 0 | L7: =J7+K7 -> 0
A8: Sheen Valles | B8: 8:30AM-9:00PM | C8: 2026-05-07 | D8: 09:00 | E8: 17:00 | F8: 25 | G8: =(E8-D8)*24 -> 8 | H8: =MIN(G8,8) -> 8 | I8: =IF(MAX(G8-8,0) - 1 < 0, 0, MAX(G8-8,0) - 1) -> 0 | J8: =H8*F8 -> 200 | K8: =I8*F8*1.2 -> 0 | L8: =J8+K8 -> 200
A9: Sheen Valles | B9: 8:30AM-9:00PM | C9: 2026-05-08 | D9: 0 | E9: 0 | F9: 25 | G9: =(E9-D9)*24 -> 0 | H9: =MIN(G9,8) -> 0 | I9: =IF(MAX(G9-8,0) - 1 < 0, 0, MAX(G9-8,0) - 1) -> 0 | J9: =H9*F9 -> 0 | K9: =I9*F9*1.2 -> 0 | L9: =J9+K9 -> 0
A10: Sheen Valles | B10: 8:30AM-9:00PM | C10: 2026-05-09 | D10: 09:00 | E10: 21:30 | F10: 25 | G10: =(E10-D10)*24 -> 12.5 | H10: =MIN(G10,8) -> 8 | I10: =IF(MAX(G10-8,0) - 1 < 0, 0, MAX(G10-8,0) - 1) -> 3.5 | J10: =H10*F10 -> 200 | K10: =I10*F10*1.2 -> 105 | L10: =J10+K10 -> 305
A11: Sheen Valles | B11: 8:30AM-9:00PM | C11: 2026-05-10 | D11: 09:00 | E11: 22:30 | F11: 25 | G11: =(E11-D11)*24 -> 13.5 | H11: =MIN(G11,8) -> 8 | I11: =IF(MAX(G11-8,0) - 1 < 0, 0, MAX(G11-8,0) - 1) -> 4.5 | J11: =H11*F11 -> 200 | K11: =I11*F11*1.2 -> 135 | L11: =J11+K11 -> 335
A12: Sheen Valles | B12: 8:30AM-9:00PM | C12: 2026-05-11 | D12: 09:00 | E12: 21:30 | F12: 25 | G12: =(E12-D12)*24 -> 12.5 | H12: =MIN(G12,8) -> 8 | I12: =IF(MAX(G12-8,0) - 1 < 0, 0, MAX(G12-8,0) - 1) -> 3.5 | J12: =H12*F12 -> 200 | K12: =I12*F12*1.2 -> 105 | L12: =J12+K12 -> 305
A13: Sheen Valles | B13: 8:30AM-9:00PM | C13: 2026-05-12 | D13: 09:00 | E13: 21:30 | F13: 37.5 | G13: =(E13-D13)*24 -> 12.5 | H13: =MIN(G13,8) -> 8 | I13: =IF(MAX(G13-8,0) - 1 < 0, 0, MAX(G13-8,0) - 1) -> 3.5 | J13: =H13*F13 -> 300 | K13: =I13*F13*1.2 -> 157.5 | L13: =J13+K13 -> 457.5
... A16: Sheen Valles | B16: 8:30AM-9:00PM | C16: 2026-05-15 | D16: 09:00 | E16: 21:30 | F16: 37.5 | G16: =(E16-D16)*24 -> 12.5 | H16: =MIN(G16,8) -> 8 | I16: =IF(MAX(G16-8,0) - 1 < 0, 0, MAX(G16-8,0) - 1) -> 3.5 | J16: =H16*F16 -> 300 | K16: =I16*F16*1.2 -> 157.5 | L16: =J16+K16 -> 457.5
A22: SUMMARY | B22: REGULAR PAY | C22: OVER TIME PAY | D22: TOTAL PAY
A23: Sheen Valles | B23: =SUM(J2:J21) -> 1900 | C23: =SUM(K2:K21) -> 922.5 | D23: =SUM(L2:L21) -> 2822.5
A31: PAYROLL SLIP
A32: Name: | B32: =A2 -> Sheen Valles
A33: Job Title: | B33: Staff
A34: Payment Date: | B34: =C8+1 -> 46150
A35: Cut Off Period: | B35: =Kent!B35 -> May-04 to May-15, 2026
A36: Days Worked | B36: =COUNTIF(D2:D16, "*:*") -> 8
A37: Adjustments
A38: Basic Pay | B38: =B23 -> 1900
A39: Bonus/Incentives | B39: 0
A40: Overtime Pay | B40: =C23 -> 922.5
A41: Other Income | B41: 0
A44: Gross Pay | B44: =D23 -> 2822.5
A45: Deductions | B45: 0
A46: WH Tax | B46: 0
A48: Net Pay | B48: =SUM(B44:B46) -> 2822.5

Sheet Cherry
A1: Employee | B1: Shift | C1: Date | D1: Time In | E1: Time Out | F1: Hourly Rate | G1: Total Hours | H1: Regular Hours | I1: Overtime Hours | J1: Regular Pay | K1: Overtime Pay | L1: Total Pay
A2: Cherry | B2: 8:30AM-9:00PM | C2: 2026-05-01 | D2: 0 | E2: 0 | F2: 46.875 | G2: =(E2-D2)*24 -> 0 | H2: =MIN(G2,8) -> 0 | I2: =IF(MAX(G2-8,0) - 1 < 0, 0, MAX(G2-8,0) - 1) -> 0 | J2: =H2*F2 -> 0 | K2: =I2*F2*1.2 -> 0 | L2: =J2+K2 -> 0
A3: Cherry | B3: 8:30AM-9:00PM | C3: 2026-05-02 | D3: 0 | E3: 0 | F3: 46.875 | G3: =(E3-D3)*24 -> 0 | H3: =MIN(G3,8) -> 0 | I3: =IF(MAX(G3-8,0) - 1 < 0, 0, MAX(G3-8,0) - 1) -> 0 | J3: =H3*F3 -> 0 | K3: =I3*F3*1.2 -> 0 | L3: =J3+K3 -> 0
A4: Cherry | B4: 8:30AM-9:00PM | C4: 2026-05-03 | D4: 0 | E4: 0 | F4: 46.875 | G4: =(E4-D4)*24 -> 0 | H4: =MIN(G4,8) -> 0 | I4: =IF(MAX(G4-8,0) - 1 < 0, 0, MAX(G4-8,0) - 1) -> 0 | J4: =H4*F4 -> 0 | K4: =I4*F4*1.2 -> 0 | L4: =J4+K4 -> 0
A5: Cherry | B5: 8:30AM-9:00PM | C5: 2026-05-04 | D5: 09:00 | E5: 21:30 | F5: 46.875 | G5: =(E5-D5)*24 -> 12.5 | H5: =MIN(G5,8) -> 8 | I5: =IF(MAX(G5-8,0) - 1 < 0, 0, MAX(G5-8,0) - 1) -> 3.5 | J5: =H5*F5 -> 375 | K5: =I5*F5*1.2 -> 196.875 | L5: =J5+K5 -> 571.875
A6: Cherry | B6: 8:30AM-9:00PM | C6: 2026-05-05 | D6: 0 | E6: 0 | F6: 46.875 | G6: =(E6-D6)*24 -> 0 | H6: =MIN(G6,8) -> 0 | I6: =IF(MAX(G6-8,0) - 1 < 0, 0, MAX(G6-8,0) - 1) -> 0 | J6: =H6*F6 -> 0 | K6: =I6*F6*1.2 -> 0 | L6: =J6+K6 -> 0
A7: Cherry | B7: 8:30AM-9:00PM | C7: 2026-05-06 | D7: 0 | E7: 0 | F7: 46.875 | G7: =(E7-D7)*24 -> 0 | H7: =MIN(G7,8) -> 0 | I7: =IF(MAX(G7-8,0) - 1 < 0, 0, MAX(G7-8,0) - 1) -> 0 | J7: =H7*F7 -> 0 | K7: =I7*F7*1.2 -> 0 | L7: =J7+K7 -> 0
A8: Cherry | B8: 8:30AM-9:00PM | C8: 2026-05-07 | D8: 09:00 | E8: 21:30 | F8: 46.875 | G8: =(E8-D8)*24 -> 12.5 | H8: =MIN(G8,8) -> 8 | I8: =IF(MAX(G8-8,0) - 1 < 0, 0, MAX(G8-8,0) - 1) -> 3.5 | J8: =H8*F8 -> 375 | K8: =I8*F8*1.2 -> 196.875 | L8: =J8+K8 -> 571.875
A9: Cherry | B9: 8:30AM-9:00PM | C9: 2026-05-08 | D9: 09:00 | E9: 22:00 | F9: 46.875 | G9: =(E9-D9)*24 -> 13 | H9: =MIN(G9,8) -> 8 | I9: =IF(MAX(G9-8,0) - 1 < 0, 0, MAX(G9-8,0) - 1) -> 4 | J9: =H9*F9 -> 375 | K9: =I9*F9*1.2 -> 225 | L9: =J9+K9 -> 600
A10: Cherry | B10: 8:30AM-9:00PM | C10: 2026-05-09 | D10: 09:00 | E10: 21:30 | F10: 46.875 | G10: =(E10-D10)*24 -> 12.5 | H10: =MIN(G10,8) -> 8 | I10: =IF(MAX(G10-8,0) - 1 < 0, 0, MAX(G10-8,0) - 1) -> 3.5 | J10: =H10*F10 -> 375 | K10: =I10*F10*1.2 -> 196.875 | L10: =J10+K10 -> 571.875
A11: Cherry | B11: 8:30AM-9:00PM | C11: 2026-05-10 | D11: 09:00 | E11: 22:30 | F11: 46.875 | G11: =(E11-D11)*24 -> 13.5 | H11: =MIN(G11,8) -> 8 | I11: =IF(MAX(G11-8,0) - 1 < 0, 0, MAX(G11-8,0) - 1) -> 4.5 | J11: =H11*F11 -> 375 | K11: =I11*F11*1.2 -> 253.125 | L11: =J11+K11 -> 628.125
A12: Cherry | B12: 8:30AM-9:00PM | C12: 2026-05-11 | D12: 09:00 | E12: 21:00 | F12: 46.875 | G12: =(E12-D12)*24 -> 12 | H12: =MIN(G12,8) -> 8 | I12: =IF(MAX(G12-8,0) - 1 < 0, 0, MAX(G12-8,0) - 1) -> 3 | J12: =H12*F12 -> 375 | K12: =I12*F12*1.2 -> 168.75 | L12: =J12+K12 -> 543.75
A13: Cherry | B13: 8:30AM-9:00PM | C13: 2026-05-12 | D13: 09:00 | E13: 21:30 | F13: 46.875 | G13: =(E13-D13)*24 -> 12.5 | H13: =MIN(G13,8) -> 8 | I13: =IF(MAX(G13-8,0) - 1 < 0, 0, MAX(G13-8,0) - 1) -> 3.5 | J13: =H13*F13 -> 375 | K13: =I13*F13*1.2 -> 196.875 | L13: =J13+K13 -> 571.875
... A16: Cherry | B16: 8:30AM-9:00PM | C16: 2026-05-15 | D16: 09:00 | E16: 21:30 | F16: 46.875 | G16: =(E16-D16)*24 -> 12.5 | H16: =MIN(G16,8) -> 8 | I16: =IF(MAX(G16-8,0) - 1 < 0, 0, MAX(G16-8,0) - 1) -> 3.5 | J16: =H16*F16 -> 375 | K16: =I16*F16*1.2 -> 196.875 | L16: =J16+K16 -> 571.875
G17: =SUM(G5:G16) -> 117.5 | H17: =MIN(G17,8) -> 8 | I17: =IF(MAX(G17-8,0) - 1 < 0, 0, MAX(G17-8,0) - 1) -> 108.5
A21: SUMMARY | B21: REGULAR PAY | C21: OVER TIME PAY | D21: TOTAL PAY
A22: Cherry | B22: =SUM(J2:J20) -> 3562.5 | C22: =SUM(K2:K20) -> 1828.125 | D22: =SUM(L2:L20) -> 5390.625
A30: PAYROLL SLIP
A31: Name: | B31: =A2 -> Cherry
A32: Job Title: | B32: Staff
A33: Payment Date: | B33: =C8+1 -> 46150
A34: Cut Off Period: | B34: =Kent!B35 -> May-04 to May-15, 2026
A35: Days Worked | B35: =COUNTIF(D2:D16, "*:*") -> 10
A36: Adjustments
A37: Basic Pay | B37: =B22 -> 3562.5
A38: Bonus/Incentives | B38: 0
A39: Overtime Pay | B39: =C22 -> 1828.125
A40: Other Income | B40: 0
A43: Gross Pay | B43: =D22 -> 5390.625
A44: Deductions | B44: 0
A45: WH Tax | B45: 0
A47: Net Pay | B47: =SUM(B43:B45) -> 5390.625

Sheet Pepito
A1: Employee | B1: Shift | C1: Date | D1: Time In | E1: Time Out | F1: Hourly Rate | G1: Total Hours | H1: Regular Hours | I1: Overtime Hours | J1: Regular Pay | K1: Overtime Pay | L1: Total Pay
A2: Pepito | B2: 8:30AM-9:00PM | C2: 2026-05-01 | D2: 0 | E2: 0 | F2: 43.75 | G2: =(E2-D2)*24 -> 0 | H2: =MIN(G2,8) -> 0 | I2: =IF(MAX(G2-8,0) - 1 < 0, 0, MAX(G2-8,0) - 1) -> 0 | J2: =H2*F2 -> 0 | K2: =I2*F2*1.2 -> 0 | L2: =J2+K2 -> 0
A3: Pepito | B3: 8:30AM-9:00PM | C3: 2026-05-02 | D3: 0 | E3: 0 | F3: 43.75 | G3: =(E3-D3)*24 -> 0 | H3: =MIN(G3,8) -> 0 | I3: =IF(MAX(G3-8,0) - 1 < 0, 0, MAX(G3-8,0) - 1) -> 0 | J3: =H3*F3 -> 0 | K3: =I3*F3*1.2 -> 0 | L3: =J3+K3 -> 0
A4: Pepito | B4: 8:30AM-9:00PM | C4: 2026-05-03 | D4: 0 | E4: 0 | F4: 43.75 | G4: =(E4-D4)*24 -> 0 | H4: =MIN(G4,8) -> 0 | I4: =IF(MAX(G4-8,0) - 1 < 0, 0, MAX(G4-8,0) - 1) -> 0 | J4: =H4*F4 -> 0 | K4: =I4*F4*1.2 -> 0 | L4: =J4+K4 -> 0
A5: Pepito | B5: 8:30AM-9:00PM | C5: 2026-05-04 | D5: 09:00 | E5: 21:00 | F5: 43.75 | G5: =(E5-D5)*24 -> 12 | H5: =MIN(G5,8) -> 8 | I5: =IF(MAX(G5-8,0) - 1 < 0, 0, MAX(G5-8,0) - 1) -> 3 | J5: =H5*F5 -> 350 | K5: =I5*F5*1.2 -> 157.5 | L5: =J5+K5 -> 507.5
A6: Pepito | B6: 8:30AM-9:00PM | C6: 2026-05-05 | D6: 09:00 | E6: 21:00 | F6: 43.75 | G6: =(E6-D6)*24 -> 12 | H6: =MIN(G6,8) -> 8 | I6: =IF(MAX(G6-8,0) - 1 < 0, 0, MAX(G6-8,0) - 1) -> 3 | J6: =H6*F6 -> 350 | K6: =I6*F6*1.2 -> 157.5 | L6: =J6+K6 -> 507.5
A7: Pepito | B7: 8:30AM-9:00PM | C7: 2026-05-06 | D7: 0 | E7: 0 | F7: 43.75 | G7: =(E7-D7)*24 -> 0 | H7: =MIN(G7,8) -> 0 | I7: =IF(MAX(G7-8,0) - 1 < 0, 0, MAX(G7-8,0) - 1) -> 0 | J7: =H7*F7 -> 0 | K7: =I7*F7*1.2 -> 0 | L7: =J7+K7 -> 0
A8: Pepito | B8: 8:30AM-9:00PM | C8: 2026-05-07 | D8: 0 | E8: 0 | F8: 43.75 | G8: =(E8-D8)*24 -> 0 | H8: =MIN(G8,8) -> 0 | I8: =IF(MAX(G8-8,0) - 1 < 0, 0, MAX(G8-8,0) - 1) -> 0 | J8: =H8*F8 -> 0 | K8: =I8*F8*1.2 -> 0 | L8: =J8+K8 -> 0
A9: Pepito | B9: 8:30AM-9:00PM | C9: 2026-05-08 | D9: 09:00 | E9: 21:00 | F9: 43.75 | G9: =(E9-D9)*24 -> 12 | H9: =MIN(G9,8) -> 8 | I9: =IF(MAX(G9-8,0) - 1 < 0, 0, MAX(G9-8,0) - 1) -> 3 | J9: =H9*F9 -> 350 | K9: =I9*F9*1.2 -> 157.5 | L9: =J9+K9 -> 507.5
A10: Pepito | B10: 8:30AM-9:00PM | C10: 2026-05-09 | D10: 09:00 | E10: 21:00 | F10: 43.75 | G10: =(E10-D10)*24 -> 12 | H10: =MIN(G10,8) -> 8 | I10: =IF(MAX(G10-8,0) - 1 < 0, 0, MAX(G10-8,0) - 1) -> 3 | J10: =H10*F10 -> 350 | K10: =I10*F10*1.2 -> 157.5 | L10: =J10+K10 -> 507.5
A11: Pepito | B11: 8:30AM-9:00PM | C11: 2026-05-10 | D11: 17:00 | E11: 21:30 | F11: 43.75 | G11: =(E11-D11)*24 -> 4.5 | H11: =MIN(G11,8) -> 4.5 | I11: =IF(MAX(G11-8,0) - 1 < 0, 0, MAX(G11-8,0) - 1) -> 0 | J11: =H11*F11 -> 196.875 | K11: =I11*F11*1.2 -> 0 | L11: =J11+K11 -> 196.875
A12: Pepito | B12: 8:30AM-9:00PM | C12: 2026-05-11 | D12: 09:00 | E12: 21:00 | F12: 43.75 | G12: =(E12-D12)*24 -> 12 | H12: =MIN(G12,8) -> 8 | I12: =IF(MAX(G12-8,0) - 1 < 0, 0, MAX(G12-8,0) - 1) -> 3 | J12: =H12*F12 -> 350 | K12: =I12*F12*1.2 -> 157.5 | L12: =J12+K12 -> 507.5
A13: Pepito | B13: 8:30AM-9:00PM | C13: 2026-05-12 | D13: 09:00 | E13: 21:00 | F13: 43.75 | G13: =(E13-D13)*24 -> 12 | H13: =MIN(G13,8) -> 8 | I13: =IF(MAX(G13-8,0) - 1 < 0, 0, MAX(G13-8,0) - 1) -> 3 | J13: =H13*F13 -> 350 | K13: =I13*F13*1.2 -> 157.5 | L13: =J13+K13 -> 507.5
... A16: Pepito | B16: 8:30AM-9:00PM | C16: 2026-05-15 | D16: 09:00 | E16: 14:00 | F16: 43.75 | G16: =(E16-D16)*24 -> 5 | H16: =MIN(G16,8) -> 5 | I16: =IF(MAX(G16-8,0) - 1 < 0, 0, MAX(G16-8,0) - 1) -> 0 | J16: =H16*F16 -> 218.75 | K16: =I16*F16*1.2 -> 0 | L16: =J16+K16 -> 218.75
A22: SUMMARY | B22: REGULAR PAY | C22: OVER TIME PAY | D22: TOTAL PAY
A23: Pepito | B23: =SUM(J2:J21) -> 2865.625 | C23: =SUM(K2:K21) -> 1102.5 | D23: =SUM(L2:L21) -> 3968.125
A31: PAYROLL SLIP
A32: Name: | B32: Pepito
A33: Job Title: | B33: Staff
A34: Payment Date: | B34: =C8+1 -> 46150
A35: Cut Off Period: | B35: =Kent!B35 -> May-04 to May-15, 2026
A36: Days Worked | B36: =COUNTIF(D2:D16, "*:*") -> 9
A37: Adjustments
A38: Basic Pay | B38: =B23 -> 2865.625
A39: Bonus/Incentives | B39: 0
A40: Overtime Pay | B40: =C23 -> 1102.5
A41: Other Income | B41: 0
A44: Gross Pay | B44: =D23 -> 3968.125
A45: Deductions | B45: 0
A46: WH Tax | B46: 0
A48: Net Pay | B48: =SUM(B44:B46) -> 3968.125

Sheet Mark
A1: Employee | B1: Shift | C1: Date | D1: Time In | E1: Time Out | F1: Hourly Rate | G1: Total Hours | H1: Regular Hours | I1: Overtime Hours | J1: Regular Pay | K1: Overtime Pay | L1: Total Pay
A2: Mark | B2: 9:00AM-9:00PM | C2: 2026-05-01 | D2: 0 | E2: 0 | F2: 43.75 | G2: =(E2-D2)*24 -> 0 | H2: =MIN(G2,8) -> 0 | I2: =IF(MAX(G2-8,0) - 1 < 0, 0, MAX(G2-8,0) - 1) -> 0 | J2: =H2*F2 -> 0 | K2: =I2*F2*1.2 -> 0 | L2: =J2+K2 -> 0
A3: Mark | B3: 9:00AM-9:00PM | C3: 2026-05-02 | D3: 0 | E3: 0 | F3: 43.75 | G3: =(E3-D3)*24 -> 0 | H3: =MIN(G3,8) -> 0 | I3: =IF(MAX(G3-8,0) - 1 < 0, 0, MAX(G3-8,0) - 1) -> 0 | J3: =H3*F3 -> 0 | K3: =I3*F3*1.2 -> 0 | L3: =J3+K3 -> 0
A4: Mark | B4: 9:00AM-9:00PM | C4: 2026-05-03 | D4: 0 | E4: 0 | F4: 43.75 | G4: =(E4-D4)*24 -> 0 | H4: =MIN(G4,8) -> 0 | I4: =IF(MAX(G4-8,0) - 1 < 0, 0, MAX(G4-8,0) - 1) -> 0 | J4: =H4*F4 -> 0 | K4: =I4*F4*1.2 -> 0 | L4: =J4+K4 -> 0
A5: Mark | B5: 9:00AM-9:00PM | C5: 2026-05-04 | D5: 10:10 | E5: 22:17 | F5: 43.75 | G5: =(E5-D5)*24 -> 12.116667 | H5: =MIN(G5,8) -> 8 | I5: =IF(MAX(G5-8,0) - 1 < 0, 0, MAX(G5-8,0) - 1) -> 3.1166667 | J5: =H5*F5 -> 350 | K5: =I5*F5*1.2 -> 163.625 | L5: =J5+K5 -> 513.625
A6: Mark | B6: 9:00AM-9:00PM | C6: 2026-05-05 | D6: 0 | E6: 0 | F6: 43.75 | G6: =(E6-D6)*24 -> 0 | H6: =MIN(G6,8) -> 0 | I6: =IF(MAX(G6-8,0) - 1 < 0, 0, MAX(G6-8,0) - 1) -> 0 | J6: =H6*F6 -> 0 | K6: =I6*F6*1.2 -> 0 | L6: =J6+K6 -> 0
A7: Mark | B7: 9:00AM-9:00PM | C7: 2026-05-06 | D7: 13:00 | E7: 21:00 | F7: 43.75 | G7: =(E7-D7)*24 -> 8 | H7: =MIN(G7,8) -> 8 | I7: =IF(MAX(G7-8,0) - 1 < 0, 0, MAX(G7-8,0) - 1) -> 0 | J7: =H7*F7 -> 350 | K7: =I7*F7*1.2 -> 0 | L7: =J7+K7 -> 350
A8: Mark | B8: 9:00AM-9:00PM | C8: 2026-05-07 | D8: 9:00 | E8: 17:00 | F8: 43.75 | G8: =(E8-D8)*24 -> 8 | H8: =MIN(G8,8) -> 8 | I8: =IF(MAX(G8-8,0) - 1 < 0, 0, MAX(G8-8,0) - 1) -> 0 | J8: =H8*F8 -> 350 | K8: =I8*F8*1.2 -> 0 | L8: =J8+K8 -> 350
A9: Mark | B9: 9:00AM-9:00PM | C9: 2026-05-08 | D9: 10:00 | E9: 21:00 | F9: 43.75 | G9: =(E9-D9)*24 -> 11 | H9: =MIN(G9,8) -> 8 | I9: =IF(MAX(G9-8,0) - 1 < 0, 0, MAX(G9-8,0) - 1) -> 2 | J9: =H9*F9 -> 350 | K9: =I9*F9*1.2 -> 105 | L9: =J9+K9 -> 455
A10: Mark | B10: 9:00AM-9:00PM | C10: 2026-05-09 | D10: 9:00 | E10: 22:30 | F10: 43.75 | G10: =(E10-D10)*24 -> 13.5 | H10: =MIN(G10,8) -> 8 | I10: =IF(MAX(G10-8,0) - 1 < 0, 0, MAX(G10-8,0) - 1) -> 4.5 | J10: =H10*F10 -> 350 | K10: =I10*F10*1.2 -> 236.25 | L10: =J10+K10 -> 586.25
A11: Mark | B11: 9:00AM-9:00PM | C11: 2026-05-10 | D11: 10:00 | E11: 17:41 | F11: 43.75 | G11: =(E11-D11)*24 -> 7.6833333 | H11: =MIN(G11,8) -> 7.6833333 | I11: =IF(MAX(G11-8,0) - 1 < 0, 0, MAX(G11-8,0) - 1) -> 0 | J11: =H11*F11 -> 336.14583 | K11: =I11*F11*1.2 -> 0 | L11: =J11+K11 -> 336.14583
A12: Mark | B12: 9:00AM-9:00PM | C12: 2026-05-11 | D12: 10:23 | E12: 21:50 | F12: 43.75 | G12: =(E12-D12)*24 -> 11.45 | H12: =MIN(G12,8) -> 8 | I12: =IF(MAX(G12-8,0) - 1 < 0, 0, MAX(G12-8,0) - 1) -> 2.45 | J12: =H12*F12 -> 350 | K12: =I12*F12*1.2 -> 128.625 | L12: =J12+K12 -> 478.625
A13: Mark | B13: 9:00AM-9:00PM | C13: 2026-05-12 | D13: 10:00 | E13: 22:16 | F13: 43.75 | G13: =(E13-D13)*24 -> 12.266667 | H13: =MIN(G13,8) -> 8 | I13: =IF(MAX(G13-8,0) - 1 < 0, 0, MAX(G13-8,0) - 1) -> 3.2666667 | J13: =H13*F13 -> 350 | K13: =I13*F13*1.2 -> 171.5 | L13: =J13+K13 -> 521.5
... A16: Mark | B16: 9:00AM-9:00PM | C16: 2026-05-15 | D16: 10:00 | E16: 22:07 | F16: 43.75 | G16: =(E16-D16)*24 -> 12.116667 | H16: =MIN(G16,8) -> 8 | I16: =IF(MAX(G16-8,0) - 1 < 0, 0, MAX(G16-8,0) - 1) -> 3.1166667 | J16: =H16*F16 -> 350 | K16: =I16*F16*1.2 -> 163.625 | L16: =J16+K16 -> 513.625
A22: SUMMARY | B22: REGULAR PAY | C22: OVER TIME PAY | D22: TOTAL PAY
A23: Mark | B23: =SUM(J2:J21) -> 3836.1458 | C23: =SUM(K2:K21) -> 1261.75 | D23: =SUM(L2:L21) -> 5097.8958
A31: PAYROLL SLIP
A32: Name: | B32: =A2 -> Mark
A33: Job Title: | B33: Staff
A34: Payment Date: | B34: =C8+1 -> 46150
A35: Cut Off Period: | B35: =Kent!B35 -> May-04 to May-15, 2026
A36: Days Worked | B36: =COUNTIF(D2:D16, "*:*") -> 11
A37: Adjustments
A38: Basic Pay | B38: =B23 -> 3836.1458
A39: Bonus/Incentives | B39: 0
A40: Overtime Pay | B40: =C23 -> 1261.75
A41: Other Income | B41: 315
A44: Gross Pay | B44: =SUM(B38:B41) -> 5412.8958
A45: Deductions | B45: 0
A46: WH Tax | B46: 0
A48: Net Pay | B48: =SUM(B44:B46) -> 5412.8958

Sheet Kim
A1: Employee | B1: Shift | C1: Date | D1: Time In | E1: Time Out | F1: Hourly Rate | G1: Total Hours | H1: Regular Hours | I1: Overtime Hours | J1: Regular Pay | K1: Overtime Pay | L1: Total Pay
A2: Kim | B2: 10:00AM-9:00PM | C2: 2026-05-01 | D2: 0 | E2: 0 | F2: 43.75 | G2: =(E2-D2)*24 -> 0 | H2: =MIN(G2,8) -> 0 | I2: =IF(MAX(G2-8,0) - 1 < 0, 0, MAX(G2-8,0) - 1) -> 0 | J2: =H2*F2 -> 0 | K2: =I2*F2*1.2 -> 0 | L2: =J2+K2 -> 0
A3: Kim | B3: 10:00AM-9:00PM | C3: 2026-05-02 | D3: 0 | E3: 0 | F3: 43.75 | G3: =(E3-D3)*24 -> 0 | H3: =MIN(G3,8) -> 0 | I3: =IF(MAX(G3-8,0) - 1 < 0, 0, MAX(G3-8,0) - 1) -> 0 | J3: =H3*F3 -> 0 | K3: =I3*F3*1.2 -> 0 | L3: =J3+K3 -> 0
A4: Kim | B4: 10:00AM-9:00PM | C4: 2026-05-03 | D4: 0 | E4: 0 | F4: 43.75 | G4: =(E4-D4)*24 -> 0 | H4: =MIN(G4,8) -> 0 | I4: =IF(MAX(G4-8,0) - 1 < 0, 0, MAX(G4-8,0) - 1) -> 0 | J4: =H4*F4 -> 0 | K4: =I4*F4*1.2 -> 0 | L4: =J4+K4 -> 0
A5: Kim | B5: 10:00AM-9:00PM | C5: 2026-05-04 | D5: 0 | E5: 0 | F5: 43.75 | G5: =(E5-D5)*24 -> 0 | H5: =MIN(G5,8) -> 0 | I5: =IF(MAX(G5-8,0) - 1 < 0, 0, MAX(G5-8,0) - 1) -> 0 | J5: =H5*F5 -> 0 | K5: =I5*F5*1.2 -> 0 | L5: =J5+K5 -> 0
A6: Kim | B6: 10:00AM-9:00PM | C6: 2026-05-05 | D6: 8:00 | E6: 17:00 | F6: 43.75 | G6: =(E6-D6)*24 -> 9 | H6: =MIN(G6,8) -> 8 | I6: =IF(MAX(G6-8,0) - 1 < 0, 0, MAX(G6-8,0) - 1) -> 1.7763568e-15 | J6: =H6*F6 -> 350 | K6: =I6*F6*1.2 -> 9.3258734e-14 | L6: =J6+K6 -> 350
A7: Kim | B7: 10:00AM-9:00PM | C7: 2026-05-06 | D7: 0 | E7: 0 | F7: 43.75 | G7: =(E7-D7)*24 -> 0 | H7: =MIN(G7,9) -> 0 | I7: =IF(MAX(G7-8,0) - 1 < 0, 0, MAX(G7-8,0) - 1) -> 0 | J7: =H7*F7 -> 0 | K7: =I7*F7*1.2 -> 0 | L7: =J7+K7 -> 0
A8: Kim | B8: 10:00AM-9:00PM | C8: 2026-05-07 | D8: 8:00 | E8: 22:00 | F8: 43.75 | G8: =(E8-D8)*24 -> 14 | H8: =MIN(G8,9) -> 9 | I8: =IF(MAX(G8-8,0) - 1 < 0, 0, MAX(G8-8,0) - 1) -> 5 | J8: =H8*F8 -> 393.75 | K8: =I8*F8*1.2 -> 262.5 | L8: =J8+K8 -> 656.25
A9: Kim | B9: 10:00AM-9:00PM | C9: 2026-05-08 | D9: 8:00 | E9: 9:30 | F9: 43.75 | G9: =(E9-D9)*24 -> 1.5 | H9: =MIN(G9,8) -> 1.5 | I9: =IF(MAX(G9-8,0) - 1 < 0, 0, MAX(G9-8,0) - 1) -> 0 | J9: =H9*F9 -> 65.625 | K9: =I9*F9*1.2 -> 0 | L9: =J9+K9 -> 65.625
A10: Kim | B10: 10:00AM-9:00PM | C10: 2026-05-09 | D10: 8:00 | E10: 22:30 | F10: 43.75 | G10: =(E10-D10)*24 -> 14.5 | H10: =MIN(G10,8) -> 8 | I10: =IF(MAX(G10-8,0) - 1 < 0, 0, MAX(G10-8,0) - 1) -> 5.5 | J10: =H10*F10 -> 350 | K10: =I10*F10*1.2 -> 288.75 | L10: =J10+K10 -> 638.75
A11: Kim | B11: 10:00AM-9:00PM | C11: 2026-05-10 | D11: 0 | E11: 0 | F11: 43.75 | G11: =(E11-D11)*24 -> 0 | H11: =MIN(G11,8) -> 0 | I11: =IF(MAX(G11-8,0) - 1 < 0, 0, MAX(G11-8,0) - 1) -> 0 | J11: =H11*F11 -> 0 | K11: =I11*F11*1.2 -> 0 | L11: =J11+K11 -> 0
A12: Kim | B12: 10:00AM-9:00PM | C12: 2026-05-11 | D12: 8:00 | E12: 17:00 | F12: 43.75 | G12: =(E12-D12)*24 -> 9 | H12: =MIN(G12,8) -> 8 | I12: =IF(MAX(G12-8,0) - 1 < 0, 0, MAX(G12-8,0) - 1) -> 1.7763568e-15 | J12: =H12*F12 -> 350 | K12: =I12*F12*1.2 -> 9.3258734e-14 | L12: =J12+K12 -> 350
A13: Kim | B13: 10:00AM-9:00PM | C13: 2026-05-12 | D13: 8:00 | E13: 18:30 | F13: 43.75 | G13: =(E13-D13)*24 -> 10.5 | H13: =MIN(G13,8) -> 8 | I13: =IF(MAX(G13-8,0) - 1 < 0, 0, MAX(G13-8,0) - 1) -> 1.5 | J13: =H13*F13 -> 350 | K13: =I13*F13*1.2 -> 78.75 | L13: =J13+K13 -> 428.75
A14: Kim | B14: 10:00AM-9:00PM | C14: 2026-05-13 | D14: 0 | E14: 0 | F14: 43.75 | G14: =(E14-D14)*24 -> 0 | H14: =MIN(G14,9) -> 0 | I14: =IF(MAX(G14-8,0) - 1 < 0, 0, MAX(G14-8,0) - 1) -> 0 | J14: =H14*F14 -> 0 | K14: =I14*F14*1.2 -> 0 | L14: =J14+K14 -> 0
A15: Kim | B15: 10:00AM-9:00PM | C15: 2026-05-14 | D15: 0 | E15: 0 | F15: 43.75 | G15: =(E15-D15)*24 -> 0 | H15: =MIN(G15,9) -> 0 | I15: =IF(MAX(G15-8,0) - 1 < 0, 0, MAX(G15-8,0) - 1) -> 0 | J15: =H15*F15 -> 0 | K15: =I15*F15*1.2 -> 0 | L15: =J15+K15 -> 0
A16: Kim | B16: 10:00AM-9:00PM | C16: 2026-05-15 | D16: 0 | E16: 0 | F16: 43.75 | G16: =(E16-D16)*24 -> 0 | H16: =MIN(G16,9) -> 0 | I16: =IF(MAX(G16-8,0) - 1 < 0, 0, MAX(G16-8,0) - 1) -> 0 | J16: =H16*F16 -> 0 | K16: =I16*F16*1.2 -> 0 | L16: =J16+K16 -> 0
A22: SUMMARY | B22: REGULAR PAY | C22: OVER TIME PAY | D22: TOTAL PAY
A23: Kim | B23: =SUM(J2:J21) -> 1859.375 | C23: =SUM(K2:K21) -> 630 | D23: =SUM(L2:L21) -> 2489.375
A27: PAYROLL SLIP
A28: Name: | B28: =A2 -> Kim
A29: Job Title: | B29: Staff
A30: Payment Date: | B30: =C8+1 -> 46150
A31: Cut Off Period: | B31: =Kent!B35 -> May-04 to May-15, 2026
A32: Days Worked | B32: =COUNTIF(D2:D16, "*:*") -> 6
A33: Adjustments
A34: Basic Pay | B34: =B23 -> 1859.375
A35: Bonus/Incentives | B35: 0
A36: Overtime Pay | B36: =C23 -> 630
A37: Other Income | B37: 0
A40: Gross Pay | B40: =D23 -> 2489.375
A41: Deductions | B41: 0
A42: WH Tax | B42: 0
A44: Net Pay | B44: =SUM(B40:B42) -> 2489.375

Sheet David
A1: Employee | B1: Shift | C1: Date | D1: Time In | E1: Time Out | F1: Hourly Rate | G1: Total Hours | H1: Regular Hours | I1: Overtime Hours | J1: Regular Pay | K1: Overtime Pay | L1: Total Pay
A2: David | B2: 5:00PM-10:00PM | C2: 2026-02-09 | D2: 09:00 | E2: 0 | L2: 420
A3: David | B3: 5:00PM-10:00PM | C3: 2026-02-10 | D3: 09:01 | E3: 0 | L3: 520
A4: David | B4: 5:00PM-10:00PM | C4: 2026-02-11 | D4: 09:02 | E4: 0 | L4: 400
A5: David | B5: 5:00PM-10:00PM | C5: 2026-02-12 | D5: 09:03 | E5: 0 | L5: 400
A6: David | B6: 5:00PM-10:00PM | C6: 2026-02-13 | D6: 09:04 | E6: 0 | L6: 400
A7: David | B7: 9:30AM-10:00PM | C7: 2026-02-14 | D7: 09:05 | E7: 0 | L7: 430
A8: David | B8: 9:30AM-10:00PM | C8: 2026-02-15 | D8: 0 | E8: 0 | L8: 0
A14: SUMMARY | B14: REGULAR PAY | C14: OVER TIME PAY | D14: TOTAL PAY
A15: Lenard | B15: =SUM(J2:J13) -> 0 | C15: =SUM(K2:K13) -> 0 | D15: =SUM(L2:L13) -> 2570
A23: PAYROLL SLIP
A24: Name: | B24: =A2 -> David
A25: Job Title: | B25: Staff
A26: Payment Date: | B26: =C8+1 -> 46069
A27: Cut Off Period: | B27: =Kent!B35 -> May-04 to May-15, 2026
A28: Days Worked | B28: =COUNTIF(D2:D8, "*:*") -> 6
A29: Adjustments
A30: Basic Pay | B30: =B15 -> 0
A31: Bonus/Incentives | B31: 0
A32: Overtime Pay | B32: =C15 -> 0
A33: Other Income | B33: 0
A36: Gross Pay | B36: =D15 -> 2570
A37: Deductions | B37: 0
A38: WH Tax | B38: 0
A40: Net Pay | B40: =SUM(B36:B38) -> 2570

Sheet Kris
A1: Employee | B1: Shift | C1: Date | D1: Time In | E1: Time Out | F1: Hourly Rate | G1: Total Hours | H1: Regular Hours | I1: Overtime Hours | J1: Regular Pay | K1: Overtime Pay | L1: Total Pay
A2: Kris Naynayan | B2: 8:30AM-9:00PM | C2: 2026-04-27 | D2: 0 | E2: 0 | F2: 40.86 | G2: =(E2-D2)*24 -> 0 | H2: =MIN(G2,8) -> 0 | I2: =IF(MAX(G2-8,0) - 1 < 0, 0, MAX(G2-8,0) - 1) -> 0 | J2: =H2*F2 -> 0 | K2: =I2*F2*1.2 -> 0 | L2: =J2+K2 -> 0
A3: Kris Naynayan | B3: 8:30AM-9:00PM | C3: 2026-04-21 | D3: 0 | E3: 0 | F3: 40.86 | G3: =(E3-D3)*24 -> 0 | H3: =MIN(G3,8) -> 0 | I3: =IF(MAX(G3-8,0) - 1 < 0, 0, MAX(G3-8,0) - 1) -> 0 | J3: =H3*F3 -> 0 | K3: =I3*F3*1.2 -> 0 | L3: =J3+K3 -> 0
A4: Kris Naynayan | B4: 8:30AM-9:00PM | C4: 2026-04-22 | D4: 0 | E4: 0 | F4: 40.86 | G4: =(E4-D4)*24 -> 0 | H4: =MIN(G4,8) -> 0 | I4: =IF(MAX(G4-8,0) - 1 < 0, 0, MAX(G4-8,0) - 1) -> 0 | J4: =H4*F4 -> 0 | K4: =I4*F4*1.2 -> 0 | L4: =J4+K4 -> 0
A5: Kris Naynayan | B5: 8:30AM-9:00PM | C5: 2026-04-23 | D5: 0 | E5: 0 | F5: 40.86 | G5: =(E5-D5)*24 -> 0 | H5: =MIN(G5,8) -> 0 | I5: =IF(MAX(G5-8,0) - 1 < 0, 0, MAX(G5-8,0) - 1) -> 0 | J5: =H5*F5 -> 0 | K5: =I5*F5*1.2 -> 0 | L5: =J5+K5 -> 0
A6: Kris Naynayan | B6: 8:30AM-9:00PM | C6: 2026-04-24 | D6: 0 | E6: 0 | F6: 40.86 | G6: =(E6-D6)*24 -> 0 | H6: =MIN(G6,8) -> 0 | I6: =IF(MAX(G6-8,0) - 1 < 0, 0, MAX(G6-8,0) - 1) -> 0 | J6: =H6*F6 -> 0 | K6: =I6*F6*1.2 -> 0 | L6: =J6+K6 -> 0
A7: Kris Naynayan | B7: 8:30AM-9:00PM | C7: 2026-04-25 | D7: 0 | E7: 0 | F7: 40.86 | G7: =(E7-D7)*24 -> 0 | H7: =MIN(G7,8) -> 0 | I7: =IF(MAX(G7-8,0) - 1 < 0, 0, MAX(G7-8,0) - 1) -> 0 | J7: =H7*F7 -> 0 | K7: =I7*F7*1.2 -> 0 | L7: =J7+K7 -> 0
A8: Kris Naynayan | B8: 8:30AM-9:00PM | C8: 2026-04-26 | D8: 0 | E8: 0 | F8: 40.86 | G8: =(E8-D8)*24 -> 0 | H8: =MIN(G8,8) -> 0 | I8: =IF(MAX(G8-8,0) - 1 < 0, 0, MAX(G8-8,0) - 1) -> 0 | J8: =H8*F8 -> 0 | K8: =I8*F8*1.2 -> 0 | L8: =J8+K8 -> 0
A9: Kris Naynayan | B9: 8:30AM-9:00PM | C9: 2026-04-27 | D9: 08:00 | E9: 17:00 | F9: 40.86 | G9: =(E9-D9)*24 -> 9 | H9: =MIN(G9,8) -> 8 | I9: =IF(MAX(G9-8,0) - 1 < 0, 0, MAX(G9-8,0) - 1) -> 1.7763568e-15 | J9: =H9*F9 -> 326.88 | K9: =I9*F9*1.2 -> 8.7098329e-14 | L9: =J9+K9 -> 326.88
A10: Kris Naynayan | B10: 8:30AM-9:00PM | C10: 2026-04-21 | D10: 0 | E10: 0 | F10: 40.86 | G10: =(E10-D10)*24 -> 0 | H10: =MIN(G10,8) -> 0 | I10: =IF(MAX(G10-8,0) - 1 < 0, 0, MAX(G10-8,0) - 1) -> 0 | J10: =H10*F10 -> 0 | K10: =I10*F10*1.2 -> 0 | L10: =J10+K10 -> 0
A11: Kris Naynayan | B11: 8:30AM-9:00PM | C11: 2026-04-22 | D11: 0 | E11: 0 | F11: 40.86 | G11: =(E11-D11)*24 -> 0 | H11: =MIN(G11,8) -> 0 | I11: =IF(MAX(G11-8,0) - 1 < 0, 0, MAX(G11-8,0) - 1) -> 0 | J11: =H11*F11 -> 0 | K11: =I11*F11*1.2 -> 0 | L11: =J11+K11 -> 0
A12: Kris Naynayan | B12: 8:30AM-9:00PM | C12: 2026-04-23 | D12: 0 | E12: 0 | F12: 40.86 | G12: =(E12-D12)*24 -> 0 | H12: =MIN(G12,8) -> 0 | I12: =IF(MAX(G12-8,0) - 1 < 0, 0, MAX(G12-8,0) - 1) -> 0 | J12: =H12*F12 -> 0 | K12: =I12*F12*1.2 -> 0 | L12: =J12+K12 -> 0
A13: Kris Naynayan | B13: 8:30AM-9:00PM | C13: 2026-04-24 | D13: 0 | E13: 0 | F13: 40.86 | G13: =(E13-D13)*24 -> 0 | H13: =MIN(G13,8) -> 0 | I13: =IF(MAX(G13-8,0) - 1 < 0, 0, MAX(G13-8,0) - 1) -> 0 | J13: =H13*F13 -> 0 | K13: =I13*F13*1.2 -> 0 | L13: =J13+K13 -> 0
... A16: Kris Naynayan | B16: 8:30AM-9:00PM | C16: 2026-04-26 | D16: 0 | E16: 0 | F16: 40.86 | G16: =(E16-D16)*24 -> 0 | H16: =MIN(G16,8) -> 0 | I16: =IF(MAX(G16-8,0) - 1 < 0, 0, MAX(G16-8,0) - 1) -> 0 | J16: =H16*F16 -> 0 | K16: =I16*F16*1.2 -> 0 | L16: =J16+K16 -> 0
A21: SUMMARY | B21: REGULAR PAY | C21: OVER TIME PAY | D21: TOTAL PAY
A22: Kris Naynayan | B22: =SUM(J2:J20) -> 326.88 | C22: =SUM(K2:K20) -> 8.7098329e-14 | D22: =SUM(L2:L20) -> 326.88
A30: PAYROLL SLIP
A31: Name: | B31: =A2 -> Kris Naynayan
A32: Job Title: | B32: Staff
A33: Payment Date: | B33: =C8+1 -> 46139
A34: Cut Off Period: | B34: =Kent!B35 -> May-04 to May-15, 2026
A35: Days Worked | B35: =COUNTIF(D2:D8, "*:*") -> 0
A36: Adjustments
A37: Basic Pay | B37: =B22 -> 326.88
A38: Bonus/Incentives | B38: 0
A39: Overtime Pay | B39: =C22 -> 8.7098329e-14
A40: Other Income | B40: 0
A43: Gross Pay | B43: =D22 -> 326.88
A44: Deductions | B44: 0
A45: WH Tax | B45: 0
A47: Net Pay | B47: =SUM(B43:B45) -> 326.88

Sheet Jay Anne
A1: Employee | B1: Shift | C1: Date | D1: Time In | E1: Time Out | F1: Hourly Rate | G1: Total Hours | H1: Regular Hours | I1: Overtime Hours | J1: Regular Pay | K1: Overtime Pay | L1: Total Pay
A2: Jay Anne | B2: 10:00AM-9:00PM | C2: 2026-04-27 | D2: 09:00 | E2: 17:00 | F2: 37.5 | G2: =(E2-D2)*24 -> 8 | H2: =MIN(G2,8) -> 8 | I2: =IF(MAX(G2-9,0) - 1 < 0, 0, MAX(G2-9,0) - 1) -> 0 | J2: =H2*F2 -> 300 | K2: =I2*F2*1.2 -> 0 | L2: =J2+K2 -> 300
A3: Jay Anne | B3: 10:00AM-9:00PM | C3: 2026-04-28 | D3: 09:28 | E3: 21:00 | F3: 37.5 | G3: =(E3-D3)*24 -> 11.533333 | H3: =MIN(G3,8) -> 8 | I3: =IF(MAX(G3-9,0) - 1 < 0, 0, MAX(G3-9,0) - 1) -> 1.5333333 | J3: =H3*F3 -> 300 | K3: =I3*F3*1.2 -> 69 | L3: =J3+K3 -> 369
A4: Jay Anne | B4: 10:00AM-9:00PM | C4: 2026-04-29 | D4: 09:00 | E4: 21:00 | F4: 37.5 | G4: =(E4-D4)*24 -> 12 | H4: =MIN(G4,8) -> 8 | I4: =IF(MAX(G4-9,0) - 1 < 0, 0, MAX(G4-9,0) - 1) -> 2 | J4: =H4*F4 -> 300 | K4: =I4*F4*1.2 -> 90 | L4: =J4+K4 -> 390
A5: Jay Anne | B5: 10:00AM-9:00PM | C5: 2026-04-30 | D5: 0 | E5: 0 | F5: 37.5 | G5: =(E5-D5)*24 -> 0 | H5: =MIN(G5,8) -> 0 | I5: =IF(MAX(G5-9,0) - 1 < 0, 0, MAX(G5-9,0) - 1) -> 0 | J5: =H5*F5 -> 0 | K5: =I5*F5*1.2 -> 0 | L5: =J5+K5 -> 0
A6: Jay Anne | B6: 10:00AM-9:00PM | C6: 2026-05-01 | D6: 0 | E6: 0 | F6: 37.5 | G6: =(E6-D6)*24 -> 0 | H6: =MIN(G6,8) -> 0 | I6: =IF(MAX(G6-9,0) - 1 < 0, 0, MAX(G6-9,0) - 1) -> 0 | J6: =H6*F6 -> 0 | K6: =I6*F6*1.2 -> 0 | L6: =J6+K6 -> 0
A7: Jay Anne | B7: 10:00AM-9:00PM | C7: 2026-05-02 | D7: 0 | E7: 0 | F7: 37.5 | G7: =(E7-D7)*24 -> 0 | H7: =MIN(G7,8) -> 0 | I7: =IF(MAX(G7-8,0) - 1 < 0, 0, MAX(G7-8,0) - 1) -> 0 | J7: =H7*F7 -> 0 | K7: =I7*F7*1.2 -> 0 | L7: =J7+K7 -> 0
A8: Jay Anne | B8: 10:00AM-9:00PM | C8: 2026-05-03 | D8: 0 | E8: 0 | F8: 37.5 | G8: =(E8-D8)*24 -> 0 | H8: =MIN(G8,8) -> 0 | I8: =IF(MAX(G8-8,0) - 1 < 0, 0, MAX(G8-8,0) - 1) -> 0 | J8: =H8*F8 -> 0 | K8: =I8*F8*1.2 -> 0 | L8: =J8+K8 -> 0
A14: SUMMARY | B14: REGULAR PAY | C14: OVER TIME PAY | D14: TOTAL PAY
A15: Jay Anne | B15: =SUM(J2:J13) -> 900 | C15: =SUM(K2:K13) -> 159 | D15: =SUM(L2:L13) -> 1059
A23: PAYROLL SLIP
A24: Name: | B24: =A2 -> Jay Anne
A25: Job Title: | B25: Cashier
A26: Payment Date: | B26: =C8+1 -> 46146
A27: Cut Off Period: | B27: =Kent!B35 -> May-04 to May-15, 2026
A28: Days Worked | B28: =COUNTIF(D2:D8, "*:*") -> 3
A29: Adjustments
A30: Basic Pay | B30: =B15 -> 900
A31: Bonus/Incentives | B31: 0
A32: Overtime Pay | B32: =C15 -> 159
A33: Other Income | B33: 0
A36: Gross Pay | B36: =D15 -> 1059
A37: Deductions | B37: 0
A38: WH Tax | B38: 0
A40: Net Pay | B40: =SUM(B36:B38) -> 1059

Sheet Chardiya
A1: Employee | B1: Shift | C1: Date | D1: Time In | E1: Time Out | F1: Hourly Rate | G1: Total Hours | H1: Regular Hours | I1: Overtime Hours | J1: Regular Pay | K1: Overtime Pay | L1: Total Pay
A2: Chadiyah | B2: 8:30AM-9:00PM | C2: 2026-02-23 | D2: 08:30 | E2: 19:00 | F2: 34.18 | G2: =(E2-D2)*24 -> 10.5 | H2: =MIN(G2,9) -> 9 | I2: =IF(MAX(G2-9,0) - 1 < 0, 0, MAX(G2-9,0) - 1) -> 0.5 | J2: =H2*F2 -> 307.62 | K2: =I2*F2*1.2 -> 20.508 | L2: =J2+K2 -> 328.128
A3: Chadiyah | B3: 8:30AM-9:00PM | C3: 2026-02-24 | D3: 08:30 | E3: 17:00 | F3: 34.18 | G3: =(E3-D3)*24 -> 8.5 | H3: =MIN(G3,9) -> 8.5 | I3: =IF(MAX(G3-9,0) - 1 < 0, 0, MAX(G3-9,0) - 1) -> 0 | J3: =H3*F3 -> 290.53 | K3: =I3*F3*1.2 -> 0 | L3: =J3+K3 -> 290.53
A4: Chadiyah | B4: 8:30AM-9:00PM | C4: 2026-02-25 | D4: 08:30 | E4: 16:00 | F4: 34.18 | G4: =(E4-D4)*24 -> 7.5 | H4: =MIN(G4,9) -> 7.5 | I4: =IF(MAX(G4-9,0) - 1 < 0, 0, MAX(G4-9,0) - 1) -> 0 | J4: =H4*F4 -> 256.35 | K4: =I4*F4*1.2 -> 0 | L4: =J4+K4 -> 256.35
A5: Chadiyah | B5: 8:30AM-9:00PM | C5: 2026-02-26 | D5: 08:30 | E5: 21:30 | F5: 34.18 | G5: =(E5-D5)*24 -> 13 | H5: =MIN(G5,9) -> 9 | I5: =IF(MAX(G5-9,0) - 1 < 0, 0, MAX(G5-9,0) - 1) -> 3 | J5: =H5*F5 -> 307.62 | K5: =I5*F5*1.2 -> 123.048 | L5: =J5+K5 -> 430.668
A6: Chadiyah | B6: 8:30AM-9:00PM | C6: 2026-02-27 | D6: 0 | E6: 0 | F6: 34.18 | G6: =(E6-D6)*24 -> 0 | H6: =MIN(G6,9) -> 0 | I6: =IF(MAX(G6-9,0) - 1 < 0, 0, MAX(G6-9,0) - 1) -> 0 | J6: =H6*F6 -> 0 | K6: =I6*F6*1.2 -> 0 | L6: =J6+K6 -> 0
A7: Chadiyah | B7: 8:30AM-9:00PM | C7: 2026-02-28 | D7: 0 | E7: 0 | F7: 34.18 | G7: =(E7-D7)*24 -> 0 | H7: =MIN(G7,9) -> 0 | I7: =IF(MAX(G7-9,0) - 1 < 0, 0, MAX(G7-9,0) - 1) -> 0 | J7: =H7*F7 -> 0 | K7: =I7*F7*1.2 -> 0 | L7: =J7+K7 -> 0
A8: Chadiyah | B8: 8:30AM-9:00PM | C8: 2026-03-01 | D8: 0 | E8: 0 | F8: 34.18 | G8: =(E8-D8)*24 -> 0 | H8: =MIN(G8,9) -> 0 | I8: =IF(MAX(G8-9,0) - 1 < 0, 0, MAX(G8-9,0) - 1) -> 0 | J8: =H8*F8 -> 0 | K8: =I8*F8*1.2 -> 0 | L8: =J8+K8 -> 0
A14: SUMMARY | B14: REGULAR PAY | C14: OVER TIME PAY | D14: TOTAL PAY
A15: Chadiyah | B15: =SUM(J2:J13) -> 1162.12 | C15: =SUM(K2:K13) -> 143.556 | D15: =SUM(L2:L13) -> 1305.676
A23: PAYROLL SLIP
A24: Name: | B24: =A2 -> Chadiyah
A25: Job Title: | B25: Staff
A26: Payment Date: | B26: =C8+1 -> 46083
A27: Cut Off Period: | B27: =Kent!B35 -> May-04 to May-15, 2026
A28: Days Worked | B28: =COUNTIF(D2:D8, "*:*") -> 4
A29: Adjustments
A30: Basic Pay | B30: =B15 -> 1162.12
A31: Bonus/Incentives | B31: 0
A32: Overtime Pay | B32: =C15 -> 143.556
A33: Other Income | B33: 0
A36: Gross Pay | B36: =D15 -> 1305.676
A37: Deductions | B37: 0
A38: WH Tax | B38: 0
A40: Net Pay | B40: =SUM(B36:B38) -> 1305.676
B41: -367
B42: =SUM(B40:B41) -> 938.676

Sheet Lenard
A1: Employee | B1: Shift | C1: Date | D1: Time In | E1: Time Out | F1: Hourly Rate | G1: Total Hours | H1: Regular Hours | I1: Overtime Hours | J1: Regular Pay | K1: Overtime Pay | L1: Total Pay
A2: Lenard | B2: 5:00PM-10:00PM | C2: 2026-02-16 | D2: 0 | E2: 0 | F2: 22.22 | G2: =(E2-D2)*24 -> 0 | H2: =MIN(G2,9) -> 0 | I2: =IF(MAX(G2-9,0) - 1 < 0, 0, MAX(G2-9,0) - 1) -> 0 | J2: =H2*F2 -> 0 | K2: =I2*F2*1.2 -> 0 | L2: =J2+K2 -> 0
A3: Lenard | B3: 5:00PM-10:00PM | C3: 2026-02-17 | D3: 0 | E3: 0 | F3: 22.22 | G3: =(E3-D3)*24 -> 0 | H3: =MIN(G3,9) -> 0 | I3: =IF(MAX(G3-9,0) - 1 < 0, 0, MAX(G3-9,0) - 1) -> 0 | J3: =H3*F3 -> 0 | K3: =I3*F3*1.2 -> 0 | L3: =J3+K3 -> 0
A4: Lenard | B4: 5:00PM-10:00PM | C4: 2026-02-18 | D4: 17:00 | E4: 21:00 | F4: 22.22 | G4: =(E4-D4)*24 -> 4 | H4: =MIN(G4,9) -> 4 | I4: =IF(MAX(G4-9,0) - 1 < 0, 0, MAX(G4-9,0) - 1) -> 0 | J4: =H4*F4 -> 88.88 | K4: =I4*F4*1.2 -> 0 | L4: 100
A5: Lenard | B5: 5:00PM-10:00PM | C5: 2026-02-19 | D5: 17:00 | E5: 21:00 | F5: 22.22 | G5: =(E5-D5)*24 -> 4 | H5: =MIN(G5,9) -> 4 | I5: =IF(MAX(G5-9,0) - 1 < 0, 0, MAX(G5-9,0) - 1) -> 0 | J5: =H5*F5 -> 88.88 | K5: =I5*F5*1.2 -> 0 | L5: 100
A6: Lenard | B6: 5:00PM-10:00PM | C6: 2026-02-20 | D6: 17:00 | E6: 21:00 | F6: 22.22 | G6: =(E6-D6)*24 -> 4 | H6: =MIN(G6,9) -> 4 | I6: =IF(MAX(G6-9,0) - 1 < 0, 0, MAX(G6-9,0) - 1) -> 0 | J6: =H6*F6 -> 88.88 | K6: =I6*F6*1.2 -> 0 | L6: 100
A7: Lenard | B7: 9:30AM-10:00PM | C7: 2026-02-21 | D7: 08:57 | E7: 21:00 | F7: 22.22 | G7: =(E7-D7)*24 -> 12.05 | H7: =MIN(G7,9) -> 9 | I7: =IF(MAX(G7-9,0) - 1 < 0, 0, MAX(G7-9,0) - 1) -> 2.05 | J7: =H7*F7 -> 199.98 | K7: =I7*F7*1.2 -> 54.6612 | L7: =J7+K7 -> 254.6412
A8: Lenard | B8: 9:30AM-10:00PM | C8: 2026-02-22 | D8: 12:23 | E8: 21:00 | F8: 22.22 | G8: =(E8-D8)*24 -> 8.6166667 | H8: =MIN(G8,9) -> 8.6166667 | I8: =IF(MAX(G8-9,0) - 1 < 0, 0, MAX(G8-9,0) - 1) -> 0 | J8: =H8*F8 -> 191.46233 | K8: =I8*F8*1.2 -> 0 | L8: =J8+K8 -> 191.46233
A14: SUMMARY | B14: REGULAR PAY | C14: OVER TIME PAY | D14: TOTAL PAY
A15: Lenard | B15: =SUM(J2:J13) -> 658.08233 | C15: =SUM(K2:K13) -> 54.6612 | D15: =SUM(L2:L13) -> 746.10353
A23: PAYROLL SLIP
A24: Name: | B24: =A2 -> Lenard
A25: Job Title: | B25: Staff
A26: Payment Date: | B26: =C8+1 -> 46076
A27: Cut Off Period: | B27: =Kent!B35 -> May-04 to May-15, 2026
A28: Days Worked | B28: =COUNTIF(D2:D8, "*:*") -> 5
A29: Adjustments
A30: Basic Pay | B30: =B15 -> 658.08233
A31: Bonus/Incentives | B31: 0
A32: Overtime Pay | B32: =C15 -> 54.6612
A33: Other Income | B33: 0
A36: Gross Pay | B36: =D15 -> 746.10353
A37: Deductions | B37: 0
A38: WH Tax | B38: 0
A40: Net Pay | B40: =SUM(B36:B38) -> 746.10353

Sheet Template
A1: Employee | B1: Shift | C1: Date | D1: Time In | E1: Time Out | F1: Hourly Rate | G1: Total Hours | H1: Regular Hours | I1: Overtime Hours | J1: Regular Pay | K1: Overtime Pay | L1: Total Pay
A2: Name | B2: 8:30AM-9:00PM | C2: 2026-01-12 | D2: 08:30 | E2: 22:00 | F2: 38.46 | G2: =(E2-D2)*24 -> 13.5 | H2: =MIN(G2,10) -> 10 | I2: =MAX(G2-10,0) - 1 -> 2.5 | J2: =H2*F2 -> 384.6 | K2: =I2*F2*1.2 -> 115.38 | L2: =J2+K2 -> 499.98
A3: Name | B3: 8:30AM-9:00PM | C3: 2026-01-13 | D3: 08:30 | E3: 22:00 | F3: 38.46 | G3: =(E3-D3)*24 -> 13.5 | H3: =MIN(G3,10) -> 10 | I3: =MAX(G3-10,0) - 1 -> 2.5 | J3: =H3*F3 -> 384.6 | K3: =I3*F3*1.2 -> 115.38 | L3: =J3+K3 -> 499.98
A4: Name | B4: 8:30AM-9:00PM | C4: 2026-01-14 | D4: 08:30 | E4: 22:00 | F4: 38.46 | G4: =(E4-D4)*24 -> 13.5 | H4: =MIN(G4,10) -> 10 | I4: =MAX(G4-10,0) - 1 -> 2.5 | J4: =H4*F4 -> 384.6 | K4: =I4*F4*1.2 -> 115.38 | L4: =J4+K4 -> 499.98
A5: Name | B5: 8:30AM-9:00PM | C5: 2026-01-15 | D5: 08:30 | E5: 22:00 | F5: 38.46 | G5: =(E5-D5)*24 -> 13.5 | H5: =MIN(G5,10) -> 10 | I5: =MAX(G5-10,0) - 1 -> 2.5 | J5: =H5*F5 -> 384.6 | K5: =I5*F5*1.2 -> 115.38 | L5: =J5+K5 -> 499.98
A6: Name | B6: 8:30AM-9:00PM | C6: 2026-01-16 | D6: 08:30 | E6: 22:00 | F6: 38.46 | G6: =(E6-D6)*24 -> 13.5 | H6: =MIN(G6,10) -> 10 | I6: =MAX(G6-10,0) - 1 -> 2.5 | J6: =H6*F6 -> 384.6 | K6: =I6*F6*1.2 -> 115.38 | L6: =J6+K6 -> 499.98
A7: Name | B7: 8:30AM-9:00PM | C7: 2026-01-17 | D7: 08:30 | E7: 22:00 | F7: 38.46 | G7: =(E7-D7)*24 -> 13.5 | H7: =MIN(G7,10) -> 10 | I7: =MAX(G7-10,0) - 1 -> 2.5 | J7: =H7*F7 -> 384.6 | K7: =I7*F7*1.2 -> 115.38 | L7: =J7+K7 -> 499.98
A8: Name | B8: 8:30AM-9:00PM | C8: 2026-01-18 | D8: 08:30 | E8: 22:00 | F8: 38.46 | G8: =(E8-D8)*24 -> 13.5 | H8: =MIN(G8,10) -> 10 | I8: =MAX(G8-10,0) - 1 -> 2.5 | J8: =H8*F8 -> 384.6 | K8: =I8*F8*1.2 -> 115.38 | L8: =J8+K8 -> 499.98
A14: SUMMARY | B14: REGULAR PAY | C14: OVER TIME PAY | D14: TOTAL PAY
A15: Rhea Mae | B15: =SUM(J2:J13) -> 2692.2 | C15: =SUM(K2:K13) -> 807.66 | D15: =SUM(L2:L13) -> 3499.86
A23: PAYROLL SLIP
A24: Name: | B24: =A2 -> Name
A25: Job Title: | B25: Store Manager
A26: Payment Date: | B26: 46041
A27: Cut Off Period: | B27: Jan-12 to Jan-28, 2026
A29: Adjustments
A30: Basic Pay | B30: =B15 -> 2692.2
A31: Bonus/Incentives | B31: 0
A32: Overtime Pay | B32: =C15 -> 807.66
A33: Other Income | B33: 0
A36: Gross Pay | B36: =D15 -> 3499.86
A37: Deductions | B37: 0
A38: WH Tax | B38: 0
A40: Net Pay | B40: =SUM(B36:B38) -> 3499.86

Sheet Rhoda
A1: Employee | B1: Date | C1: Shift | D1: Time In | E1: Time Out | F1: Hourly Rate | G1: Total Hours | H1: Regular Hours | I1: Overtime Hours | J1: Regular Pay | K1: Overtime Pay | L1: Total Pay
A2: Rhoda | B2: 46021 | C2: 9:00AM-7:00PM | D2: 0.45833333 | E2: 0.99930556 | F2: 29.91 | G2: 15 | H2: =MIN(G2,9) -> 9 | I2: =MAX(G2-9,0) - 1 -> 5 | J2: =H2*F2 -> 269.19 | K2: =I2*F2*1.2 -> 179.46 | L2: =J2+K2 -> 448.65
A3: Rhoda | B3: 46022 | C3: 9:00AM-7:00PM | D3: 0.41666667 | E3: 0.8125 | F3: 29.91 | G3: =(E3-D3)*24 -> 9.5 | H3: =MIN(G3,9) -> 9 | I3: =MAX(G3-9,0) - 1 -> -0.5 | J3: =H3*F3 -> 269.19 | L3: 538 | M3: doublepay
A4: Rhoda | B4: 46027 | C4: 9:00AM-7:00PM | D4: 0.375 | E4: 0.91666667 | F4: 29.91 | G4: =(E4-D4)*24 -> 13 | H4: =MIN(G4,9) -> 9 | I4: =MAX(G4-9,0) - 1 -> 3 | J4: =H4*F4 -> 269.19 | K4: =I4*F4*1.2 -> 107.676 | L4: =J4+K4 -> 376.866
A5: Rhoda | B5: 46028 | C5: 9:00AM-7:00PM | D5: 0.375 | E5: 0.875 | F5: 29.91 | G5: =(E5-D5)*24 -> 12 | H5: =MIN(G5,9) -> 9 | I5: =MAX(G5-9,0) - 1 -> 2 | J5: =H5*F5 -> 269.19 | K5: =I5*F5*1.2 -> 71.784 | L5: =J5+K5 -> 340.974
A6: Rhoda | B6: 46029 | C6: 9:00AM-7:00PM | D6: 0.375 | E6: 0.9375 | F6: 29.91 | G6: =(E6-D6)*24 -> 13.5 | H6: =MIN(G6,9) -> 9 | I6: =MAX(G6-9,0) - 1 -> 3.5 | J6: =H6*F6 -> 269.19 | K6: =I6*F6*1.2 -> 125.622 | L6: =J6+K6 -> 394.812
A7: Rhoda | B7: 46030 | C7: 9:00AM-7:00PM | D7: 0.375 | E7: 0.99930556 | F7: 29.91 | G7: 15 | H7: =MIN(G7,9) -> 9 | I7: =MAX(G7-9,0) - 1 -> 5 | J7: =H7*F7 -> 269.19 | K7: =I7*F7*1.2 -> 179.46 | L7: =J7+K7 -> 448.65
A8: Rhoda | B8: 46031 | C8: 9:00AM-7:00PM | D8: 0.51041667 | E8: 0.91805556 | F8: 29.91 | G8: =(E8-D8)*24 -> 9.7833333 | H8: =MIN(G8,9) -> 9 | I8: =MAX(G8-9,0) - 1 -> -0.21666667 | J8: =H8*F8 -> 269.19 | L8: =J8+K8 -> 269.19
A9: Rhoda | B9: 46032 | C9: 9:00AM-7:00PM | D9: 0.43402778 | E9: 0.90625 | F9: 29.91 | G9: =(E9-D9)*24 -> 11.333333 | H9: =MIN(G9,9) -> 9 | I9: =MAX(G9-9,0) - 1 -> 1.3333333 | J9: =H9*F9 -> 269.19 | K9: =I9*F9*1.2 -> 47.856 | L9: =J9+K9 -> 317.046
J10: =SUM(J2:J9) -> 2153.52 | K10: =SUM(K2:K9) -> 711.858 | L10: =SUM(L2:L9) -> 3134.188

Sheet Kenneth
A1: Employee | B1: Date | C1: Shift | D1: Time In | E1: Time Out | F1: Hourly Rate | G1: Total Hours | H1: Regular Hours | I1: Overtime Hours | J1: Regular Pay | K1: Overtime Pay | L1: Total Pay
A2: Kenneth | B2: 46027
A3: Kenneth | B3: 46028
A4: Kenneth | B4: 46029
A5: Kenneth | B5: 46030
A6: Kenneth | B6: 46031 | D6: 0.70833333 | E6: 0.9375 | F6: 22.22 | G6: =(E6-D6)*24 -> 5.5 | H6: =MIN(G6,9) -> 5.5 | I6: =MAX(G6-9,0) - 1 -> -1 | J6: =H6*F6 -> 122.21 | L6: =J6+K6 -> 122.21
A7: Kenneth | B7: 46032 | D7: 0.70833333 | E7: 0.91666667 | F7: 22.22 | G7: =(E7-D7)*24 -> 5 | H7: =MIN(G7,9) -> 5 | I7: =MAX(G7-9,0) - 1 -> -1 | J7: =H7*F7 -> 111.1 | L7: =J7+K7 -> 111.1
A8: Kenneth | B8: 46033 | D8: 0.72986111 | E8: 0.91666667 | F8: 22.22 | G8: =(E8-D8)*24 -> 4.4833333 | H8: =MIN(G8,9) -> 4.4833333 | I8: =MAX(G8-9,0) - 1 -> -1 | J8: =H8*F8 -> 99.619667 | L8: =J8+K8 -> 99.619667
L9: =SUM(L6:L8) -> 332.92967
