Workbook

Sheet Payslip
A1: PAYROLL SLIP | D1: PAYROLL SLIP
A2: =Lino!A29 -> Name: | B2: =Lino!B29 -> Lino | D2: ='Jay Anne'!A24 -> Name: | E2: =Micky!B32 -> Micky
A3: =Lino!A30 -> Job Title: | B3: =Lino!B30 -> Staff | D3: ='Jay Anne'!A25 -> Job Title: | E3: =Micky!B33 -> Staff
A4: =Lino!A31 -> Payment Date: | B4: =Lino!B31 -> 46238 | D4: ='Jay Anne'!A26 -> Payment Date: | E4: =Micky!B34 -> 46238
A5: =Lino!A32 -> Cut Off Period: | B5: =Lino!B32 -> July-1 to July-15, 2026 | D5: ='Jay Anne'!A27 -> Cut Off Period: | E5: =Micky!B35 -> July-1 to July-15, 2026
A6: =Lino!A33 -> Days Worked | B6: =Lino!B33 -> 13 | D6: ='Jay Anne'!A28 -> Days Worked | E6: =Micky!B36 -> 14
A7: =Lino!A34 -> Adjustments | B7: =Lino!B34 -> 0 | D7: ='Jay Anne'!A29 -> Adjustments
A8: =Lino!A35 -> Basic Pay | B8: =Lino!B35 -> 2600 | D8: ='Jay Anne'!A30 -> Basic Pay | E8: =Micky!B38 -> 4200
A9: =Lino!A36 -> Bonus/Incentives | B9: =Lino!B36 -> 0 | D9: ='Jay Anne'!A31 -> Bonus/Incentives | E9: =Micky!B39 -> 500
A10: =Lino!A37 -> Overtime Pay | B10: =Lino!B37 -> 912.5 | D10: ='Jay Anne'!A32 -> Overtime Pay | E10: =Micky!B40 -> 1920
A11: =Lino!A38 -> Other Income | B11: =Lino!B38 -> 0 | D11: ='Jay Anne'!A33 -> Other Income | E11: =Micky!B41 -> 0
A14: =Lino!A41 -> Gross Pay | B14: =Lino!B41 -> 3512.5 | D14: ='Jay Anne'!A36 -> Gross Pay | E14: =Micky!B44 -> 6620
A15: =Lino!A42 -> Deductions | B15: =Lino!B42 -> 0 | D15: ='Jay Anne'!A37 -> Deductions | E15: =Micky!B45 -> 0
A16: =Lino!A43 -> . | D16: ='Jay Anne'!A38 -> WH Tax | E16: =Micky!B46 -> 0
A17: =Lino!A44 -> Net Pay | B17: =Lino!B44 -> 3512.5
D18: ='Jay Anne'!A40 -> Net Pay | E18: =Micky!B48 -> 6620
A21: PAYROLL SLIP | D21: PAYROLL SLIP
A22: =Renelyn!A32 -> Name: | B22: =Renelyn!B32 -> Renelyn | D22: =Pepito!A32 -> Name: | E22: =Monico!B29 -> Monico
A23: =Renelyn!A33 -> Job Title: | B23: =Renelyn!B33 -> Staff | D23: =Pepito!A33 -> Job Title: | E23: =Monico!B30 -> Staff
A24: =Renelyn!A34 -> Payment Date: | B24: =Renelyn!B34 -> 46238 | D24: =Pepito!A34 -> Payment Date: | E24: =Monico!B31 -> 46238
A25: =Renelyn!A35 -> Cut Off Period: | B25: =Renelyn!B35 -> July-1 to July-15, 2026 | D25: =Pepito!A35 -> Cut Off Period: | E25: =Monico!B32 -> July-1 to July-15, 2026
A26: =Renelyn!A36 -> Days Worked | B26: =Renelyn!B36 -> 13 | D26: =Pepito!A36 -> Days Worked | E26: =Monico!B33 -> 12
A27: =Renelyn!A37 -> Adjustments | D27: =Pepito!A37 -> Adjustments | E27: =Monico!B34 -> 0
A28: =Renelyn!A38 -> Basic Pay | B28: =Renelyn!B38 -> 3600 | D28: =Pepito!A38 -> Basic Pay | E28: =Monico!B35 -> 2906.25
A29: =Renelyn!A39 -> Bonus/Incentives | B29: =Renelyn!B39 -> 0 | D29: =Pepito!A39 -> Bonus/Incentives | E29: =Monico!B36 -> 0
A30: =Renelyn!A40 -> Overtime Pay | B30: =Renelyn!B40 -> 1417.5 | D30: =Pepito!A40 -> Overtime Pay | E30: =Monico!B37 -> 818.75
A31: =Renelyn!A41 -> Other Income | B31: =Renelyn!B41 -> 0 | D31: =Pepito!A41 -> Other Income | E31: =Monico!B38 -> 0
A34: =Renelyn!A44 -> Gross Pay | B34: =Renelyn!B44 -> 5017.5 | D34: =Pepito!A44 -> Gross Pay | E34: =Monico!B41 -> 3725
A35: =Renelyn!A45 -> Deductions | B35: =Renelyn!B45 -> 0 | D35: =Pepito!A45 -> Deductions
A36: =Renelyn!A46 -> Sisig | B36: =Renelyn!B46 -> -150 | D36: =Pepito!A46 -> WH Tax | E36: =Monico!B43 -> -500
A37: =Renelyn!A47 -> Short | B37: =Renelyn!B47 -> -315
A38: =Renelyn!A48 -> Net Pay | B38: =Renelyn!B48 -> 4867.5 | D38: =Pepito!A48 -> Net Pay | E38: =Monico!B45 -> 3175
A42: PAYROLL SLIP | D42: PAYROLL SLIP
A43: =Cherry!A31 -> Name: | B43: =Cherry!B31 -> Cherry | D43: =Nino!A29 -> Name: | E43: =Nino!B29 -> Nino
A44: =Cherry!A32 -> Job Title: | B44: =Cherry!B32 -> Staff | D44: =Nino!A30 -> Job Title: | E44: =Nino!B30 -> Staff
A45: =Cherry!A33 -> Payment Date: | B45: =Cherry!B33 -> 46238 | D45: =Nino!A31 -> Payment Date: | E45: =Nino!B31 -> 46238
A46: =Cherry!A34 -> Cut Off Period: | B46: =Cherry!B34 -> July-1 to July-15, 2026 | D46: =Nino!A32 -> Cut Off Period: | E46: =Nino!B32 -> July-1 to July-15, 2026
A47: =Cherry!A35 -> Days Worked | B47: =Cherry!B35 -> 14 | D47: =Nino!A33 -> Days Worked | E47: =Nino!B33 -> 11
A48: =Cherry!A36 -> Adjustments | D48: =Nino!A34 -> Adjustments
A49: =Cherry!A37 -> Basic Pay | B49: =Cherry!B37 -> 5203.125 | D49: =Nino!A35 -> Basic Pay | E49: =Nino!B35 -> 2738.75
...

Sheet Summary
A1: micky harabi | B1: 2026-07-16 | C1: 09:34 | D1: 21:41
A2: micky harabi | B2: 2026-07-17 | C2: 08:59 | D2: 21:22
A3: micky harabi | B3: 2026-07-18 | C3: 08:16 | D3: 21:38
A4: micky harabi | B4: 2026-07-19 | C4: 08:50 | D4: 22:04
A5: micky harabi | B5: 2026-07-20 | C5: 08:55 | D5: 21:49
A6: micky harabi | B6: 2026-07-21 | C6: 08:57 | D6: 21:20
A7: micky harabi | B7: 2026-07-22 | C7: Missed | D7: Missed
A8: micky harabi | B8: 2026-07-23 | C8: 08:51 | D8: 21:14
A9: micky harabi | B9: 2026-07-24 | C9: 08:54 | D9: 22:10
A10: micky harabi | B10: 2026-07-25 | C10: 08:58 | D10: 21:31
A11: micky harabi | B11: 2026-07-26 | C11: 09:04 | D11: 21:23
A12: micky harabi | B12: 2026-07-27 | C12: 09:03 | D12: 21:32
... A160: lino | B160: 2026-07-31 | C160: Missed | D160: 21:54

Sheet Micky
A1: Employee | B1: Shift | C1: Date | D1: Time In | E1: Time Out | F1: Hourly Rate | G1: Total Hours | H1: Regular Hours | I1: Overtime Hours | J1: Regular Pay | K1: Overtime Pay | L1: Total Pay
A2: Micky | B2: 10:00AM-9:00PM | C2: 2026-07-16 | D2: 09:30 | E2: 21:10 | F2: 37.5 | G2: =(E2-D2)*24 -> 11.666667 | H2: =MIN(G2,8) -> 8 | I2: =IF(MAX(G2-8,0) - 1 < 0, 0, MAX(G2-8,0) - 1) -> 2.6666667 | J2: =H2*F2 -> 300 | K2: =I2*F2*1.2 -> 120 | L2: =J2+K2 -> 420
A3: Micky | B3: 10:00AM-9:00PM | C3: 2026-07-17 | D3: 09:00 | E3: 21:00 | F3: 37.5 | G3: =(E3-D3)*24 -> 12 | H3: =MIN(G3,8) -> 8 | I3: =IF(MAX(G3-8,0) - 1 < 0, 0, MAX(G3-8,0) - 1) -> 3 | J3: =H3*F3 -> 300 | K3: =I3*F3*1.2 -> 135 | L3: =J3+K3 -> 435
A4: Micky | B4: 10:00AM-9:00PM | C4: 2026-07-18 | D4: 09:00 | E4: 21:00 | F4: 37.5 | G4: =(E4-D4)*24 -> 12 | H4: =MIN(G4,8) -> 8 | I4: =IF(MAX(G4-8,0) - 1 < 0, 0, MAX(G4-8,0) - 1) -> 3 | J4: =H4*F4 -> 300 | K4: =I4*F4*1.2 -> 135 | L4: =J4+K4 -> 435
A5: Micky | B5: 10:00AM-9:00PM | C5: 2026-07-19 | D5: 09:00 | E5: 21:30 | F5: 37.5 | G5: =(E5-D5)*24 -> 12.5 | H5: =MIN(G5,8) -> 8 | I5: =IF(MAX(G5-8,0) - 1 < 0, 0, MAX(G5-8,0) - 1) -> 3.5 | J5: =H5*F5 -> 300 | K5: =I5*F5*1.2 -> 157.5 | L5: =J5+K5 -> 457.5
A6: Micky | B6: 10:00AM-9:00PM | C6: 2026-07-20 | D6: 09:00 | E6: 21:10 | F6: 37.5 | G6: =(E6-D6)*24 -> 12.166667 | H6: =MIN(G6,8) -> 8 | I6: =IF(MAX(G6-8,0) - 1 < 0, 0, MAX(G6-8,0) - 1) -> 3.1666667 | J6: =H6*F6 -> 300 | K6: =I6*F6*1.2 -> 142.5 | L6: =J6+K6 -> 442.5
A7: Micky | B7: 10:00AM-9:00PM | C7: 2026-07-21 | D7: 09:00 | E7: 21:00 | F7: 37.5 | G7: =(E7-D7)*24 -> 12 | H7: =MIN(G7,8) -> 8 | I7: =IF(MAX(G7-8,0) - 1 < 0, 0, MAX(G7-8,0) - 1) -> 3 | J7: =H7*F7 -> 300 | K7: =I7*F7*1.2 -> 135 | L7: =J7+K7 -> 435
A8: Micky | B8: 10:00AM-9:00PM | C8: 2026-07-22 | D8: 0 | E8: 0 | F8: 37.5 | G8: =(E8-D8)*24 -> 0 | H8: =MIN(G8,8) -> 0 | I8: =IF(MAX(G8-8,0) - 1 < 0, 0, MAX(G8-8,0) - 1) -> 0 | J8: =H8*F8 -> 0 | K8: =I8*F8*1.2 -> 0 | L8: =J8+K8 -> 0
A9: Micky | B9: 10:00AM-9:00PM | C9: 2026-07-23 | D9: 09:00 | E9: 21:00 | F9: 37.5 | G9: =(E9-D9)*24 -> 12 | H9: =MIN(G9,8) -> 8 | I9: =IF(MAX(G9-8,0) - 1 < 0, 0, MAX(G9-8,0) - 1) -> 3 | J9: =H9*F9 -> 300 | K9: =I9*F9*1.2 -> 135 | L9: =J9+K9 -> 435
A10: Micky | B10: 10:00AM-9:00PM | C10: 2026-07-24 | D10: 09:00 | E10: 21:00 | F10: 37.5 | G10: =(E10-D10)*24 -> 12 | H10: =MIN(G10,8) -> 8 | I10: =IF(MAX(G10-8,0) - 1 < 0, 0, MAX(G10-8,0) - 1) -> 3 | J10: =H10*F10 -> 300 | K10: =I10*F10*1.2 -> 135 | L10: =J10+K10 -> 435
A11: Micky | B11: 10:00AM-9:00PM | C11: 2026-07-25 | D11: 09:00 | E11: 21:00 | F11: 37.5 | G11: =(E11-D11)*24 -> 12 | H11: =MIN(G11,8) -> 8 | I11: =IF(MAX(G11-8,0) - 1 < 0, 0, MAX(G11-8,0) - 1) -> 3 | J11: =H11*F11 -> 300 | K11: =I11*F11*1.2 -> 135 | L11: =J11+K11 -> 435
A12: Micky | B12: 10:00AM-9:00PM | C12: 2026-07-26 | D12: 09:00 | E12: 21:00 | F12: 37.5 | G12: =(E12-D12)*24 -> 12 | H12: =MIN(G12,8) -> 8 | I12: =IF(MAX(G12-8,0) - 1 < 0, 0, MAX(G12-8,0) - 1) -> 3 | J12: =H12*F12 -> 300 | K12: =I12*F12*1.2 -> 135 | L12: =J12+K12 -> 435
A13: Micky | B13: 10:00AM-9:00PM | C13: 2026-07-27 | D13: 09:00 | E13: 21:00 | F13: 37.5 | G13: =(E13-D13)*24 -> 12 | H13: =MIN(G13,8) -> 8 | I13: =IF(MAX(G13-8,0) - 1 < 0, 0, MAX(G13-8,0) - 1) -> 3 | J13: =H13*F13 -> 300 | K13: =I13*F13*1.2 -> 135 | L13: =J13+K13 -> 435
... A17: Micky | B17: 10:00AM-9:00PM | C17: 2026-07-31 | D17: 09:00 | E17: 21:20 | F17: 37.5 | G17: =(E17-D17)*24 -> 12.333333 | H17: =MIN(G17,8) -> 8 | I17: =IF(MAX(G17-8,0) - 1 < 0, 0, MAX(G17-8,0) - 1) -> 3.3333333 | J17: =H17*F17 -> 300 | K17: =I17*F17*1.2 -> 150 | L17: =J17+K17 -> 450
A22: SUMMARY | B22: REGULAR PAY | C22: OVER TIME PAY | D22: TOTAL PAY
A23: Micky | B23: =SUM(J2:J21) -> 4200 | C23: =SUM(K2:K21) -> 1920 | D23: =SUM(L2:L21) -> 6120
A31: PAYROLL SLIP
A32: Name: | B32: =A2 -> Micky
A33: Job Title: | B33: Staff
A34: Payment Date: | B34: =C16+5 -> 46238
A35: Cut Off Period: | B35: =Marlon!B35 -> July-1 to July-15, 2026
A36: Days Worked | B36: =COUNTIF(D2:D17, "*:*") -> 14
A37: Adjustments
A38: Basic Pay | B38: =B23 -> 4200
A39: Bonus/Incentives | B39: 500
A40: Overtime Pay | B40: =C23 -> 1920
A41: Other Income | B41: 0
A44: Gross Pay | B44: =SUM(B38:B43) -> 6620
A45: Deductions | B45: 0
A46: WH Tax | B46: 0
A48: Net Pay | B48: =SUM(B44:B46) -> 6620

Sheet Monico
A1: Employee | B1: Shift | C1: Date | D1: Time In | E1: Time Out | F1: Hourly Rate | G1: Total Hours | H1: Regular Hours | I1: Overtime Hours | J1: Regular Pay | K1: Overtime Pay | L1: Total Pay
A2: Monico | B2: 10:00AM-9:00PM | C2: 2026-07-16 | D2: 12:00 | E2: 21:00 | F2: 31.25 | G2: =(E2-D2)*24 -> 9 | H2: =MIN(G2,8) -> 8 | I2: =IF(MAX(G2-8,0) - 1 < 0, 0, MAX(G2-8,0) - 1) -> 0 | J2: =H2*F2 -> 250 | K2: =I2*F2*1.2 -> 0 | L2: =J2+K2 -> 250
A3: Monico | B3: 10:00AM-9:00PM | C3: 2026-07-17 | D3: 12:00 | E3: 21:00 | F3: 31.25 | G3: =(E3-D3)*24 -> 9 | H3: =MIN(G3,8) -> 8 | I3: =IF(MAX(G3-8,0) - 1 < 0, 0, MAX(G3-8,0) - 1) -> 0 | J3: =H3*F3 -> 250 | K3: =I3*F3*1.2 -> 0 | L3: =J3+K3 -> 250
A4: Monico | B4: 10:00AM-9:00PM | C4: 2026-07-18 | D4: 08:30 | E4: 21:00 | F4: 31.25 | G4: =(E4-D4)*24 -> 12.5 | H4: =MIN(G4,8) -> 8 | I4: =IF(MAX(G4-8,0) - 1 < 0, 0, MAX(G4-8,0) - 1) -> 3.5 | J4: =H4*F4 -> 250 | K4: =I4*F4*1.2 -> 131.25 | L4: =J4+K4 -> 381.25
A5: Monico | B5: 10:00AM-9:00PM | C5: 2026-07-19 | D5: 0 | E5: 0 | F5: 31.25 | G5: =(E5-D5)*24 -> 0 | H5: =MIN(G5,8) -> 0 | I5: =IF(MAX(G5-8,0) - 1 < 0, 0, MAX(G5-8,0) - 1) -> 0 | J5: =H5*F5 -> 0 | K5: =I5*F5*1.2 -> 0 | L5: =J5+K5 -> 0
A6: Monico | B6: 10:00AM-9:00PM | C6: 2026-07-20 | D6: 0 | E6: 0 | F6: 31.25 | G6: =(E6-D6)*24 -> 0 | H6: =MIN(G6,8) -> 0 | I6: =IF(MAX(G6-8,0) - 1 < 0, 0, MAX(G6-8,0) - 1) -> 0 | J6: =H6*F6 -> 0 | K6: =I6*F6*1.2 -> 0 | L6: =J6+K6 -> 0
A7: Monico | B7: 10:00AM-9:00PM | C7: 2026-07-21 | D7: 09:00 | E7: 18:00 | F7: 31.25 | G7: =(E7-D7)*24 -> 9 | H7: =MIN(G7,8) -> 8 | I7: =IF(MAX(G7-8,0) - 1 < 0, 0, MAX(G7-8,0) - 1) -> 0 | J7: =H7*F7 -> 250 | K7: =I7*F7*1.2 -> 0 | L7: =J7+K7 -> 250
A8: Monico | B8: 10:00AM-9:00PM | C8: 2026-07-22 | D8: 0 | E8: 0 | F8: 31.25 | G8: =(E8-D8)*24 -> 0 | H8: =MIN(G8,8) -> 0 | I8: =IF(MAX(G8-8,0) - 1 < 0, 0, MAX(G8-8,0) - 1) -> 0 | J8: =H8*F8 -> 0 | K8: =I8*F8*1.2 -> 0 | L8: =J8+K8 -> 0
A9: Monico | B9: 10:00AM-9:00PM | C9: 2026-07-23 | D9: 12:00 | E9: 21:00 | F9: 31.25 | G9: =(E9-D9)*24 -> 9 | H9: =MIN(G9,8) -> 8 | I9: =IF(MAX(G9-8,0) - 1 < 0, 0, MAX(G9-8,0) - 1) -> 0 | J9: =H9*F9 -> 250 | K9: =I9*F9*1.2 -> 0 | L9: =J9+K9 -> 250
A10: Monico | B10: 10:00AM-9:00PM | C10: 2026-07-24 | D10: 09:00 | E10: 21:00 | F10: 31.25 | G10: =(E10-D10)*24 -> 12 | H10: =MIN(G10,8) -> 8 | I10: =IF(MAX(G10-8,0) - 1 < 0, 0, MAX(G10-8,0) - 1) -> 3 | J10: =H10*F10 -> 250 | K10: =I10*F10*1.2 -> 112.5 | L10: =J10+K10 -> 362.5
A11: Monico | B11: 10:00AM-9:00PM | C11: 2026-07-25 | D11: 09:00 | E11: 21:00 | F11: 31.25 | G11: =(E11-D11)*24 -> 12 | H11: =MIN(G11,8) -> 8 | I11: =IF(MAX(G11-8,0) - 1 < 0, 0, MAX(G11-8,0) - 1) -> 3 | J11: =H11*F11 -> 250 | K11: =I11*F11*1.2 -> 112.5 | L11: =J11+K11 -> 362.5
A12: Monico | B12: 10:00AM-9:00PM | C12: 2026-07-26 | D12: 16:00 | E12: 21:00 | F12: 31.25 | G12: =(E12-D12)*24 -> 5 | H12: =MIN(G12,8) -> 5 | I12: =IF(MAX(G12-8,0) - 1 < 0, 0, MAX(G12-8,0) - 1) -> 0 | J12: =H12*F12 -> 156.25 | K12: =I12*F12*1.2 -> 0 | L12: =J12+K12 -> 156.25
A13: Monico | B13: 10:00AM-9:00PM | C13: 2026-07-27 | D13: 09:00 | E13: 21:00 | F13: 31.25 | G13: =(E13-D13)*24 -> 12 | H13: =MIN(G13,8) -> 8 | I13: =IF(MAX(G13-8,0) - 1 < 0, 0, MAX(G13-8,0) - 1) -> 3 | J13: =H13*F13 -> 250 | K13: =I13*F13*1.2 -> 112.5 | L13: =J13+K13 -> 362.5
... A17: Monico | B17: 10:00AM-9:00PM | C17: 2026-07-31 | D17: 09:00 | E17: 21:20 | F17: 31.25 | G17: =(E17-D17)*24 -> 12.333333 | H17: =MIN(G17,8) -> 8 | I17: =IF(MAX(G17-8,0) - 1 < 0, 0, MAX(G17-8,0) - 1) -> 3.3333333 | J17: =H17*F17 -> 250 | K17: =I17*F17*1.2 -> 125 | L17: =J17+K17 -> 375
A23: SUMMARY | B23: REGULAR PAY | C23: OVER TIME PAY | D23: TOTAL PAY
A24: Monico | B24: =SUM(J2:J22) -> 2906.25 | C24: =SUM(K2:K22) -> 818.75 | D24: =SUM(L2:L22) -> 3725
A28: PAYROLL SLIP
A29: Name: | B29: =A2 -> Monico
A30: Job Title: | B30: Staff
A31: Payment Date: | B31: =C16+5 -> 46238
A32: Cut Off Period: | B32: =Marlon!B35 -> July-1 to July-15, 2026
A33: Days Worked | B33: =COUNTIF(D2:D18, "*:*") -> 12
A34: Adjustments
A35: Basic Pay | B35: =B24 -> 2906.25
A36: Bonus/Incentives | B36: 0
A37: Overtime Pay | B37: =C24 -> 818.75
A38: Other Income | B38: 0
A41: Gross Pay | B41: =D24 -> 3725
A42: Deductions
A43: Allowance(07-27) | B43: -500
A44: Short | B44: -50
A45: Net Pay | B45: =SUM(B41:B44) -> 3175

Sheet Renelyn
A1: Employee | B1: Shift | C1: Date | D1: Time In | E1: Time Out | F1: Hourly Rate | G1: Total Hours | H1: Regular Hours | I1: Overtime Hours | J1: Regular Pay | K1: Overtime Pay | L1: Total Pay
A2: Renelyn | B2: 8:30AM-9:00PM | C2: 2026-07-16 | D2: 09:00 | E2: 21:10 | F2: 37.5 | G2: =(E2-D2)*24 -> 12.166667 | H2: =MIN(G2,8) -> 8 | I2: =IF(MAX(G2-8,0) - 1 < 0, 0, MAX(G2-8,0) - 1) -> 3.1666667 | J2: =H2*F2 -> 300 | K2: =I2*F2*1.2 -> 142.5 | L2: =J2+K2 -> 442.5
A3: Renelyn | B3: 8:30AM-9:00PM | C3: 2026-07-17 | D3: 09:00 | E3: 21:00 | F3: 37.5 | G3: =(E3-D3)*24 -> 12 | H3: =MIN(G3,8) -> 8 | I3: =IF(MAX(G3-8,0) - 1 < 0, 0, MAX(G3-8,0) - 1) -> 3 | J3: =H3*F3 -> 300 | K3: =I3*F3*1.2 -> 135 | L3: =J3+K3 -> 435
A4: Renelyn | B4: 8:30AM-9:00PM | C4: 2026-07-18 | D4: 09:00 | E4: 21:00 | F4: 37.5 | G4: =(E4-D4)*24 -> 12 | H4: =MIN(G4,8) -> 8 | I4: =IF(MAX(G4-8,0) - 1 < 0, 0, MAX(G4-8,0) - 1) -> 3 | J4: =H4*F4 -> 300 | K4: =I4*F4*1.2 -> 135 | L4: =J4+K4 -> 435
A5: Renelyn | B5: 8:30AM-9:00PM | C5: 2026-07-19 | D5: 09:00 | E5: 21:30 | F5: 37.5 | G5: =(E5-D5)*24 -> 12.5 | H5: =MIN(G5,8) -> 8 | I5: =IF(MAX(G5-8,0) - 1 < 0, 0, MAX(G5-8,0) - 1) -> 3.5 | J5: =H5*F5 -> 300 | K5: =I5*F5*1.2 -> 157.5 | L5: =J5+K5 -> 457.5
A6: Renelyn | B6: 8:30AM-9:00PM | C6: 2026-07-20 | D6: 09:00 | E6: 21:10 | F6: 37.5 | G6: =(E6-D6)*24 -> 12.166667 | H6: =MIN(G6,8) -> 8 | I6: =IF(MAX(G6-8,0) - 1 < 0, 0, MAX(G6-8,0) - 1) -> 3.1666667 | J6: =H6*F6 -> 300 | K6: =I6*F6*1.2 -> 142.5 | L6: =J6+K6 -> 442.5
A7: Renelyn | B7: 8:30AM-9:00PM | C7: 2026-07-21 | D7: 09:00 | E7: 21:00 | F7: 37.5 | G7: =(E7-D7)*24 -> 12 | H7: =MIN(G7,8) -> 8 | I7: =IF(MAX(G7-8,0) - 1 < 0, 0, MAX(G7-8,0) - 1) -> 3 | J7: =H7*F7 -> 300 | K7: =I7*F7*1.2 -> 135 | L7: =J7+K7 -> 435
A8: Renelyn | B8: 8:30AM-9:00PM | C8: 2026-07-22 | D8: 0 | E8: 0 | F8: 37.5 | G8: =(E8-D8)*24 -> 0 | H8: =MIN(G8,8) -> 0 | I8: =IF(MAX(G8-8,0) - 1 < 0, 0, MAX(G8-8,0) - 1) -> 0 | J8: =H8*F8 -> 0 | K8: =I8*F8*1.2 -> 0 | L8: =J8+K8 -> 0
A9: Renelyn | B9: 8:30AM-9:00PM | C9: 2026-07-23 | D9: 09:00 | E9: 21:00 | F9: 37.5 | G9: =(E9-D9)*24 -> 12 | H9: =MIN(G9,8) -> 8 | I9: =IF(MAX(G9-8,0) - 1 < 0, 0, MAX(G9-8,0) - 1) -> 3 | J9: =H9*F9 -> 300 | K9: =I9*F9*1.2 -> 135 | L9: =J9+K9 -> 435
A10: Renelyn | B10: 8:30AM-9:00PM | C10: 2026-07-24 | D10: 0 | E10: 0 | F10: 37.5 | G10: =(E10-D10)*24 -> 0 | H10: =MIN(G10,8) -> 0 | I10: =IF(MAX(G10-8,0) - 1 < 0, 0, MAX(G10-8,0) - 1) -> 0 | J10: =H10*F10 -> 0 | K10: =I10*F10*1.2 -> 0 | L10: =J10+K10 -> 0
A11: Renelyn | B11: 8:30AM-9:00PM | C11: 2026-07-25 | D11: 09:00 | E11: 21:00 | F11: 37.5 | G11: =(E11-D11)*24 -> 12 | H11: =MIN(G11,8) -> 8 | I11: =IF(MAX(G11-8,0) - 1 < 0, 0, MAX(G11-8,0) - 1) -> 3 | J11: =H11*F11 -> 300 | K11: =I11*F11*1.2 -> 135 | L11: =J11+K11 -> 435
A12: Renelyn | B12: 8:30AM-9:00PM | C12: 2026-07-26 | D12: 09:00 | E12: 21:00 | F12: 37.5 | G12: =(E12-D12)*24 -> 12 | H12: =MIN(G12,8) -> 8 | I12: =IF(MAX(G12-8,0) - 1 < 0, 0, MAX(G12-8,0) - 1) -> 3 | J12: =H12*F12 -> 300 | K12: =I12*F12*1.2 -> 135 | L12: =J12+K12 -> 435
A13: Renelyn | B13: 8:30AM-9:00PM | C13: 2026-07-27 | D13: 09:00 | E13: 18:00 | F13: 37.5 | G13: =(E13-D13)*24 -> 9 | H13: =MIN(G13,8) -> 8 | I13: =IF(MAX(G13-8,0) - 1 < 0, 0, MAX(G13-8,0) - 1) -> 0 | J13: =H13*F13 -> 300 | K13: =I13*F13*1.2 -> 0 | L13: =J13+K13 -> 300
... A17: Renelyn | B17: 8:30AM-9:00PM | C17: 2026-07-31 | D17: 09:00 | E17: 21:20 | F17: 37.5 | G17: =(E17-D17)*24 -> 12.333333 | H17: =MIN(G17,8) -> 8 | I17: =IF(MAX(G17-8,0) - 1 < 0, 0, MAX(G17-8,0) - 1) -> 3.3333333 | J17: =H17*F17 -> 300 | K17: =I17*F17*1.2 -> 150 | L17: =J17+K17 -> 450
A22: SUMMARY | B22: REGULAR PAY | C22: OVER TIME PAY | D22: TOTAL PAY
A23: Niel | B23: =SUM(J3:J21) -> 3600 | C23: =SUM(K3:K21) -> 1417.5 | D23: =SUM(L3:L21) -> 5017.5
A31: PAYROLL SLIP
A32: Name: | B32: =A3 -> Renelyn
A33: Job Title: | B33: Staff
A34: Payment Date: | B34: =C16+5 -> 46238
A35: Cut Off Period: | B35: =Marlon!B35 -> July-1 to July-15, 2026
A36: Days Worked | B36: =COUNTIF(D2:D19, "*:*") -> 13
A37: Adjustments
A38: Basic Pay | B38: =B23 -> 3600
A39: Bonus/Incentives | B39: 0
A40: Overtime Pay | B40: =C23 -> 1417.5
A41: Other Income | B41: 0
A44: Gross Pay | B44: =D23 -> 5017.5
A45: Deductions
A46: Sisig | B46: -150
A47: Short | B47: -315
A48: Net Pay | B48: =SUM(B44:B46) -> 4867.5

Sheet Cherry
A1: Employee | B1: Shift | C1: Date | D1: Time In | E1: Time Out | F1: Hourly Rate | G1: Total Hours | H1: Regular Hours | I1: Overtime Hours | J1: Regular Pay | K1: Overtime Pay | L1: Total Pay
A2: Cherry | B2: 8:30AM-9:00PM | C2: 2026-07-16 | D2: 09:00 | E2: 21:11 | F2: 46.875 | G2: =(E2-D2)*24 -> 12.183333 | H2: =MIN(G2,8) -> 8 | I2: =IF(MAX(G2-8,0) - 1 < 0, 0, MAX(G2-8,0) - 1) -> 3.1833333 | J2: =H2*F2 -> 375 | K2: =I2*F2*1.2 -> 179.0625 | L2: =J2+K2 -> 554.0625
A3: Cherry | B3: 8:30AM-9:00PM | C3: 2026-07-17 | D3: 09:00 | E3: 21:00 | F3: 46.875 | G3: =(E3-D3)*24 -> 12 | H3: =MIN(G3,8) -> 8 | I3: =IF(MAX(G3-8,0) - 1 < 0, 0, MAX(G3-8,0) - 1) -> 3 | J3: =H3*F3 -> 375 | K3: =I3*F3*1.2 -> 168.75 | L3: =J3+K3 -> 543.75
A4: Cherry | B4: 8:30AM-9:00PM | C4: 2026-07-18 | D4: 08:30 | E4: 21:00 | F4: 46.875 | G4: =(E4-D4)*24 -> 12.5 | H4: =MIN(G4,8) -> 8 | I4: =IF(MAX(G4-8,0) - 1 < 0, 0, MAX(G4-8,0) - 1) -> 3.5 | J4: =H4*F4 -> 375 | K4: =I4*F4*1.2 -> 196.875 | L4: =J4+K4 -> 571.875
A5: Cherry | B5: 8:30AM-9:00PM | C5: 2026-07-19 | D5: 09:00 | E5: 21:30 | F5: 46.875 | G5: =(E5-D5)*24 -> 12.5 | H5: =MIN(G5,8) -> 8 | I5: =IF(MAX(G5-8,0) - 1 < 0, 0, MAX(G5-8,0) - 1) -> 3.5 | J5: =H5*F5 -> 375 | K5: =I5*F5*1.2 -> 196.875 | L5: =J5+K5 -> 571.875
A6: Cherry | B6: 8:30AM-9:00PM | C6: 2026-07-20 | D6: 09:00 | E6: 21:10 | F6: 46.875 | G6: =(E6-D6)*24 -> 12.166667 | H6: =MIN(G6,8) -> 8 | I6: =IF(MAX(G6-8,0) - 1 < 0, 0, MAX(G6-8,0) - 1) -> 3.1666667 | J6: =H6*F6 -> 375 | K6: =I6*F6*1.2 -> 178.125 | L6: =J6+K6 -> 553.125
A7: Cherry | B7: 8:30AM-9:00PM | C7: 2026-07-21 | D7: 09:00 | E7: 21:00 | F7: 46.875 | G7: =(E7-D7)*24 -> 12 | H7: =MIN(G7,8) -> 8 | I7: =IF(MAX(G7-8,0) - 1 < 0, 0, MAX(G7-8,0) - 1) -> 3 | J7: =H7*F7 -> 375 | K7: =I7*F7*1.2 -> 168.75 | L7: =J7+K7 -> 543.75
A8: Cherry | B8: 8:30AM-9:00PM | C8: 2026-07-22 | D8: 0 | E8: 0 | F8: 46.875 | G8: =(E8-D8)*24 -> 0 | H8: =MIN(G8,8) -> 0 | I8: =IF(MAX(G8-8,0) - 1 < 0, 0, MAX(G8-8,0) - 1) -> 0 | J8: =H8*F8 -> 0 | K8: =I8*F8*1.2 -> 0 | L8: =J8+K8 -> 0
A9: Cherry | B9: 8:30AM-9:00PM | C9: 2026-07-23 | D9: 09:00 | E9: 21:00 | F9: 46.875 | G9: =(E9-D9)*24 -> 12 | H9: =MIN(G9,8) -> 8 | I9: =IF(MAX(G9-8,0) - 1 < 0, 0, MAX(G9-8,0) - 1) -> 3 | J9: =H9*F9 -> 375 | K9: =I9*F9*1.2 -> 168.75 | L9: =J9+K9 -> 543.75
A10: Cherry | B10: 8:30AM-9:00PM | C10: 2026-07-24 | D10: 09:00 | E10: 16:00 | F10: 46.875 | G10: =(E10-D10)*24 -> 7 | H10: =MIN(G10,8) -> 7 | I10: =IF(MAX(G10-8,0) - 1 < 0, 0, MAX(G10-8,0) - 1) -> 0 | J10: =H10*F10 -> 328.125 | K10: =I10*F10*1.2 -> 0 | L10: =J10+K10 -> 328.125
A11: Cherry | B11: 8:30AM-9:00PM | C11: 2026-07-25 | D11: 09:00 | E11: 21:00 | F11: 46.875 | G11: =(E11-D11)*24 -> 12 | H11: =MIN(G11,8) -> 8 | I11: =IF(MAX(G11-8,0) - 1 < 0, 0, MAX(G11-8,0) - 1) -> 3 | J11: =H11*F11 -> 375 | K11: =I11*F11*1.2 -> 168.75 | L11: =J11+K11 -> 543.75
A12: Cherry | B12: 8:30AM-9:00PM | C12: 2026-07-26 | D12: 09:00 | E12: 21:00 | F12: 46.875 | G12: =(E12-D12)*24 -> 12 | H12: =MIN(G12,8) -> 8 | I12: =IF(MAX(G12-8,0) - 1 < 0, 0, MAX(G12-8,0) - 1) -> 3 | J12: =H12*F12 -> 375 | K12: =I12*F12*1.2 -> 168.75 | L12: =J12+K12 -> 543.75
A13: Cherry | B13: 8:30AM-9:00PM | C13: 2026-07-27 | D13: 09:00 | E13: 21:00 | F13: 46.875 | G13: =(E13-D13)*24 -> 12 | H13: =MIN(G13,8) -> 8 | I13: =IF(MAX(G13-8,0) - 1 < 0, 0, MAX(G13-8,0) - 1) -> 3 | J13: =H13*F13 -> 375 | K13: =I13*F13*1.2 -> 168.75 | L13: =J13+K13 -> 543.75
... A17: Cherry | B17: 8:30AM-9:00PM | C17: 2026-07-31 | D17: 09:00 | E17: 21:20 | F17: 46.875 | G17: =(E17-D17)*24 -> 12.333333 | H17: =MIN(G17,8) -> 8 | I17: =IF(MAX(G17-8,0) - 1 < 0, 0, MAX(G17-8,0) - 1) -> 3.3333333 | J17: =H17*F17 -> 375 | K17: =I17*F17*1.2 -> 187.5 | L17: =J17+K17 -> 562.5
A21: SUMMARY | B21: REGULAR PAY | C21: OVER TIME PAY | D21: TOTAL PAY
A22: Cherry | B22: =SUM(J2:J20) -> 5203.125 | C22: =SUM(K2:K20) -> 2316.5625 | D22: =SUM(L2:L20) -> 7519.6875
A30: PAYROLL SLIP
A31: Name: | B31: =A2 -> Cherry
A32: Job Title: | B32: Staff
A33: Payment Date: | B33: =C16+5 -> 46238
A34: Cut Off Period: | B34: =Marlon!B35 -> July-1 to July-15, 2026
A35: Days Worked | B35: =COUNTIF(D1:D19, "*:*") -> 14
A36: Adjustments
A37: Basic Pay | B37: =B22 -> 5203.125
A38: Bonus/Incentives | B38: 500
A39: Overtime Pay | B39: =C22 -> 2316.5625
A40: Other Income | B40: 0
A43: Gross Pay | B43: =SUM(B37:B40) -> 8019.6875
A44: Deductions | B44: 0
A45: WH Tax | B45: 0
A47: Net Pay | B47: =SUM(B43:B46) -> 8019.6875

Sheet Marlon
A1: Employee | B1: Shift | C1: Date | D1: Time In | E1: Time Out | F1: Hourly Rate | G1: Total Hours | H1: Regular Hours | I1: Overtime Hours | J1: Regular Pay | K1: Overtime Pay | L1: Total Pay
A2: Marlon | B2: 8:30AM-9:00PM | C2: 2026-07-16 | D2: 09:00 | E2: 21:00 | F2: 37.5 | G2: =(E2-D2)*24 -> 12 | H2: =MIN(G2,8) -> 8 | I2: =IF(MAX(G2-8,0) - 1 < 0, 0, MAX(G2-8,0) - 1) -> 3 | J2: =H2*F2 -> 300 | K2: =I2*F2*1.2 -> 135 | L2: =J2+K2 -> 435
A3: Marlon | B3: 8:30AM-9:00PM | C3: 2026-07-17 | D3: 09:00 | E3: 21:00 | F3: 37.5 | G3: =(E3-D3)*24 -> 12 | H3: =MIN(G3,8) -> 8 | I3: =IF(MAX(G3-8,0) - 1 < 0, 0, MAX(G3-8,0) - 1) -> 3 | J3: =H3*F3 -> 300 | K3: =I3*F3*1.2 -> 135 | L3: =J3+K3 -> 435
A4: Marlon | B4: 8:30AM-9:00PM | C4: 2026-07-18 | D4: 08:30 | E4: 21:10 | F4: 37.5 | G4: =(E4-D4)*24 -> 12.666667 | H4: =MIN(G4,8) -> 8 | I4: =IF(MAX(G4-8,0) - 1 < 0, 0, MAX(G4-8,0) - 1) -> 3.6666667 | J4: =H4*F4 -> 300 | K4: =I4*F4*1.2 -> 165 | L4: =J4+K4 -> 465
A5: Marlon | B5: 8:30AM-9:00PM | C5: 2026-07-19 | D5: 09:00 | E5: 21:30 | F5: 37.5 | G5: =(E5-D5)*24 -> 12.5 | H5: =MIN(G5,8) -> 8 | I5: =IF(MAX(G5-8,0) - 1 < 0, 0, MAX(G5-8,0) - 1) -> 3.5 | J5: =H5*F5 -> 300 | K5: =I5*F5*1.2 -> 157.5 | L5: =J5+K5 -> 457.5
A6: Marlon | B6: 8:30AM-9:00PM | C6: 2026-07-20 | D6: 09:00 | E6: 21:00 | F6: 37.5 | G6: =(E6-D6)*24 -> 12 | H6: =MIN(G6,8) -> 8 | I6: =IF(MAX(G6-8,0) - 1 < 0, 0, MAX(G6-8,0) - 1) -> 3 | J6: =H6*F6 -> 300 | K6: =I6*F6*1.2 -> 135 | L6: =J6+K6 -> 435
A7: Marlon | B7: 8:30AM-9:00PM | C7: 2026-07-21 | D7: 09:00 | E7: 21:00 | F7: 37.5 | G7: =(E7-D7)*24 -> 12 | H7: =MIN(G7,8) -> 8 | I7: =IF(MAX(G7-8,0) - 1 < 0, 0, MAX(G7-8,0) - 1) -> 3 | J7: =H7*F7 -> 300 | K7: =I7*F7*1.2 -> 135 | L7: =J7+K7 -> 435
A8: Marlon | B8: 8:30AM-9:00PM | C8: 2026-07-22 | D8: 0 | E8: 0 | F8: 37.5 | G8: =(E8-D8)*24 -> 0 | H8: =MIN(G8,8) -> 0 | I8: =IF(MAX(G8-8,0) - 1 < 0, 0, MAX(G8-8,0) - 1) -> 0 | J8: =H8*F8 -> 0 | K8: =I8*F8*1.2 -> 0 | L8: =J8+K8 -> 0
A9: Marlon | B9: 8:30AM-9:00PM | C9: 2026-07-23 | D9: 09:00 | E9: 21:00 | F9: 37.5 | G9: =(E9-D9)*24 -> 12 | H9: =MIN(G9,8) -> 8 | I9: =IF(MAX(G9-8,0) - 1 < 0, 0, MAX(G9-8,0) - 1) -> 3 | J9: =H9*F9 -> 300 | K9: =I9*F9*1.2 -> 135 | L9: =J9+K9 -> 435
A10: Marlon | B10: 8:30AM-9:00PM | C10: 2026-07-24 | D10: 09:00 | E10: 21:30 | F10: 37.5 | G10: =(E10-D10)*24 -> 12.5 | H10: =MIN(G10,8) -> 8 | I10: =IF(MAX(G10-8,0) - 1 < 0, 0, MAX(G10-8,0) - 1) -> 3.5 | J10: =H10*F10 -> 300 | K10: =I10*F10*1.2 -> 157.5 | L10: =J10+K10 -> 457.5
A11: Marlon | B11: 8:30AM-9:00PM | C11: 2026-07-25 | D11: 0 | E11: 0 | F11: 37.5 | G11: =(E11-D11)*24 -> 0 | H11: =MIN(G11,8) -> 0 | I11: =IF(MAX(G11-8,0) - 1 < 0, 0, MAX(G11-8,0) - 1) -> 0 | J11: =H11*F11 -> 0 | K11: =I11*F11*1.2 -> 0 | L11: =J11+K11 -> 0
A12: Marlon | B12: 8:30AM-9:00PM | C12: 2026-07-26 | D12: 09:00 | E12: 21:00 | F12: 37.5 | G12: =(E12-D12)*24 -> 12 | H12: =MIN(G12,8) -> 8 | I12: =IF(MAX(G12-8,0) - 1 < 0, 0, MAX(G12-8,0) - 1) -> 3 | J12: =H12*F12 -> 300 | K12: =I12*F12*1.2 -> 135 | L12: =J12+K12 -> 435
A13: Marlon | B13: 8:30AM-9:00PM | C13: 2026-07-27 | D13: 09:00 | E13: 21:00 | F13: 37.5 | G13: =(E13-D13)*24 -> 12 | H13: =MIN(G13,8) -> 8 | I13: =IF(MAX(G13-8,0) - 1 < 0, 0, MAX(G13-8,0) - 1) -> 3 | J13: =H13*F13 -> 300 | K13: =I13*F13*1.2 -> 135 | L13: =J13+K13 -> 435
... A17: Marlon | B17: 8:30AM-9:00PM | C17: 2026-07-31 | D17: 09:00 | E17: 18:00 | F17: 37.5 | G17: =(E17-D17)*24 -> 9 | H17: =MIN(G17,8) -> 8 | I17: =IF(MAX(G17-8,0) - 1 < 0, 0, MAX(G17-8,0) - 1) -> 0 | J17: =H17*F17 -> 300 | K17: =I17*F17*1.2 -> 0 | L17: =J17+K17 -> 300
A22: SUMMARY | B22: REGULAR PAY | C22: OVER TIME PAY | D22: TOTAL PAY
A23: Marlon | B23: =SUM(J2:J21) -> 4200 | C23: =SUM(K2:K21) -> 1852.5 | D23: =SUM(L2:L21) -> 6052.5
A31: PAYROLL SLIP
A32: Name: | B32: Marlon
A33: Job Title: | B33: Cook
A34: Payment Date: | B34: =C16+5 -> 46238
A35: Cut Off Period: | B35: July-1 to July-15, 2026
A36: Days Worked | B36: =COUNTIF(D2:D19, "*:*") -> 14
A37: Adjustments
A38: Basic Pay | B38: =B23 -> 4200
A39: Bonus/Incentives | B39: 0
A40: Overtime Pay | B40: =C23 -> 1852.5
A41: Other Income | B41: 0
A43: Gross Pay | B43: =D23 -> 6052.5
A44: Deductions
A45: Allowance | B45: -500
A46: Allowance | B46: -500
A49: Net Pay | B49: =SUM(B43:B48) -> 5052.5

Sheet Lino
A1: Employee | B1: Shift | C1: Date | D1: Time In | E1: Time Out | F1: Hourly Rate | G1: Total Hours | H1: Regular Hours | I1: Overtime Hours | J1: Regular Pay | K1: Overtime Pay | L1: Total Pay
A2: Lino | B2: 10:00AM-9:00PM | C2: 2026-07-16 | D2: 0 | E2: 0 | F2: 25 | G2: =(E2-D2)*24 -> 0 | H2: =MIN(G2,8) -> 0 | I2: =IF(MAX(G2-8,0) - 1 < 0, 0, MAX(G2-8,0) - 1) -> 0 | J2: =H2*F2 -> 0 | K2: =I2*F2*1.2 -> 0 | L2: =J2+K2 -> 0
A3: Lino | B3: 10:00AM-9:00PM | C3: 2026-07-17 | D3: 09:00 | E3: 17:00 | F3: 25 | G3: =(E3-D3)*24 -> 8 | H3: =MIN(G3,8) -> 8 | I3: =IF(MAX(G3-8,0) - 1 < 0, 0, MAX(G3-8,0) - 1) -> 0 | J3: =H3*F3 -> 200 | K3: =I3*F3*1.2 -> 0 | L3: =J3+K3 -> 200
A4: Lino | B4: 10:00AM-9:00PM | C4: 2026-07-18 | D4: 09:00 | E4: 17:00 | F4: 25 | G4: =(E4-D4)*24 -> 8 | H4: =MIN(G4,8) -> 8 | I4: =IF(MAX(G4-8,0) - 1 < 0, 0, MAX(G4-8,0) - 1) -> 0 | J4: =H4*F4 -> 200 | K4: =I4*F4*1.2 -> 0 | L4: =J4+K4 -> 200
A5: Lino | B5: 10:00AM-9:00PM | C5: 2026-07-19 | D5: 09:00 | E5: 17:00 | F5: 25 | G5: =(E5-D5)*24 -> 8 | H5: =MIN(G5,8) -> 8 | I5: =IF(MAX(G5-8,0) - 1 < 0, 0, MAX(G5-8,0) - 1) -> 0 | J5: =H5*F5 -> 200 | K5: =I5*F5*1.2 -> 0 | L5: =J5+K5 -> 200
A6: Lino | B6: 10:00AM-9:00PM | C6: 2026-07-20 | D6: 09:19 | E6: 21:10 | F6: 25 | G6: =(E6-D6)*24 -> 11.85 | H6: =MIN(G6,8) -> 8 | I6: =IF(MAX(G6-8,0) - 1 < 0, 0, MAX(G6-8,0) - 1) -> 2.85 | J6: =H6*F6 -> 200 | K6: =I6*F6*1.2 -> 85.5 | L6: =J6+K6 -> 285.5
A7: Lino | B7: 10:00AM-9:00PM | C7: 2026-07-21 | D7: 09:00 | E7: 21:00 | F7: 25 | G7: =(E7-D7)*24 -> 12 | H7: =MIN(G7,8) -> 8 | I7: =IF(MAX(G7-8,0) - 1 < 0, 0, MAX(G7-8,0) - 1) -> 3 | J7: =H7*F7 -> 200 | K7: =I7*F7*1.2 -> 90 | L7: =J7+K7 -> 290
A8: Lino | B8: 10:00AM-9:00PM | C8: 2026-07-22 | D8: 0 | E8: 0 | F8: 25 | G8: =(E8-D8)*24 -> 0 | H8: =MIN(G8,8) -> 0 | I8: =IF(MAX(G8-8,0) - 1 < 0, 0, MAX(G8-8,0) - 1) -> 0 | J8: =H8*F8 -> 0 | K8: =I8*F8*1.2 -> 0 | L8: =J8+K8 -> 0
A9: Lino | B9: 10:00AM-9:00PM | C9: 2026-07-23 | D9: 09:00 | E9: 21:00 | F9: 25 | G9: =(E9-D9)*24 -> 12 | H9: =MIN(G9,8) -> 8 | I9: =IF(MAX(G9-8,0) - 1 < 0, 0, MAX(G9-8,0) - 1) -> 3 | J9: =H9*F9 -> 200 | K9: =I9*F9*1.2 -> 90 | L9: =J9+K9 -> 290
A10: Lino | B10: 10:00AM-9:00PM | C10: 2026-07-24 | D10: 09:00 | E10: 21:30 | F10: 25 | G10: =(E10-D10)*24 -> 12.5 | H10: =MIN(G10,8) -> 8 | I10: =IF(MAX(G10-8,0) - 1 < 0, 0, MAX(G10-8,0) - 1) -> 3.5 | J10: =H10*F10 -> 200 | K10: =I10*F10*1.2 -> 105 | L10: =J10+K10 -> 305
A11: Lino | B11: 10:00AM-9:00PM | C11: 2026-07-25 | D11: 09:00 | E11: 21:00 | F11: 25 | G11: =(E11-D11)*24 -> 12 | H11: =MIN(G11,8) -> 8 | I11: =IF(MAX(G11-8,0) - 1 < 0, 0, MAX(G11-8,0) - 1) -> 3 | J11: =H11*F11 -> 200 | K11: =I11*F11*1.2 -> 90 | L11: =J11+K11 -> 290
A12: Lino | B12: 10:00AM-9:00PM | C12: 2026-07-26 | D12: 0 | E12: 0 | F12: 25 | G12: =(E12-D12)*24 -> 0 | H12: =MIN(G12,8) -> 0 | I12: =IF(MAX(G12-8,0) - 1 < 0, 0, MAX(G12-8,0) - 1) -> 0 | J12: =H12*F12 -> 0 | K12: =I12*F12*1.2 -> 0 | L12: =J12+K12 -> 0
A13: Lino | B13: 10:00AM-9:00PM | C13: 2026-07-27 | D13: 09:16 | E13: 21:00 | F13: 25 | G13: =(E13-D13)*24 -> 11.733333 | H13: =MIN(G13,8) -> 8 | I13: =IF(MAX(G13-8,0) - 1 < 0, 0, MAX(G13-8,0) - 1) -> 2.7333333 | J13: =H13*F13 -> 200 | K13: =I13*F13*1.2 -> 82 | L13: =J13+K13 -> 282
... A17: Lino | B17: 10:00AM-9:00PM | C17: 2026-07-31 | D17: 09:00 | E17: 21:10 | F17: 25 | G17: =(E17-D17)*24 -> 12.166667 | H17: =MIN(G17,8) -> 8 | I17: =IF(MAX(G17-8,0) - 1 < 0, 0, MAX(G17-8,0) - 1) -> 3.1666667 | J17: =H17*F17 -> 200 | K17: =I17*F17*1.2 -> 95 | L17: =J17+K17 -> 295
A23: SUMMARY | B23: REGULAR PAY | C23: OVER TIME PAY | D23: TOTAL PAY
A24: Kim | B24: =SUM(J2:J22) -> 2600 | C24: =SUM(K2:K22) -> 912.5 | D24: =SUM(L2:L22) -> 3512.5
A28: PAYROLL SLIP
A29: Name: | B29: =A2 -> Lino
A30: Job Title: | B30: Staff
A31: Payment Date: | B31: =C16+5 -> 46238
A32: Cut Off Period: | B32: =Marlon!B35 -> July-1 to July-15, 2026
A33: Days Worked | B33: =COUNTIF(D2:D18, "*:*") -> 13
A34: Adjustments
A35: Basic Pay | B35: =B24 -> 2600
A36: Bonus/Incentives | B36: 0
A37: Overtime Pay | B37: =C24 -> 912.5
A38: Other Income | B38: 0
A41: Gross Pay | B41: =D24 -> 3512.5
A42: Deductions | B42: 0
A43: .
A44: Net Pay | B44: =SUM(B41:B42) -> 3512.5

Sheet Nino
A1: Employee | B1: Shift | C1: Date | D1: Time In | E1: Time Out | F1: Hourly Rate | G1: Total Hours | H1: Regular Hours | I1: Overtime Hours | J1: Regular Pay | K1: Overtime Pay | L1: Total Pay
A2: Nino | B2: 10:00AM-9:00PM | C2: 2026-07-16 | D2: 8:00 | E2: 17:50 | F2: 35 | G2: =(E2-D2)*24 -> 9.8333333 | H2: =MIN(G2,8) -> 8 | I2: =IF(MAX(G2-8,0) - 1 < 0, 0, MAX(G2-8,0) - 1) -> 0.83333333 | J2: =H2*F2 -> 280 | K2: =I2*F2*1.2 -> 35 | L2: =J2+K2 -> 315
A3: Nino | B3: 10:00AM-9:00PM | C3: 2026-07-17 | D3: 8:00 | E3: 16:45 | F3: 35 | G3: =(E3-D3)*24 -> 8.75 | H3: =MIN(G3,8) -> 8 | I3: =IF(MAX(G3-8,0) - 1 < 0, 0, MAX(G3-8,0) - 1) -> 0 | J3: =H3*F3 -> 280 | K3: =I3*F3*1.2 -> 0 | L3: =J3+K3 -> 280
A4: Nino | B4: 10:00AM-9:00PM | C4: 2026-07-18 | D4: 8:00 | E4: 16:20 | F4: 35 | G4: =(E4-D4)*24 -> 8.3333333 | H4: =MIN(G4,8) -> 8 | I4: =IF(MAX(G4-8,0) - 1 < 0, 0, MAX(G4-8,0) - 1) -> 0 | J4: =H4*F4 -> 280 | K4: =I4*F4*1.2 -> 0 | L4: =J4+K4 -> 280
A5: Nino | B5: 10:00AM-9:00PM | C5: 2026-07-19 | D5: 0 | E5: 0 | F5: 35 | G5: =(E5-D5)*24 -> 0 | H5: =MIN(G5,8) -> 0 | I5: =IF(MAX(G5-8,0) - 1 < 0, 0, MAX(G5-8,0) - 1) -> 0 | J5: =H5*F5 -> 0 | K5: =I5*F5*1.2 -> 0 | L5: =J5+K5 -> 0
A6: Nino | B6: 10:00AM-9:00PM | C6: 2026-07-20 | D6: 8:00 | E6: 13:55 | F6: 35 | G6: =(E6-D6)*24 -> 5.9166667 | H6: =MIN(G6,8) -> 5.9166667 | I6: =IF(MAX(G6-8,0) - 1 < 0, 0, MAX(G6-8,0) - 1) -> 0 | J6: =H6*F6 -> 207.08333 | K6: =I6*F6*1.2 -> 0 | L6: =J6+K6 -> 207.08333
A7: Nino | B7: 10:00AM-9:00PM | C7: 2026-07-21 | D7: 0 | E7: 0 | F7: 35 | G7: =(E7-D7)*24 -> 0 | H7: =MIN(G7,8) -> 0 | I7: =IF(MAX(G7-8,0) - 1 < 0, 0, MAX(G7-8,0) - 1) -> 0 | J7: =H7*F7 -> 0 | K7: =I7*F7*1.2 -> 0 | L7: =J7+K7 -> 0
A8: Nino | B8: 10:00AM-9:00PM | C8: 2026-07-22 | D8: 8:00 | E8: 16:05 | F8: 35 | G8: =(E8-D8)*24 -> 8.0833333 | H8: =MIN(G8,8) -> 8 | I8: =IF(MAX(G8-8,0) - 1 < 0, 0, MAX(G8-8,0) - 1) -> 0 | J8: =H8*F8 -> 280 | K8: =I8*F8*1.2 -> 0 | L8: =J8+K8 -> 280
A9: Nino | B9: 10:00AM-9:00PM | C9: 2026-07-23 | D9: 8:00 | E9: 13:20 | F9: 35 | G9: =(E9-D9)*24 -> 5.3333333 | H9: =MIN(G9,8) -> 5.3333333 | I9: =IF(MAX(G9-8,0) - 1 < 0, 0, MAX(G9-8,0) - 1) -> 0 | J9: =H9*F9 -> 186.66667 | K9: =I9*F9*1.2 -> 0 | L9: =J9+K9 -> 186.66667
A10: Nino | B10: 10:00AM-9:00PM | C10: 2026-07-24 | D10: 8:00 | E10: 17:45 | F10: 35 | G10: =(E10-D10)*24 -> 9.75 | H10: =MIN(G10,8) -> 8 | I10: =IF(MAX(G10-8,0) - 1 < 0, 0, MAX(G10-8,0) - 1) -> 0.75 | J10: =H10*F10 -> 280 | K10: =I10*F10*1.2 -> 31.5 | L10: =J10+K10 -> 311.5
A11: Nino | B11: 10:00AM-9:00PM | C11: 2026-07-25 | D11: 8:00 | E11: 12:40 | F11: 35 | G11: =(E11-D11)*24 -> 4.6666667 | H11: =MIN(G11,8) -> 4.6666667 | I11: =IF(MAX(G11-8,0) - 1 < 0, 0, MAX(G11-8,0) - 1) -> 0 | J11: =H11*F11 -> 163.33333 | K11: =I11*F11*1.2 -> 0 | L11: =J11+K11 -> 163.33333
A12: Nino | B12: 10:00AM-9:00PM | C12: 2026-07-26 | D12: 0 | E12: 0 | F12: 35 | G12: =(E12-D12)*24 -> 0 | H12: =MIN(G12,8) -> 0 | I12: =IF(MAX(G12-8,0) - 1 < 0, 0, MAX(G12-8,0) - 1) -> 0 | J12: =H12*F12 -> 0 | K12: =I12*F12*1.2 -> 0 | L12: =J12+K12 -> 0
A13: Nino | B13: 10:00AM-9:00PM | C13: 2026-07-27 | D13: 09:39 | E13: 18:00 | F13: 35 | G13: =(E13-D13)*24 -> 8.35 | H13: =MIN(G13,8) -> 8 | I13: =IF(MAX(G13-8,0) - 1 < 0, 0, MAX(G13-8,0) - 1) -> 0 | J13: =H13*F13 -> 280 | K13: =I13*F13*1.2 -> 0 | L13: =J13+K13 -> 280
... A17: Nino | B17: 10:00AM-9:00PM | C17: 2026-07-31 | D17: 0 | E17: 0 | F17: 35 | G17: =(E17-D17)*24 -> 0 | H17: =MIN(G17,8) -> 0 | I17: =IF(MAX(G17-8,0) - 1 < 0, 0, MAX(G17-8,0) - 1) -> 0 | J17: =H17*F17 -> 0 | K17: =I17*F17*1.2 -> 0 | L17: =J17+K17 -> 0
A23: SUMMARY | B23: REGULAR PAY | C23: OVER TIME PAY | D23: TOTAL PAY
A24: Kim | B24: =SUM(J2:J22) -> 2738.75 | C24: =SUM(K2:K22) -> 66.5 | D24: =SUM(L2:L22) -> 2805.25
A28: PAYROLL SLIP
A29: Name: | B29: =A2 -> Nino
A30: Job Title: | B30: Staff
A31: Payment Date: | B31: =C16+5 -> 46238
A32: Cut Off Period: | B32: =Marlon!B35 -> July-1 to July-15, 2026
A33: Days Worked | B33: =COUNTIF(D2:D18, "*:*") -> 11
A34: Adjustments
A35: Basic Pay | B35: =B24 -> 2738.75
A36: Bonus/Incentives | B36: 0
A37: Overtime Pay | B37: =C24 -> 66.5
A38: Other Income | B38: 0
A41: Gross Pay | B41: =D24 -> 2805.25
A42: Deductions
A43: Allowance | B43: -500
A44: Allowance | B44: -500
A45: Charge PRK BBQ | B45: -375
A46: Net Pay | B46: =SUM(B41:B44) -> 1805.25

Sheet Ralph
A1: Employee | B1: Shift | C1: Date | D1: Time In | E1: Time Out | F1: Hourly Rate | G1: Total Hours | H1: Regular Hours | I1: Overtime Hours | J1: Regular Pay | K1: Overtime Pay | L1: Total Pay
A2: Ralph | B2: 9:00AM-9:00PM | C2: 2026-07-16 | D2: 8:00 | E2: 17:50 | F2: 35 | G2: =(E2-D2)*24 -> 9.8333333 | H2: =MIN(G2,8) -> 8 | I2: =IF(MAX(G2-8,0) - 1 < 0, 0, MAX(G2-8,0) - 1) -> 0.83333333 | J2: =H2*F2 -> 280 | K2: =I2*F2*1.2 -> 35 | L2: =J2+K2 -> 315
A3: Ralph | B3: 9:00AM-9:00PM | C3: 2026-07-17 | D3: 8:00 | E3: 16:45 | F3: 35 | G3: =(E3-D3)*24 -> 8.75 | H3: =MIN(G3,8) -> 8 | I3: =IF(MAX(G3-8,0) - 1 < 0, 0, MAX(G3-8,0) - 1) -> 0 | J3: =H3*F3 -> 280 | K3: =I3*F3*1.2 -> 0 | L3: =J3+K3 -> 280
A4: Ralph | B4: 9:00AM-9:00PM | C4: 2026-07-18 | D4: 8:00 | E4: 16:20 | F4: 35 | G4: =(E4-D4)*24 -> 8.3333333 | H4: =MIN(G4,8) -> 8 | I4: =IF(MAX(G4-8,0) - 1 < 0, 0, MAX(G4-8,0) - 1) -> 0 | J4: =H4*F4 -> 280 | K4: =I4*F4*1.2 -> 0 | L4: =J4+K4 -> 280
A5: Ralph | B5: 9:00AM-9:00PM | C5: 2026-07-19 | D5: 8:00 | E5: 12:58 | F5: 35 | G5: =(E5-D5)*24 -> 4.9666667 | H5: =MIN(G5,8) -> 4.9666667 | I5: =IF(MAX(G5-8,0) - 1 < 0, 0, MAX(G5-8,0) - 1) -> 0 | J5: =H5*F5 -> 173.83333 | K5: =I5*F5*1.2 -> 0 | L5: =J5+K5 -> 173.83333
A6: Ralph | B6: 9:00AM-9:00PM | C6: 2026-07-20 | D6: 8:00 | E6: 13:55 | F6: 35 | G6: =(E6-D6)*24 -> 5.9166667 | H6: =MIN(G6,8) -> 5.9166667 | I6: =IF(MAX(G6-8,0) - 1 < 0, 0, MAX(G6-8,0) - 1) -> 0 | J6: =H6*F6 -> 207.08333 | K6: =I6*F6*1.2 -> 0 | L6: =J6+K6 -> 207.08333
A7: Ralph | B7: 9:00AM-9:00PM | C7: 2026-07-21 | D7: 13:00 | E7: 18:40 | F7: 35 | G7: =(E7-D7)*24 -> 5.6666667 | H7: =MIN(G7,8) -> 5.6666667 | I7: =IF(MAX(G7-8,0) - 1 < 0, 0, MAX(G7-8,0) - 1) -> 0 | J7: =H7*F7 -> 198.33333 | K7: =I7*F7*1.2 -> 0 | L7: =J7+K7 -> 198.33333
A8: Ralph | B8: 9:00AM-9:00PM | C8: 2026-07-22 | D8: 8:00 | E8: 16:05 | F8: 35 | G8: =(E8-D8)*24 -> 8.0833333 | H8: =MIN(G8,8) -> 8 | I8: =IF(MAX(G8-8,0) - 1 < 0, 0, MAX(G8-8,0) - 1) -> 0 | J8: =H8*F8 -> 280 | K8: =I8*F8*1.2 -> 0 | L8: =J8+K8 -> 280
A9: Ralph | B9: 9:00AM-9:00PM | C9: 2026-07-23 | D9: 8:00 | E9: 13:20 | F9: 35 | G9: =(E9-D9)*24 -> 5.3333333 | H9: =MIN(G9,8) -> 5.3333333 | I9: =IF(MAX(G9-8,0) - 1 < 0, 0, MAX(G9-8,0) - 1) -> 0 | J9: =H9*F9 -> 186.66667 | K9: =I9*F9*1.2 -> 0 | L9: =J9+K9 -> 186.66667
A10: Ralph | B10: 9:00AM-9:00PM | C10: 2026-07-24 | D10: 8:00 | E10: 17:54 | F10: 35 | G10: =(E10-D10)*24 -> 9.9 | H10: =MIN(G10,8) -> 8 | I10: =IF(MAX(G10-8,0) - 1 < 0, 0, MAX(G10-8,0) - 1) -> 0.9 | J10: =H10*F10 -> 280 | K10: =I10*F10*1.2 -> 37.8 | L10: =J10+K10 -> 317.8
A11: Ralph | B11: 9:00AM-9:00PM | C11: 2026-07-25 | D11: 8:00 | E11: 12:40 | F11: 35 | G11: =(E11-D11)*24 -> 4.6666667 | H11: =MIN(G11,8) -> 4.6666667 | I11: =IF(MAX(G11-8,0) - 1 < 0, 0, MAX(G11-8,0) - 1) -> 0 | J11: =H11*F11 -> 163.33333 | K11: =I11*F11*1.2 -> 0 | L11: =J11+K11 -> 163.33333
A12: Ralph | B12: 9:00AM-9:00PM | C12: 2026-07-26 | D12: 0 | E12: 0 | F12: 35 | G12: =(E12-D12)*24 -> 0 | H12: =MIN(G12,8) -> 0 | I12: =IF(MAX(G12-8,0) - 1 < 0, 0, MAX(G12-8,0) - 1) -> 0 | J12: =H12*F12 -> 0 | K12: =I12*F12*1.2 -> 0 | L12: =J12+K12 -> 0
A13: Ralph | B13: 9:00AM-9:00PM | C13: 2026-07-27 | D13: 8:00 | E13: 19:00 | F13: 35 | G13: =(E13-D13)*24 -> 11 | H13: =MIN(G13,8) -> 8 | I13: =IF(MAX(G13-8,0) - 1 < 0, 0, MAX(G13-8,0) - 1) -> 2 | J13: =H13*F13 -> 280 | K13: =I13*F13*1.2 -> 84 | L13: =J13+K13 -> 364
... A17: Ralph | B17: 9:00AM-9:00PM | C17: 2026-07-31 | D17: 8:00 | E17: 15:02 | F17: 35 | G17: =(E17-D17)*24 -> 7.0333333 | H17: =MIN(G17,8) -> 7.0333333 | I17: =IF(MAX(G17-8,0) - 1 < 0, 0, MAX(G17-8,0) - 1) -> 0 | J17: =H17*F17 -> 246.16667 | K17: =I17*F17*1.2 -> 0 | L17: =J17+K17 -> 246.16667
A22: SUMMARY | B22: REGULAR PAY | C22: OVER TIME PAY | D22: TOTAL PAY
A23: Mark | B23: =SUM(J2:J21) -> 3567.0833 | C23: =SUM(K2:K21) -> 156.8 | D23: =SUM(L2:L21) -> 3723.8833
A31: PAYROLL SLIP
A32: Name: | B32: =A2 -> Ralph
A33: Job Title: | B33: Staff
A34: Payment Date: | B34: =C16+5 -> 46238
A35: Cut Off Period: | B35: =Marlon!B35 -> July-1 to July-15, 2026
A36: Days Worked | B36: =COUNTIF(D2:D18, "*:*") -> 15
A37: Adjustments
A38: Basic Pay | B38: =B23 -> 3567.0833
A39: Bonus/Incentives | B39: 0
A40: Overtime Pay | B40: =C23 -> 156.8
A41: Other Income | B41: 0
A44: Gross Pay | B44: =SUM(B38:B41) -> 3723.8833
A45: Deductions | B45: 0
A46: WH Tax | B46: 0
A48: Net Pay | B48: =SUM(B44:B46) -> 3723.8833

Sheet David
A1: Employee | B1: Shift | C1: Date | D1: Time In | E1: Time Out | F1: Hourly Rate | G1: Total Hours | H1: Regular Hours | I1: Overtime Hours | J1: Regular Pay | K1: Overtime Pay | L1: Total Pay
A2: David | B2: 5:00PM-10:00PM | C2: 2026-06-01 | D2: 09:00 | E2: 0 | L2: 605
A3: David | B3: 5:00PM-10:00PM | C3: 2026-06-03 | D3: 09:01 | E3: 0 | L3: 550
A4: David | B4: 5:00PM-10:00PM | C4: 2026-06-03 | D4: 09:02 | E4: 0 | L4: 495
A5: David | B5: 5:00PM-10:00PM | C5: 2026-06-07 | D5: 09:03 | E5: 0 | L5: 605
A6: David | B6: 5:00PM-10:00PM | C6: 2026-06-08 | D6: 09:04 | E6: 0 | L6: 550
A7: David | B7: 9:30AM-10:00PM | C7: 2026-06-14 | D7: 09:05 | E7: 0 | L7: 510
A8: David | B8: 9:30AM-10:00PM | C8: 2026-06-15 | D8: 09:05 | E8: 0 | L8: 540
A14: SUMMARY | B14: REGULAR PAY | C14: OVER TIME PAY | D14: TOTAL PAY
A15: Lenard | B15: =SUM(J2:J13) -> 0 | C15: =SUM(K2:K13) -> 0 | D15: =SUM(L2:L13) -> 3855
A23: PAYROLL SLIP
A24: Name: | B24: =A2 -> David
A25: Job Title: | B25: Staff
A26: Payment Date: | B26: 46193
A27: Cut Off Period: | B27: =Marlon!B35 -> July-1 to July-15, 2026
A28: Days Worked | B28: =COUNTIF(D2:D8, "*:*") -> 7
A29: Adjustments
A30: Basic Pay | B30: =D15 -> 3855
A31: Bonus/Incentives | B31: 0
A32: Overtime Pay | B32: =C15 -> 0
A33: Other Income | B33: 0
A36: Gross Pay | B36: =D15 -> 3855
A37: Deductions | B37: -1147
A38: WH Tax | B38: 0
A40: Net Pay | B40: =SUM(B36:B38) -> 2708

Sheet Kris
A1: Employee | B1: Shift | C1: Date | D1: Time In | E1: Time Out | F1: Hourly Rate | G1: Total Hours | H1: Regular Hours | I1: Overtime Hours | J1: Regular Pay | K1: Overtime Pay | L1: Total Pay
A2: Kris Naynayan | B2: 8:30AM-9:00PM | C2: 2026-04-27 | D2: 0 | E2: 0 | F2: 40.86 | G2: =(E2-D2)*24 -> 0 | H2: =MIN(G2,8) -> 0 | I2: =IF(MAX(G2-8,0) - 1 < 0, 0, MAX(G2-8,0) - 1) -> 0 | J2: =H2*F2 -> 0 | K2: =I2*F2*1.2 -> 0 | L2: =J2+K2 -> 0
A3: Kris Naynayan | B3: 8:30AM-9:00PM | C3: 2026-04-21 | D3: 0 | E3: 0 | F3: 40.86 | G3: =(E3-D3)*24 -> 0 | H3: =MIN(G3,8) -> 0 | I3: =IF(MAX(G3-8,0) - 1 < 0, 0, MAX(G3-8,0) - 1) -> 0 | J3: =H3*F3 -> 0 | K3: =I3*F3*1.2 -> 0 | L3: =J3+K3 -> 0
A4: Kris Naynayan | B4: 8:30AM-9:00PM | C4: 2026-04-22 | D4: 0 | E4: 0 | F4: 40.86 | G4: =(E4-D4)*24 -> 0 | H4: =MIN(G4,8) -> 0 | I4: =IF(MAX(G4-8,0) - 1 < 0, 0, MAX(G4-8,0) - 1) -> 0 | J4: =H4*F4 -> 0 | K4: =I4*F4*1.2 -> 0 | L4: =J4+K4 -> 0
A5: Kris Naynayan | B5: 8:30AM-9:00PM | C5: 2026-04-23 | D5: 0 | E5: 0 | F5: 40.86 | G5: =(E5-D5)*24 -> 0 | H5: =MIN(G5,8) -> 0 | I5: =IF(MAX(G5-8,0) - 1 < 0, 0, MAX(G5-8,0) - 1) -> 0 | J5: =H5*F5 -> 0 | K5: =I5*F5*1.2 -> 0 | L5: =J5+K5 -> 0
A6: Kris Naynayan | B6: 8:30AM-9:00PM | C6: 2026-04-24 | D6: 0 | E6: 0 | F6: 40.86 | G6: =(E6-D6)*24 -> 0 | H6: =MIN(G6,8) -> 0 | I6: =IF(MAX(G6-8,0) - 1 < 0, 0, MAX(G6-8,0) - 1) -> 0 | J6: =H6*F6 -> 0 | K6: =I6*F6*1.2 -> 0 | L6: =J6+K6 -> 0
A7: Kris Naynayan | B7: 8:30AM-9:00PM | C7: 2026-04-25 | D7: 0 | E7: 0 | F7: 40.86 | G7: =(E7-D7)*24 -> 0 | H7: =MIN(G7,8) -> 0 | I7: =IF(MAX(G7-8,0) - 1 < 0, 0, MAX(G7-8,0) - 1) -> 0 | J7: =H7*F7 -> 0 | K7: =I7*F7*1.2 -> 0 | L7: =J7+K7 -> 0
A8: Kris Naynayan | B8: 8:30AM-9:00PM | C8: 2026-04-26 | D8: 0 | E8: 0 | F8: 40.86 | G8: =(E8-D8)*24 -> 0 | H8: =MIN(G8,8) -> 0 | I8: =IF(MAX(G8-8,0) - 1 < 0, 0, MAX(G8-8,0) - 1) -> 0 | J8: =H8*F8 -> 0 | K8: =I8*F8*1.2 -> 0 | L8: =J8+K8 -> 0
A9: Kris Naynayan | B9: 8:30AM-9:00PM | C9: 2026-04-27 | D9: 08:00 | E9: 17:00 | F9: 40.86 | G9: =(E9-D9)*24 -> 9 | H9: =MIN(G9,8) -> 8 | I9: =IF(MAX(G9-8,0) - 1 < 0, 0, MAX(G9-8,0) - 1) -> 1.7763568e-15 | J9: =H9*F9 -> 326.88 | K9: =I9*F9*1.2 -> 8.7098329e-14 | L9: =J9+K9 -> 326.88
A10: Kris Naynayan | B10: 8:30AM-9:00PM | C10: 2026-04-21 | D10: 0 | E10: 0 | F10: 40.86 | G10: =(E10-D10)*24 -> 0 | H10: =MIN(G10,8) -> 0 | I10: =IF(MAX(G10-8,0) - 1 < 0, 0, MAX(G10-8,0) - 1) -> 0 | J10: =H10*F10 -> 0 | K10: =I10*F10*1.2 -> 0 | L10: =J10+K10 -> 0
A11: Kris Naynayan | B11: 8:30AM-9:00PM | C11: 2026-04-22 | D11: 0 | E11: 0 | F11: 40.86 | G11: =(E11-D11)*24 -> 0 | H11: =MIN(G11,8) -> 0 | I11: =IF(MAX(G11-8,0) - 1 < 0, 0, MAX(G11-8,0) - 1) -> 0 | J11: =H11*F11 -> 0 | K11: =I11*F11*1.2 -> 0 | L11: =J11+K11 -> 0
A12: Kris Naynayan | B12: 8:30AM-9:00PM | C12: 2026-04-23 | D12: 0 | E12: 0 | F12: 40.86 | G12: =(E12-D12)*24 -> 0 | H12: =MIN(G12,8) -> 0 | I12: =IF(MAX(G12-8,0) - 1 < 0, 0, MAX(G12-8,0) - 1) -> 0 | J12: =H12*F12 -> 0 | K12: =I12*F12*1.2 -> 0 | L12: =J12+K12 -> 0
A13: Kris Naynayan | B13: 8:30AM-9:00PM | C13: 2026-04-24 | D13: 0 | E13: 0 | F13: 40.86 | G13: =(E13-D13)*24 -> 0 | H13: =MIN(G13,8) -> 0 | I13: =IF(MAX(G13-8,0) - 1 < 0, 0, MAX(G13-8,0) - 1) -> 0 | J13: =H13*F13 -> 0 | K13: =I13*F13*1.2 -> 0 | L13: =J13+K13 -> 0
... A16: Kris Naynayan | B16: 8:30AM-9:00PM | C16: 2026-04-26 | D16: 0 | E16: 0 | F16: 40.86 | G16: =(E16-D16)*24 -> 0 | H16: =MIN(G16,8) -> 0 | I16: =IF(MAX(G16-8,0) - 1 < 0, 0, MAX(G16-8,0) - 1) -> 0 | J16: =H16*F16 -> 0 | K16: =I16*F16*1.2 -> 0 | L16: =J16+K16 -> 0
A21: SUMMARY | B21: REGULAR PAY | C21: OVER TIME PAY | D21: TOTAL PAY
A22: Kris Naynayan | B22: =SUM(J2:J20) -> 326.88 | C22: =SUM(K2:K20) -> 8.7098329e-14 | D22: =SUM(L2:L20) -> 326.88
A30: PAYROLL SLIP
A31: Name: | B31: =A2 -> Kris Naynayan
A32: Job Title: | B32: Staff
A33: Payment Date: | B33: =C8+1 -> 46139
A34: Cut Off Period: | B34: =Marlon!B35 -> July-1 to July-15, 2026
A35: Days Worked | B35: =COUNTIF(D2:D8, "*:*") -> 0
A36: Adjustments
A37: Basic Pay | B37: =B22 -> 326.88
A38: Bonus/Incentives | B38: 0
A39: Overtime Pay | B39: =C22 -> 8.7098329e-14
A40: Other Income | B40: 0
A43: Gross Pay | B43: =D22 -> 326.88
A44: Deductions | B44: 0
A45: WH Tax | B45: 0
A47: Net Pay | B47: =SUM(B43:B45) -> 326.88

Sheet Brett
A1: Employee | B1: Shift | C1: Date | D1: Time In | E1: Time Out | F1: Hourly Rate | G1: Total Hours | H1: Regular Hours | I1: Overtime Hours | J1: Regular Pay | K1: Overtime Pay | L1: Total Pay
A2: Brett | B2: 10:00AM-9:00PM | C2: 2026-07-01 | D2: 0 | E2: 0 | F2: 31.25 | G2: =(E2-D2)*24 -> 0 | H2: =MIN(G2,8) -> 0 | I2: =IF(MAX(G2-8,0) - 1 < 0, 0, MAX(G2-8,0) - 1) -> 0 | J2: =H2*F2 -> 0 | K2: =I2*F2*1.2 -> 0 | L2: =J2+K2 -> 0
A3: Brett | B3: 10:00AM-9:00PM | C3: 2026-07-02 | D3: 0 | E3: 0 | F3: 31.25 | G3: =(E3-D3)*24 -> 0 | H3: =MIN(G3,8) -> 0 | I3: =IF(MAX(G3-8,0) - 1 < 0, 0, MAX(G3-8,0) - 1) -> 0 | J3: =H3*F3 -> 0 | K3: =I3*F3*1.2 -> 0 | L3: =J3+K3 -> 0
A4: Brett | B4: 10:00AM-9:00PM | C4: 2026-07-03 | D4: 0 | E4: 0 | F4: 31.25 | G4: =(E4-D4)*24 -> 0 | H4: =MIN(G4,8) -> 0 | I4: =IF(MAX(G4-8,0) - 1 < 0, 0, MAX(G4-8,0) - 1) -> 0 | J4: =H4*F4 -> 0 | K4: =I4*F4*1.2 -> 0 | L4: =J4+K4 -> 0
A5: Brett | B5: 10:00AM-9:00PM | C5: 2026-07-04 | D5: 0 | E5: 0 | F5: 31.25 | G5: =(E5-D5)*24 -> 0 | H5: =MIN(G5,8) -> 0 | I5: =IF(MAX(G5-8,0) - 1 < 0, 0, MAX(G5-8,0) - 1) -> 0 | J5: =H5*F5 -> 0 | K5: =I5*F5*1.2 -> 0 | L5: =J5+K5 -> 0
A6: Brett | B6: 10:00AM-9:00PM | C6: 2026-07-05 | D6: 0 | E6: 0 | F6: 31.25 | G6: =(E6-D6)*24 -> 0 | H6: =MIN(G6,8) -> 0 | I6: =IF(MAX(G6-8,0) - 1 < 0, 0, MAX(G6-8,0) - 1) -> 0 | J6: =H6*F6 -> 0 | K6: =I6*F6*1.2 -> 0 | L6: =J6+K6 -> 0
A7: Brett | B7: 10:00AM-9:00PM | C7: 2026-07-06 | D7: 17:00 | E7: 21:00 | F7: 31.25 | G7: =(E7-D7)*24 -> 4 | H7: =MIN(G7,8) -> 4 | I7: =IF(MAX(G7-8,0) - 1 < 0, 0, MAX(G7-8,0) - 1) -> 0 | J7: =H7*F7 -> 125 | K7: =I7*F7*1.2 -> 0 | L7: =J7+K7 -> 125
A8: Brett | B8: 10:00AM-9:00PM | C8: 2026-07-07 | D8: 17:00 | E8: 21:00 | F8: 31.25 | G8: =(E8-D8)*24 -> 4 | H8: =MIN(G8,8) -> 4 | I8: =IF(MAX(G8-8,0) - 1 < 0, 0, MAX(G8-8,0) - 1) -> 0 | J8: =H8*F8 -> 125 | K8: =I8*F8*1.2 -> 0 | L8: =J8+K8 -> 125
A9: Brett | B9: 10:00AM-9:00PM | C9: 2026-07-08 | D9: 0 | E9: 0 | F9: 31.25 | G9: =(E9-D9)*24 -> 0 | H9: =MIN(G9,8) -> 0 | I9: =IF(MAX(G9-8,0) - 1 < 0, 0, MAX(G9-8,0) - 1) -> 0 | J9: =H9*F9 -> 0 | K9: =I9*F9*1.2 -> 0 | L9: =J9+K9 -> 0
A10: Brett | B10: 10:00AM-9:00PM | C10: 2026-07-09 | D10: 09:00 | E10: 17:00 | F10: 31.25 | G10: =(E10-D10)*24 -> 8 | H10: =MIN(G10,8) -> 8 | I10: =IF(MAX(G10-8,0) - 1 < 0, 0, MAX(G10-8,0) - 1) -> 0 | J10: =H10*F10 -> 250 | K10: =I10*F10*1.2 -> 0 | L10: =J10+K10 -> 250
A11: Brett | B11: 10:00AM-9:00PM | C11: 2026-07-10 | D11: 09:00 | E11: 17:00 | F11: 31.25 | G11: =(E11-D11)*24 -> 8 | H11: =MIN(G11,8) -> 8 | I11: =IF(MAX(G11-8,0) - 1 < 0, 0, MAX(G11-8,0) - 1) -> 0 | J11: =H11*F11 -> 250 | K11: =I11*F11*1.2 -> 0 | L11: =J11+K11 -> 250
A12: Brett | B12: 10:00AM-9:00PM | C12: 2026-07-11 | D12: 09:00 | E12: 21:00 | F12: 31.25 | G12: =(E12-D12)*24 -> 12 | H12: =MIN(G12,8) -> 8 | I12: =IF(MAX(G12-8,0) - 1 < 0, 0, MAX(G12-8,0) - 1) -> 3 | J12: =H12*F12 -> 250 | K12: =I12*F12*1.2 -> 112.5 | L12: =J12+K12 -> 362.5
A13: Brett | B13: 10:00AM-9:00PM | C13: 2026-07-12 | D13: 09:00 | E13: 21:09 | F13: 31.25 | G13: =(E13-D13)*24 -> 12.15 | H13: =MIN(G13,8) -> 8 | I13: =IF(MAX(G13-8,0) - 1 < 0, 0, MAX(G13-8,0) - 1) -> 3.15 | J13: =H13*F13 -> 250 | K13: =I13*F13*1.2 -> 118.125 | L13: =J13+K13 -> 368.125
... A17: Brett | B17: 10:00AM-9:00PM | C17: 2026-07-15 | D17: 0 | E17: 0 | F17: 31.25 | G17: =(E17-D17)*24 -> 0 | H17: =MIN(G17,8) -> 0 | I17: =IF(MAX(G17-8,0) - 1 < 0, 0, MAX(G17-8,0) - 1) -> 0 | J17: =H17*F17 -> 0 | K17: =I17*F17*1.2 -> 0 | L17: =J17+K17 -> 0
A23: SUMMARY | B23: REGULAR PAY | C23: OVER TIME PAY | D23: TOTAL PAY
A24: Kim | B24: =SUM(J2:J22) -> 1250 | C24: =SUM(K2:K22) -> 230.625 | D24: =SUM(L2:L22) -> 1480.625
A28: PAYROLL SLIP
A29: Name: | B29: =A2 -> Brett
A30: Job Title: | B30: Staff
A31: Payment Date: | B31: =C16+5 -> 46223
A32: Cut Off Period: | B32: =Marlon!B35 -> July-1 to July-15, 2026
A33: Days Worked | B33: =COUNTIF(D2:D18, "*:*") -> 6
A34: Adjustments
A35: Basic Pay | B35: =B24 -> 1250
A36: Bonus/Incentives | B36: 0
A37: Overtime Pay | B37: =C24 -> 230.625
A38: Other Income | B38: 0
A41: Gross Pay | B41: =D24 -> 1480.625
A42: Deductions
A43: Allowance | B43: -500
B44: 0
A45: .
A46: Net Pay | B46: =SUM(B41:B44) -> 980.625

Sheet Pepito
A1: Employee | B1: Shift | C1: Date | D1: Time In | E1: Time Out | F1: Hourly Rate | G1: Total Hours | H1: Regular Hours | I1: Overtime Hours | J1: Regular Pay | K1: Overtime Pay | L1: Total Pay
A2: Pepito | B2: 8:30AM-9:00PM | C2: 2026-05-01 | D2: 0 | E2: 0 | F2: 43.75 | G2: =(E2-D2)*24 -> 0 | H2: =MIN(G2,8) -> 0 | I2: =IF(MAX(G2-8,0) - 1 < 0, 0, MAX(G2-8,0) - 1) -> 0 | J2: =H2*F2 -> 0 | K2: =I2*F2*1.2 -> 0 | L2: =J2+K2 -> 0
A3: Pepito | B3: 8:30AM-9:00PM | C3: 2026-05-02 | D3: 0 | E3: 0 | F3: 43.75 | G3: =(E3-D3)*24 -> 0 | H3: =MIN(G3,8) -> 0 | I3: =IF(MAX(G3-8,0) - 1 < 0, 0, MAX(G3-8,0) - 1) -> 0 | J3: =H3*F3 -> 0 | K3: =I3*F3*1.2 -> 0 | L3: =J3+K3 -> 0
A4: Pepito | B4: 8:30AM-9:00PM | C4: 2026-05-03 | D4: 0 | E4: 0 | F4: 43.75 | G4: =(E4-D4)*24 -> 0 | H4: =MIN(G4,8) -> 0 | I4: =IF(MAX(G4-8,0) - 1 < 0, 0, MAX(G4-8,0) - 1) -> 0 | J4: =H4*F4 -> 0 | K4: =I4*F4*1.2 -> 0 | L4: =J4+K4 -> 0
A5: Pepito | B5: 8:30AM-9:00PM | C5: 2026-05-04 | D5: 09:00 | E5: 21:00 | F5: 43.75 | G5: =(E5-D5)*24 -> 12 | H5: =MIN(G5,8) -> 8 | I5: =IF(MAX(G5-8,0) - 1 < 0, 0, MAX(G5-8,0) - 1) -> 3 | J5: =H5*F5 -> 350 | K5: =I5*F5*1.2 -> 157.5 | L5: =J5+K5 -> 507.5
A6: Pepito | B6: 8:30AM-9:00PM | C6: 2026-05-05 | D6: 09:00 | E6: 21:00 | F6: 43.75 | G6: =(E6-D6)*24 -> 12 | H6: =MIN(G6,8) -> 8 | I6: =IF(MAX(G6-8,0) - 1 < 0, 0, MAX(G6-8,0) - 1) -> 3 | J6: =H6*F6 -> 350 | K6: =I6*F6*1.2 -> 157.5 | L6: =J6+K6 -> 507.5
A7: Pepito | B7: 8:30AM-9:00PM | C7: 2026-05-06 | D7: 0 | E7: 0 | F7: 43.75 | G7: =(E7-D7)*24 -> 0 | H7: =MIN(G7,8) -> 0 | I7: =IF(MAX(G7-8,0) - 1 < 0, 0, MAX(G7-8,0) - 1) -> 0 | J7: =H7*F7 -> 0 | K7: =I7*F7*1.2 -> 0 | L7: =J7+K7 -> 0
A8: Pepito | B8: 8:30AM-9:00PM | C8: 2026-05-07 | D8: 0 | E8: 0 | F8: 43.75 | G8: =(E8-D8)*24 -> 0 | H8: =MIN(G8,8) -> 0 | I8: =IF(MAX(G8-8,0) - 1 < 0, 0, MAX(G8-8,0) - 1) -> 0 | J8: =H8*F8 -> 0 | K8: =I8*F8*1.2 -> 0 | L8: =J8+K8 -> 0
A9: Pepito | B9: 8:30AM-9:00PM | C9: 2026-05-08 | D9: 09:00 | E9: 21:00 | F9: 43.75 | G9: =(E9-D9)*24 -> 12 | H9: =MIN(G9,8) -> 8 | I9: =IF(MAX(G9-8,0) - 1 < 0, 0, MAX(G9-8,0) - 1) -> 3 | J9: =H9*F9 -> 350 | K9: =I9*F9*1.2 -> 157.5 | L9: =J9+K9 -> 507.5
A10: Pepito | B10: 8:30AM-9:00PM | C10: 2026-05-09 | D10: 09:00 | E10: 21:00 | F10: 43.75 | G10: =(E10-D10)*24 -> 12 | H10: =MIN(G10,8) -> 8 | I10: =IF(MAX(G10-8,0) - 1 < 0, 0, MAX(G10-8,0) - 1) -> 3 | J10: =H10*F10 -> 350 | K10: =I10*F10*1.2 -> 157.5 | L10: =J10+K10 -> 507.5
A11: Pepito | B11: 8:30AM-9:00PM | C11: 2026-05-10 | D11: 17:00 | E11: 21:30 | F11: 43.75 | G11: =(E11-D11)*24 -> 4.5 | H11: =MIN(G11,8) -> 4.5 | I11: =IF(MAX(G11-8,0) - 1 < 0, 0, MAX(G11-8,0) - 1) -> 0 | J11: =H11*F11 -> 196.875 | K11: =I11*F11*1.2 -> 0 | L11: =J11+K11 -> 196.875
A12: Pepito | B12: 8:30AM-9:00PM | C12: 2026-05-11 | D12: 09:00 | E12: 21:00 | F12: 43.75 | G12: =(E12-D12)*24 -> 12 | H12: =MIN(G12,8) -> 8 | I12: =IF(MAX(G12-8,0) - 1 < 0, 0, MAX(G12-8,0) - 1) -> 3 | J12: =H12*F12 -> 350 | K12: =I12*F12*1.2 -> 157.5 | L12: =J12+K12 -> 507.5
A13: Pepito | B13: 8:30AM-9:00PM | C13: 2026-05-12 | D13: 09:00 | E13: 21:00 | F13: 43.75 | G13: =(E13-D13)*24 -> 12 | H13: =MIN(G13,8) -> 8 | I13: =IF(MAX(G13-8,0) - 1 < 0, 0, MAX(G13-8,0) - 1) -> 3 | J13: =H13*F13 -> 350 | K13: =I13*F13*1.2 -> 157.5 | L13: =J13+K13 -> 507.5
... A16: Pepito | B16: 8:30AM-9:00PM | C16: 2026-05-15 | D16: 09:00 | E16: 14:00 | F16: 43.75 | G16: =(E16-D16)*24 -> 5 | H16: =MIN(G16,8) -> 5 | I16: =IF(MAX(G16-8,0) - 1 < 0, 0, MAX(G16-8,0) - 1) -> 0 | J16: =H16*F16 -> 218.75 | K16: =I16*F16*1.2 -> 0 | L16: =J16+K16 -> 218.75
A22: SUMMARY | B22: REGULAR PAY | C22: OVER TIME PAY | D22: TOTAL PAY
A23: Pepito | B23: =SUM(J2:J21) -> 2865.625 | C23: =SUM(K2:K21) -> 1102.5 | D23: =SUM(L2:L21) -> 3968.125
A31: PAYROLL SLIP
A32: Name: | B32: Pepito
A33: Job Title: | B33: Staff
A34: Payment Date: | B34: =C8+1 -> 46150
A35: Cut Off Period: | B35: =Marlon!B35 -> July-1 to July-15, 2026
A36: Days Worked | B36: =COUNTIF(D2:D16, "*:*") -> 9
A37: Adjustments
A38: Basic Pay | B38: =B23 -> 2865.625
A39: Bonus/Incentives | B39: 0
A40: Overtime Pay | B40: =C23 -> 1102.5
A41: Other Income | B41: 0
A44: Gross Pay | B44: =D23 -> 3968.125
A45: Deductions | B45: 0
A46: WH Tax | B46: 0
A48: Net Pay | B48: =SUM(B44:B46) -> 3968.125

Sheet Jay Anne
A1: Employee | B1: Shift | C1: Date | D1: Time In | E1: Time Out | F1: Hourly Rate | G1: Total Hours | H1: Regular Hours | I1: Overtime Hours | J1: Regular Pay | K1: Overtime Pay | L1: Total Pay
A2: Jay Anne | B2: 10:00AM-9:00PM | C2: 2026-04-27 | D2: 09:00 | E2: 17:00 | F2: 37.5 | G2: =(E2-D2)*24 -> 8 | H2: =MIN(G2,8) -> 8 | I2: =IF(MAX(G2-9,0) - 1 < 0, 0, MAX(G2-9,0) - 1) -> 0 | J2: =H2*F2 -> 300 | K2: =I2*F2*1.2 -> 0 | L2: =J2+K2 -> 300
A3: Jay Anne | B3: 10:00AM-9:00PM | C3: 2026-04-28 | D3: 09:28 | E3: 21:00 | F3: 37.5 | G3: =(E3-D3)*24 -> 11.533333 | H3: =MIN(G3,8) -> 8 | I3: =IF(MAX(G3-9,0) - 1 < 0, 0, MAX(G3-9,0) - 1) -> 1.5333333 | J3: =H3*F3 -> 300 | K3: =I3*F3*1.2 -> 69 | L3: =J3+K3 -> 369
A4: Jay Anne | B4: 10:00AM-9:00PM | C4: 2026-04-29 | D4: 09:00 | E4: 21:00 | F4: 37.5 | G4: =(E4-D4)*24 -> 12 | H4: =MIN(G4,8) -> 8 | I4: =IF(MAX(G4-9,0) - 1 < 0, 0, MAX(G4-9,0) - 1) -> 2 | J4: =H4*F4 -> 300 | K4: =I4*F4*1.2 -> 90 | L4: =J4+K4 -> 390
A5: Jay Anne | B5: 10:00AM-9:00PM | C5: 2026-04-30 | D5: 0 | E5: 0 | F5: 37.5 | G5: =(E5-D5)*24 -> 0 | H5: =MIN(G5,8) -> 0 | I5: =IF(MAX(G5-9,0) - 1 < 0, 0, MAX(G5-9,0) - 1) -> 0 | J5: =H5*F5 -> 0 | K5: =I5*F5*1.2 -> 0 | L5: =J5+K5 -> 0
A6: Jay Anne | B6: 10:00AM-9:00PM | C6: 2026-05-01 | D6: 0 | E6: 0 | F6: 37.5 | G6: =(E6-D6)*24 -> 0 | H6: =MIN(G6,8) -> 0 | I6: =IF(MAX(G6-9,0) - 1 < 0, 0, MAX(G6-9,0) - 1) -> 0 | J6: =H6*F6 -> 0 | K6: =I6*F6*1.2 -> 0 | L6: =J6+K6 -> 0
A7: Jay Anne | B7: 10:00AM-9:00PM | C7: 2026-05-02 | D7: 0 | E7: 0 | F7: 37.5 | G7: =(E7-D7)*24 -> 0 | H7: =MIN(G7,8) -> 0 | I7: =IF(MAX(G7-8,0) - 1 < 0, 0, MAX(G7-8,0) - 1) -> 0 | J7: =H7*F7 -> 0 | K7: =I7*F7*1.2 -> 0 | L7: =J7+K7 -> 0
A8: Jay Anne | B8: 10:00AM-9:00PM | C8: 2026-05-03 | D8: 0 | E8: 0 | F8: 37.5 | G8: =(E8-D8)*24 -> 0 | H8: =MIN(G8,8) -> 0 | I8: =IF(MAX(G8-8,0) - 1 < 0, 0, MAX(G8-8,0) - 1) -> 0 | J8: =H8*F8 -> 0 | K8: =I8*F8*1.2 -> 0 | L8: =J8+K8 -> 0
A14: SUMMARY | B14: REGULAR PAY | C14: OVER TIME PAY | D14: TOTAL PAY
A15: Jay Anne | B15: =SUM(J2:J13) -> 900 | C15: =SUM(K2:K13) -> 159 | D15: =SUM(L2:L13) -> 1059
A23: PAYROLL SLIP
A24: Name: | B24: =A2 -> Jay Anne
A25: Job Title: | B25: Cashier
A26: Payment Date: | B26: =C8+1 -> 46146
A27: Cut Off Period: | B27: =Marlon!B35 -> July-1 to July-15, 2026
A28: Days Worked | B28: =COUNTIF(D2:D8, "*:*") -> 3
A29: Adjustments
A30: Basic Pay | B30: =B15 -> 900
A31: Bonus/Incentives | B31: 0
A32: Overtime Pay | B32: =C15 -> 159
A33: Other Income | B33: 0
A36: Gross Pay | B36: =D15 -> 1059
A37: Deductions | B37: 0
A38: WH Tax | B38: 0
A40: Net Pay | B40: =SUM(B36:B38) -> 1059

Sheet Sheen
A1: Employee | B1: Shift | C1: Date | D1: Time In | E1: Time Out | F1: Hourly Rate | G1: Total Hours | H1: Regular Hours | I1: Overtime Hours | J1: Regular Pay | K1: Overtime Pay | L1: Total Pay
A2: Sheen Valles | B2: 8:30AM-9:00PM | C2: 2026-05-16 | D2: 0 | E2: 0 | F2: 25 | G2: =(E2-D2)*24 -> 0 | H2: =MIN(G2,8) -> 0 | I2: =IF(MAX(G2-8,0) - 1 < 0, 0, MAX(G2-8,0) - 1) -> 0 | J2: =H2*F2 -> 0 | K2: =I2*F2*1.2 -> 0 | L2: =J2+K2 -> 0
A3: Sheen Valles | B3: 8:30AM-9:00PM | C3: 2026-05-17 | D3: 09:00 | E3: 21:15 | F3: 25 | G3: =(E3-D3)*24 -> 12.25 | H3: =MIN(G3,8) -> 8 | I3: =IF(MAX(G3-8,0) - 1 < 0, 0, MAX(G3-8,0) - 1) -> 3.25 | J3: =H3*F3 -> 200 | K3: =I3*F3*1.2 -> 97.5 | L3: =J3+K3 -> 297.5
A4: Sheen Valles | B4: 8:30AM-9:00PM | C4: 2026-05-18 | D4: 09:00 | E4: 17:00 | F4: 25 | G4: =(E4-D4)*24 -> 8 | H4: =MIN(G4,8) -> 8 | I4: =IF(MAX(G4-8,0) - 1 < 0, 0, MAX(G4-8,0) - 1) -> 0 | J4: =H4*F4 -> 200 | K4: =I4*F4*1.2 -> 0 | L4: =J4+K4 -> 200
A5: Sheen Valles | B5: 8:30AM-9:00PM | C5: 2026-05-19 | D5: 0 | E5: 0 | F5: 25 | G5: =(E5-D5)*24 -> 0 | H5: =MIN(G5,8) -> 0 | I5: =IF(MAX(G5-8,0) - 1 < 0, 0, MAX(G5-8,0) - 1) -> 0 | J5: =H5*F5 -> 0 | K5: =I5*F5*1.2 -> 0 | L5: =J5+K5 -> 0
A6: Sheen Valles | B6: 8:30AM-9:00PM | C6: 2026-05-20 | D6: 17:00 | E6: 21:15 | F6: 25 | G6: =(E6-D6)*24 -> 4.25 | H6: =MIN(G6,8) -> 4.25 | I6: =IF(MAX(G6-8,0) - 1 < 0, 0, MAX(G6-8,0) - 1) -> 0 | J6: =H6*F6 -> 106.25 | K6: =I6*F6*1.2 -> 0 | L6: =J6+K6 -> 106.25
A7: Sheen Valles | B7: 8:30AM-9:00PM | C7: 2026-05-21 | D7: 17:00 | E7: 21:15 | F7: 25 | G7: =(E7-D7)*24 -> 4.25 | H7: =MIN(G7,8) -> 4.25 | I7: =IF(MAX(G7-8,0) - 1 < 0, 0, MAX(G7-8,0) - 1) -> 0 | J7: =H7*F7 -> 106.25 | K7: =I7*F7*1.2 -> 0 | L7: =J7+K7 -> 106.25
A8: Sheen Valles | B8: 8:30AM-9:00PM | C8: 2026-05-22 | D8: 17:00 | E8: 21:30 | F8: 25 | G8: =(E8-D8)*24 -> 4.5 | H8: =MIN(G8,8) -> 4.5 | I8: =IF(MAX(G8-8,0) - 1 < 0, 0, MAX(G8-8,0) - 1) -> 0 | J8: =H8*F8 -> 112.5 | K8: =I8*F8*1.2 -> 0 | L8: =J8+K8 -> 112.5
A9: Sheen Valles | B9: 8:30AM-9:00PM | C9: 2026-05-23 | D9: 09:00 | E9: 21:15 | F9: 25 | G9: =(E9-D9)*24 -> 12.25 | H9: =MIN(G9,8) -> 8 | I9: =IF(MAX(G9-8,0) - 1 < 0, 0, MAX(G9-8,0) - 1) -> 3.25 | J9: =H9*F9 -> 200 | K9: =I9*F9*1.2 -> 97.5 | L9: =J9+K9 -> 297.5
A10: Sheen Valles | B10: 8:30AM-9:00PM | C10: 2026-05-24 | D10: 09:00 | E10: 21:30 | F10: 25 | G10: =(E10-D10)*24 -> 12.5 | H10: =MIN(G10,8) -> 8 | I10: =IF(MAX(G10-8,0) - 1 < 0, 0, MAX(G10-8,0) - 1) -> 3.5 | J10: =H10*F10 -> 200 | K10: =I10*F10*1.2 -> 105 | L10: =J10+K10 -> 305
A11: Sheen Valles | B11: 8:30AM-9:00PM | C11: 2026-05-25 | D11: 09:00 | E11: 21:15 | F11: 25 | G11: =(E11-D11)*24 -> 12.25 | H11: =MIN(G11,8) -> 8 | I11: =IF(MAX(G11-8,0) - 1 < 0, 0, MAX(G11-8,0) - 1) -> 3.25 | J11: =H11*F11 -> 200 | K11: =I11*F11*1.2 -> 97.5 | L11: =J11+K11 -> 297.5
A12: Sheen Valles | B12: 8:30AM-9:00PM | C12: 2026-05-26 | D12: 09:00 | E12: 21:15 | F12: 25 | G12: =(E12-D12)*24 -> 12.25 | H12: =MIN(G12,8) -> 8 | I12: =IF(MAX(G12-8,0) - 1 < 0, 0, MAX(G12-8,0) - 1) -> 3.25 | J12: =H12*F12 -> 200 | K12: =I12*F12*1.2 -> 97.5 | L12: =J12+K12 -> 297.5
A13: Sheen Valles | B13: 8:30AM-9:00PM | C13: 2026-05-27 | D13: 0 | E13: 0 | F13: 37.5 | G13: =(E13-D13)*24 -> 0 | H13: =MIN(G13,8) -> 0 | I13: =IF(MAX(G13-8,0) - 1 < 0, 0, MAX(G13-8,0) - 1) -> 0 | J13: =H13*F13 -> 0 | K13: =I13*F13*1.2 -> 0 | L13: =J13+K13 -> 0
... A17: Sheen Valles | B17: 8:30AM-9:00PM | C17: 2026-05-31 | D17: 0 | E17: 0 | F17: 37.5 | G17: =(E17-D17)*24 -> 0 | H17: =MIN(G17,8) -> 0 | I17: =IF(MAX(G17-8,0) - 1 < 0, 0, MAX(G17-8,0) - 1) -> 0 | J17: =H17*F17 -> 0 | K17: =I17*F17*1.2 -> 0 | L17: =J17+K17 -> 0
A22: SUMMARY | B22: REGULAR PAY | C22: OVER TIME PAY | D22: TOTAL PAY
A23: Sheen Valles | B23: =SUM(J2:J21) -> 2325 | C23: =SUM(K2:K21) -> 787.5 | D23: =SUM(L2:L21) -> 3112.5
A31: PAYROLL SLIP
