Workbook

Sheet Payslip
A1: PAYROLL SLIP | D1: PAYROLL SLIP
A2: ='Rhea Mae'!A24 -> Name: | B2: ='Rhea Mae'!B24 -> Rhea Mae | D2: ='Jay Anne'!A24 -> Name: | E2: ='Jay Anne'!B24 -> Jay Anne
A3: ='Rhea Mae'!A25 -> Job Title: | B3: ='Rhea Mae'!B25 -> Store Manager | D3: ='Jay Anne'!A25 -> Job Title: | E3: ='Jay Anne'!B25 -> Cashier
A4: ='Rhea Mae'!A26 -> Payment Date: | B4: ='Rhea Mae'!B26 -> 46062 | D4: ='Jay Anne'!A26 -> Payment Date: | E4: ='Jay Anne'!B26 -> 46062
A5: ='Rhea Mae'!A27 -> Cut Off Period: | B5: ='Rhea Mae'!B27 -> Feb-2 to Feb-08, 2026 | D5: ='Jay Anne'!A27 -> Cut Off Period: | E5: ='Jay Anne'!B27 -> Feb-2 to Feb-08, 2026
A6: ='Rhea Mae'!A28 -> Days Worked | B6: ='Rhea Mae'!B28 -> 4 | D6: ='Jay Anne'!A28 -> Days Worked | E6: ='Jay Anne'!B28 -> 6
A7: ='Rhea Mae'!A29 -> Adjustments | D7: ='Jay Anne'!A29 -> Adjustments
A8: ='Rhea Mae'!A30 -> Basic Pay | B8: ='Rhea Mae'!B30 -> 1341.613 | D8: ='Jay Anne'!A30 -> Basic Pay | E8: ='Jay Anne'!B30 -> 1615.14
A9: ='Rhea Mae'!A31 -> Bonus/Incentives | B9: ='Rhea Mae'!B31 -> 0 | D9: ='Jay Anne'!A31 -> Bonus/Incentives | E9: ='Jay Anne'!B31 -> 0
A10: ='Rhea Mae'!A32 -> Overtime Pay | B10: ='Rhea Mae'!B32 -> 415.368 | D10: ='Jay Anne'!A32 -> Overtime Pay | E10: ='Jay Anne'!B32 -> 163.9068
A11: ='Rhea Mae'!A33 -> Other Income | B11: ='Rhea Mae'!B33 -> 0 | D11: ='Jay Anne'!A33 -> Other Income | E11: ='Jay Anne'!B33 -> 0
A14: ='Rhea Mae'!A36 -> Gross Pay | B14: ='Rhea Mae'!B36 -> 1756.981 | D14: ='Jay Anne'!A36 -> Gross Pay | E14: ='Jay Anne'!B36 -> 1779.0468
A15: ='Rhea Mae'!A37 -> Deductions | B15: ='Rhea Mae'!B37 -> 0 | D15: ='Jay Anne'!A37 -> Deductions | E15: ='Jay Anne'!B37 -> 0
A16: ='Rhea Mae'!A38 -> WH Tax | B16: ='Rhea Mae'!B38 -> 0 | D16: ='Jay Anne'!A38 -> WH Tax | E16: ='Jay Anne'!B38 -> 0
A18: ='Rhea Mae'!A40 -> Net Pay | B18: ='Rhea Mae'!B40 -> 1756.981 | D18: ='Jay Anne'!A40 -> Net Pay | E18: ='Jay Anne'!B40 -> 1779.0468
A21: PAYROLL SLIP | D21: PAYROLL SLIP
A22: =Kris!A24 -> Name: | B22: =Kris!B24 -> Kris Naynayan | D22: =Christian!A24 -> Name: | E22: =Christian!B24 -> Christian
A23: =Kris!A25 -> Job Title: | B23: =Kris!B25 -> Staff | D23: =Christian!A25 -> Job Title: | E23: =Christian!B25 -> Staff
A24: =Kris!A26 -> Payment Date: | B24: =Kris!B26 -> 46062 | D24: =Christian!A26 -> Payment Date: | E24: =Christian!B26 -> 46062
A25: =Kris!A27 -> Cut Off Period: | B25: =Kris!B27 -> Feb-2 to Feb-08, 2026 | D25: =Christian!A27 -> Cut Off Period: | E25: =Christian!B27 -> Feb-2 to Feb-08, 2026
A26: =Kris!A28 -> Days Worked | B26: =Kris!B28 -> 5 | D26: =Christian!A28 -> Days Worked | E26: =Christian!B28 -> 6
A27: =Kris!A29 -> Adjustments | D27: =Christian!A29 -> Adjustments
A28: =Kris!A30 -> Basic Pay | B28: =Kris!B30 -> 1587.7893 | D28: =Christian!A30 -> Basic Pay | E28: =Christian!B30 -> 1961.28
A29: =Kris!A31 -> Bonus/Incentives | B29: =Kris!B31 -> 0 | D29: =Christian!A31 -> Bonus/Incentives | E29: =Christian!B31 -> 0
A30: =Kris!A32 -> Overtime Pay | B30: =Kris!B32 -> 374.096 | D30: =Christian!A32 -> Overtime Pay | E30: =Christian!B32 -> 637.0528
A31: =Kris!A33 -> Other Income | B31: =Kris!B33 -> 0 | D31: =Christian!A33 -> Other Income | E31: =Christian!B33 -> 0
A34: =Kris!A36 -> Gross Pay | B34: =Kris!B36 -> 1961.8853 | D34: =Christian!A36 -> Gross Pay | E34: =Christian!B36 -> 2598.3328
A35: =Kris!A37 -> Deductions | B35: =Kris!B37 -> 0 | D35: =Christian!A37 -> Deductions | E35: =Christian!B37 -> 0
A36: =Kris!A38 -> WH Tax | B36: =Kris!B38 -> 0 | D36: =Christian!A38 -> WH Tax | E36: =Christian!B38 -> 0
A38: =Kris!A40 -> Net Pay | B38: =Kris!B40 -> 1961.8853 | D38: =Christian!A40 -> Net Pay | E38: =Christian!B40 -> 2598.3328
A42: PAYROLL SLIP | D42: PAYROLL SLIP
A43: =Cherry!A24 -> Name: | B43: =Cherry!B24 -> Cherry | D43: =Aldrin!A24 -> Name: | E43: =Aldrin!B24 -> Aldrin
A44: =Cherry!A25 -> Job Title: | B44: =Cherry!B25 -> Staff | D44: =Aldrin!A25 -> Job Title: | E44: =Aldrin!B25 -> Staff
A45: =Cherry!A26 -> Payment Date: | B45: =Cherry!B26 -> 46062 | D45: =Aldrin!A26 -> Payment Date: | E45: =Aldrin!B26 -> 46062
A46: =Cherry!A27 -> Cut Off Period: | B46: =Cherry!B27 -> Feb-2 to Feb-08, 2026 | D46: =Aldrin!A27 -> Cut Off Period: | E46: =Aldrin!B27 -> Feb-2 to Feb-08, 2026
A47: =Cherry!A28 -> Days Worked | B47: =Cherry!B28 -> 5 | D47: =Aldrin!A28 -> Days Worked | E47: =Aldrin!B28 -> 4
A48: =Cherry!A29 -> Adjustments | D48: =Aldrin!A29 -> Adjustments
A49: =Cherry!A30 -> Basic Pay | B49: =Cherry!B30 -> 1499.85 | D49: =Aldrin!A30 -> Basic Pay | E49: =Aldrin!B30 -> 871.51517
A50: =Cherry!A31 -> Bonus/Incentives | B50: =Cherry!B31 -> 0 | D50: =Aldrin!A31 -> Bonus/Incentives | E50: =Aldrin!B31 -> 0
A51: =Cherry!A32 -> Overtime Pay | B51: =Cherry!B32 -> 568.6098 | D51: =Aldrin!A32 -> Overtime Pay | E51: =Aldrin!B32 -> 147.7364
...

Sheet Summary
A1: Employee | B1: Total Pay
A2: ='Rhea Mae'!A15 -> Rhea Mae | B2: ='Rhea Mae'!D15 -> 1756.981
A3: ='Jay Anne'!A15 -> Jay Anne | B3: ='Jay Anne'!D15 -> 1779.0468
A4: =Kris!A15 -> Kris Naynayan | B4: =Kris!D15 -> 1961.8853
A5: =Christian!A15 -> Christian | B5: =Christian!D15 -> 2598.3328
A6: =Cherry!A15 -> Cherry | B6: =Cherry!D15 -> 2068.4598
A7: =Aldrin!A15 -> Aldrin | B7: =Aldrin!D15 -> 1019.2516
A8: =Mark!A15 -> Mark | B8: =Mark!D15 -> 1207.995
A9: =Lenard!A15 -> Lenard | B9: =Lenard!D15 -> 0
A10: =Chadiyah!A15 -> Chadiyah | B10: =Chadiyah!D15 -> 1804.704
B11: =SUM(B2:B10) -> 14196.656

Sheet Rhea Mae
A1: Employee | B1: Shift | C1: Date | D1: Time In | E1: Time Out | F1: Hourly Rate | G1: Total Hours | H1: Regular Hours | I1: Overtime Hours | J1: Regular Pay | K1: Overtime Pay | L1: Total Pay
A2: Rhea Mae | B2: 8:30AM-9:00PM | C2: 2026-02-02 | D2: 13:07 | E2: 21:00 | F2: 38.46 | G2: =(E2-D2)*24 -> 7.8833333 | H2: =MIN(G2,9) -> 7.8833333 | I2: =IF(MAX(G2-9,0) - 1 < 0, 0, MAX(G2-9,0) - 1) -> 0 | J2: =H2*F2 -> 303.193 | K2: =I2*F2*1.2 -> 0 | L2: =J2+K2 -> 303.193
A3: Rhea Mae | B3: 8:30AM-9:00PM | C3: 2026-02-03 | D3: 08:30 | E3: 21:00 | F3: 38.46 | G3: =(E3-D3)*24 -> 12.5 | H3: =MIN(G3,9) -> 9 | I3: =IF(MAX(G3-9,0) - 1 < 0, 0, MAX(G3-9,0) - 1) -> 2.5 | J3: =H3*F3 -> 346.14 | K3: =I3*F3*1.2 -> 115.38 | L3: =J3+K3 -> 461.52
A4: Rhea Mae | B4: 8:30AM-9:00PM | C4: 2026-02-04 | D4: 0 | E4: 0 | F4: 38.46 | G4: =(E4-D4)*24 -> 0 | H4: =MIN(G4,9) -> 0 | I4: =IF(MAX(G4-9,0) - 1 < 0, 0, MAX(G4-9,0) - 1) -> 0 | J4: =H4*F4 -> 0 | K4: =I4*F4*1.2 -> 0 | L4: =J4+K4 -> 0
A5: Rhea Mae | B5: 8:30AM-9:00PM | C5: 2026-02-05 | D5: 08:30 | E5: 21:30 | F5: 38.46 | G5: =(E5-D5)*24 -> 13 | H5: =MIN(G5,9) -> 9 | I5: =IF(MAX(G5-9,0) - 1 < 0, 0, MAX(G5-9,0) - 1) -> 3 | J5: =H5*F5 -> 346.14 | K5: =I5*F5*1.2 -> 138.456 | L5: =J5+K5 -> 484.596
A6: Rhea Mae | B6: 8:30AM-9:00PM | C6: 2026-02-06 | D6: 08:30 | E6: 22:00 | F6: 38.46 | G6: =(E6-D6)*24 -> 13.5 | H6: =MIN(G6,9) -> 9 | I6: =IF(MAX(G6-9,0) - 1 < 0, 0, MAX(G6-9,0) - 1) -> 3.5 | J6: =H6*F6 -> 346.14 | K6: =I6*F6*1.2 -> 161.532 | L6: =J6+K6 -> 507.672
A7: Rhea Mae | B7: 8:30AM-9:00PM | C7: 2026-02-07 | D7: 0 | E7: 0 | F7: 38.46 | G7: =(E7-D7)*24 -> 0 | H7: =MIN(G7,9) -> 0 | I7: =IF(MAX(G7-9,0) - 1 < 0, 0, MAX(G7-9,0) - 1) -> 0 | J7: =H7*F7 -> 0 | K7: =I7*F7*1.2 -> 0 | L7: =J7+K7 -> 0
A8: Rhea Mae | B8: 8:30AM-9:00PM | C8: 2026-02-08 | D8: 0 | E8: 0 | F8: 38.46 | G8: =(E8-D8)*24 -> 0 | H8: =MIN(G8,9) -> 0 | I8: =IF(MAX(G8-9,0) - 1 < 0, 0, MAX(G8-9,0) - 1) -> 0 | J8: =H8*F8 -> 0 | K8: =I8*F8*1.2 -> 0 | L8: =J8+K8 -> 0
A14: SUMMARY | B14: REGULAR PAY | C14: OVER TIME PAY | D14: TOTAL PAY
A15: Rhea Mae | B15: =SUM(J2:J13) -> 1341.613 | C15: =SUM(K2:K13) -> 415.368 | D15: =SUM(L2:L13) -> 1756.981
A23: PAYROLL SLIP
A24: Name: | B24: =A2 -> Rhea Mae
A25: Job Title: | B25: Store Manager
A26: Payment Date: | B26: =C8+1 -> 46062
A27: Cut Off Period: | B27: Feb-2 to Feb-08, 2026
A28: Days Worked | B28: =COUNTIF(D2:D8, "*:*") -> 4
A29: Adjustments
A30: Basic Pay | B30: =B15 -> 1341.613
A31: Bonus/Incentives | B31: 0
A32: Overtime Pay | B32: =C15 -> 415.368
A33: Other Income | B33: 0
A36: Gross Pay | B36: =D15 -> 1756.981
A37: Deductions | B37: 0
A38: WH Tax | B38: 0
A40: Net Pay | B40: =SUM(B36:B38) -> 1756.981

Sheet Jay Anne
A1: Employee | B1: Shift | C1: Date | D1: Time In | E1: Time Out | F1: Hourly Rate | G1: Total Hours | H1: Regular Hours | I1: Overtime Hours | J1: Regular Pay | K1: Overtime Pay | L1: Total Pay
A2: Jay Anne | B2: 10:00AM-9:00PM | C2: 2026-02-02 | D2: 10:00 | E2: 21:00 | F2: 29.91 | G2: =(E2-D2)*24 -> 11 | H2: =MIN(G2,9) -> 9 | I2: =IF(MAX(G2-9,0) - 1 < 0, 0, MAX(G2-9,0) - 1) -> 1 | J2: =H2*F2 -> 269.19 | K2: =I2*F2*1.2 -> 35.892 | L2: =J2+K2 -> 305.082
A3: Jay Anne | B3: 10:00AM-9:00PM | C3: 2026-02-03 | D3: 0 | E3: 0 | F3: 29.91 | G3: =(E3-D3)*24 -> 0 | H3: =MIN(G3,9) -> 0 | I3: =IF(MAX(G3-9,0) - 1 < 0, 0, MAX(G3-9,0) - 1) -> 0 | J3: =H3*F3 -> 0 | K3: =I3*F3*1.2 -> 0 | L3: =J3+K3 -> 0
A4: Jay Anne | B4: 10:00AM-9:00PM | C4: 2026-02-04 | D4: 10:06 | E4: 21:00 | F4: 29.91 | G4: =(E4-D4)*24 -> 10.9 | H4: =MIN(G4,9) -> 9 | I4: =IF(MAX(G4-9,0) - 1 < 0, 0, MAX(G4-9,0) - 1) -> 0.9 | J4: =H4*F4 -> 269.19 | K4: =I4*F4*1.2 -> 32.3028 | L4: =J4+K4 -> 301.4928
A5: Jay Anne | B5: 10:00AM-9:00PM | C5: 2026-02-05 | D5: 10:00 | E5: 20:30 | F5: 29.91 | G5: =(E5-D5)*24 -> 10.5 | H5: =MIN(G5,9) -> 9 | I5: =IF(MAX(G5-9,0) - 1 < 0, 0, MAX(G5-9,0) - 1) -> 0.5 | J5: =H5*F5 -> 269.19 | K5: =I5*F5*1.2 -> 17.946 | L5: =J5+K5 -> 287.136
A6: Jay Anne | B6: 10:00AM-9:00PM | C6: 2026-02-06 | D6: 10:01 | E6: 21:00 | F6: 29.91 | G6: =(E6-D6)*24 -> 10.983333 | H6: =MIN(G6,9) -> 9 | I6: =IF(MAX(G6-9,0) - 1 < 0, 0, MAX(G6-9,0) - 1) -> 0.98333333 | J6: =H6*F6 -> 269.19 | K6: =I6*F6*1.2 -> 35.2938 | L6: =J6+K6 -> 304.4838
A7: Jay Anne | B7: 10:00AM-9:00PM | C7: 2026-02-07 | D7: 10:12 | E7: 21:00 | F7: 29.91 | G7: =(E7-D7)*24 -> 10.8 | H7: =MIN(G7,9) -> 9 | I7: =IF(MAX(G7-9,0) - 1 < 0, 0, MAX(G7-9,0) - 1) -> 0.8 | J7: =H7*F7 -> 269.19 | K7: =I7*F7*1.2 -> 28.7136 | L7: =J7+K7 -> 297.9036
A8: Jay Anne | B8: 10:00AM-9:00PM | C8: 2026-02-08 | D8: 10:07 | E8: 20:30 | F8: 29.91 | G8: =(E8-D8)*24 -> 10.383333 | H8: =MIN(G8,9) -> 9 | I8: =IF(MAX(G8-9,0) - 1 < 0, 0, MAX(G8-9,0) - 1) -> 0.38333333 | J8: =H8*F8 -> 269.19 | K8: =I8*F8*1.2 -> 13.7586 | L8: =J8+K8 -> 282.9486
A14: SUMMARY | B14: REGULAR PAY | C14: OVER TIME PAY | D14: TOTAL PAY
A15: Jay Anne | B15: =SUM(J2:J13) -> 1615.14 | C15: =SUM(K2:K13) -> 163.9068 | D15: =SUM(L2:L13) -> 1779.0468
A23: PAYROLL SLIP
A24: Name: | B24: =A2 -> Jay Anne
A25: Job Title: | B25: Cashier
A26: Payment Date: | B26: =C8+1 -> 46062
A27: Cut Off Period: | B27: Feb-2 to Feb-08, 2026
A28: Days Worked | B28: =COUNTIF(D2:D8, "*:*") -> 6
A29: Adjustments
A30: Basic Pay | B30: =B15 -> 1615.14
A31: Bonus/Incentives | B31: 0
A32: Overtime Pay | B32: =C15 -> 163.9068
A33: Other Income | B33: 0
A36: Gross Pay | B36: =D15 -> 1779.0468
A37: Deductions | B37: 0
A38: WH Tax | B38: 0
A40: Net Pay | B40: =SUM(B36:B38) -> 1779.0468

Sheet Kris
A1: Employee | B1: Shift | C1: Date | D1: Time In | E1: Time Out | F1: Hourly Rate | G1: Total Hours | H1: Regular Hours | I1: Overtime Hours | J1: Regular Pay | K1: Overtime Pay | L1: Total Pay
A2: Kris Naynayan | B2: 8:30AM-9:00PM | C2: 2026-02-02 | D2: 0 | E2: 0 | F2: 36.32 | G2: =(E2-D2)*24 -> 0 | H2: =MIN(G2,9) -> 0 | I2: =IF(MAX(G2-9,0) - 1 < 0, 0, MAX(G2-9,0) - 1) -> 0 | J2: =H2*F2 -> 0 | K2: =I2*F2*1.2 -> 0 | L2: =J2+K2 -> 0
A3: Kris Naynayan | B3: 8:30AM-9:00PM | C3: 2026-02-03 | D3: 11:01 | E3: 21:30 | F3: 36.32 | G3: =(E3-D3)*24 -> 10.483333 | H3: =MIN(G3,9) -> 9 | I3: =IF(MAX(G3-9,0) - 1 < 0, 0, MAX(G3-9,0) - 1) -> 0.48333333 | J3: =H3*F3 -> 326.88 | K3: =I3*F3*1.2 -> 21.0656 | L3: =J3+K3 -> 347.9456
A4: Kris Naynayan | B4: 8:30AM-9:00PM | C4: 2026-02-04 | D4: 08:30 | E4: 16:13 | F4: 36.32 | G4: =(E4-D4)*24 -> 7.7166667 | H4: =MIN(G4,9) -> 7.7166667 | I4: =IF(MAX(G4-9,0) - 1 < 0, 0, MAX(G4-9,0) - 1) -> 0 | J4: =H4*F4 -> 280.26933 | K4: =I4*F4*1.2 -> 0 | L4: =J4+K4 -> 280.26933
A5: Kris Naynayan | B5: 8:30AM-9:00PM | C5: 2026-02-05 | D5: 08:30 | E5: 21:30 | F5: 36.32 | G5: =(E5-D5)*24 -> 13 | H5: =MIN(G5,9) -> 9 | I5: =IF(MAX(G5-9,0) - 1 < 0, 0, MAX(G5-9,0) - 1) -> 3 | J5: =H5*F5 -> 326.88 | K5: =I5*F5*1.2 -> 130.752 | L5: =J5+K5 -> 457.632
A6: Kris Naynayan | B6: 8:30AM-9:00PM | C6: 2026-02-06 | D6: 08:38 | E6: 21:30 | F6: 36.32 | G6: =(E6-D6)*24 -> 12.866667 | H6: =MIN(G6,9) -> 9 | I6: =IF(MAX(G6-9,0) - 1 < 0, 0, MAX(G6-9,0) - 1) -> 2.8666667 | J6: =H6*F6 -> 326.88 | K6: =I6*F6*1.2 -> 124.9408 | L6: =J6+K6 -> 451.8208
A7: Kris Naynayan | B7: 8:30AM-9:00PM | C7: 2026-02-07 | D7: 0 | E7: 0 | F7: 36.32 | G7: =(E7-D7)*24 -> 0 | H7: =MIN(G7,9) -> 0 | I7: =IF(MAX(G7-9,0) - 1 < 0, 0, MAX(G7-9,0) - 1) -> 0 | J7: =H7*F7 -> 0 | K7: =I7*F7*1.2 -> 0 | L7: =J7+K7 -> 0
A8: Kris Naynayan | B8: 8:30AM-9:00PM | C8: 2026-02-08 | D8: 08:35 | E8: 20:49 | F8: 36.32 | G8: =(E8-D8)*24 -> 12.233333 | H8: =MIN(G8,9) -> 9 | I8: =IF(MAX(G8-9,0) - 1 < 0, 0, MAX(G8-9,0) - 1) -> 2.2333333 | J8: =H8*F8 -> 326.88 | K8: =I8*F8*1.2 -> 97.3376 | L8: =J8+K8 -> 424.2176
A14: SUMMARY | B14: REGULAR PAY | C14: OVER TIME PAY | D14: TOTAL PAY
A15: Kris Naynayan | B15: =SUM(J2:J13) -> 1587.7893 | C15: =SUM(K2:K13) -> 374.096 | D15: =SUM(L2:L13) -> 1961.8853
A23: PAYROLL SLIP
A24: Name: | B24: =A2 -> Kris Naynayan
A25: Job Title: | B25: Staff
A26: Payment Date: | B26: =C8+1 -> 46062
A27: Cut Off Period: | B27: Feb-2 to Feb-08, 2026
A28: Days Worked | B28: =COUNTIF(D2:D8, "*:*") -> 5
A29: Adjustments
A30: Basic Pay | B30: =B15 -> 1587.7893
A31: Bonus/Incentives | B31: 0
A32: Overtime Pay | B32: =C15 -> 374.096
A33: Other Income | B33: 0
A36: Gross Pay | B36: =D15 -> 1961.8853
A37: Deductions | B37: 0
A38: WH Tax | B38: 0
A40: Net Pay | B40: =SUM(B36:B38) -> 1961.8853

Sheet Christian
A1: Employee | B1: Shift | C1: Date | D1: Time In | E1: Time Out | F1: Hourly Rate | G1: Total Hours | H1: Regular Hours | I1: Overtime Hours | J1: Regular Pay | K1: Overtime Pay | L1: Total Pay
A2: Christian | B2: 8:30AM-9:00PM | C2: 2026-02-02 | D2: 08:45 | E2: 21:00 | F2: 36.32 | G2: =(E2-D2)*24 -> 12.25 | H2: =MIN(G2,9) -> 9 | I2: =IF(MAX(G2-9,0) - 1 < 0, 0, MAX(G2-9,0) - 1) -> 2.25 | J2: =H2*F2 -> 326.88 | K2: =I2*F2*1.2 -> 98.064 | L2: =J2+K2 -> 424.944
A3: Christian | B3: 8:30AM-9:00PM | C3: 2026-02-03 | D3: 08:33 | E3: 21:00 | F3: 36.32 | G3: =(E3-D3)*24 -> 12.45 | H3: =MIN(G3,9) -> 9 | I3: =IF(MAX(G3-9,0) - 1 < 0, 0, MAX(G3-9,0) - 1) -> 2.45 | J3: =H3*F3 -> 326.88 | K3: =I3*F3*1.2 -> 106.7808 | L3: =J3+K3 -> 433.6608
A4: Christian | B4: 8:30AM-9:00PM | C4: 2026-02-04 | D4: 08:30 | E4: 21:00 | F4: 36.32 | G4: =(E4-D4)*24 -> 12.5 | H4: =MIN(G4,9) -> 9 | I4: =IF(MAX(G4-9,0) - 1 < 0, 0, MAX(G4-9,0) - 1) -> 2.5 | J4: =H4*F4 -> 326.88 | K4: =I4*F4*1.2 -> 108.96 | L4: =J4+K4 -> 435.84
A5: Christian | B5: 8:30AM-9:00PM | C5: 2026-02-05 | D5: 08:30 | E5: 21:00 | F5: 36.32 | G5: =(E5-D5)*24 -> 12.5 | H5: =MIN(G5,9) -> 9 | I5: =IF(MAX(G5-9,0) - 1 < 0, 0, MAX(G5-9,0) - 1) -> 2.5 | J5: =H5*F5 -> 326.88 | K5: =I5*F5*1.2 -> 108.96 | L5: =J5+K5 -> 435.84
A6: Christian | B6: 8:30AM-9:00PM | C6: 2026-02-06 | D6: 08:30 | E6: 21:00 | F6: 36.32 | G6: =(E6-D6)*24 -> 12.5 | H6: =MIN(G6,9) -> 9 | I6: =IF(MAX(G6-9,0) - 1 < 0, 0, MAX(G6-9,0) - 1) -> 2.5 | J6: =H6*F6 -> 326.88 | K6: =I6*F6*1.2 -> 108.96 | L6: =J6+K6 -> 435.84
A7: Christian | B7: 8:30AM-9:00PM | C7: 2026-02-07 | D7: 08:35 | E7: 21:00 | F7: 36.32 | G7: =(E7-D7)*24 -> 12.416667 | H7: =MIN(G7,9) -> 9 | I7: =IF(MAX(G7-9,0) - 1 < 0, 0, MAX(G7-9,0) - 1) -> 2.4166667 | J7: =H7*F7 -> 326.88 | K7: =I7*F7*1.2 -> 105.328 | L7: =J7+K7 -> 432.208
A8: Christian | B8: 8:30AM-9:00PM | C8: 2026-02-08 | D8: 0 | E8: 0 | F8: 36.32 | G8: =(E8-D8)*24 -> 0 | H8: =MIN(G8,9) -> 0 | I8: =IF(MAX(G8-9,0) - 1 < 0, 0, MAX(G8-9,0) - 1) -> 0 | J8: =H8*F8 -> 0 | K8: =I8*F8*1.2 -> 0 | L8: =J8+K8 -> 0
A14: SUMMARY | B14: REGULAR PAY | C14: OVER TIME PAY | D14: TOTAL PAY
A15: Christian | B15: =SUM(J2:J13) -> 1961.28 | C15: =SUM(K2:K13) -> 637.0528 | D15: =SUM(L2:L13) -> 2598.3328
A23: PAYROLL SLIP
A24: Name: | B24: =A2 -> Christian
A25: Job Title: | B25: Staff
A26: Payment Date: | B26: =C8+1 -> 46062
A27: Cut Off Period: | B27: Feb-2 to Feb-08, 2026
A28: Days Worked | B28: =COUNTIF(D2:D8, "*:*") -> 6
A29: Adjustments
A30: Basic Pay | B30: =B15 -> 1961.28
A31: Bonus/Incentives | B31: 0
A32: Overtime Pay | B32: =C15 -> 637.0528
A33: Other Income | B33: 0
A36: Gross Pay | B36: =D15 -> 2598.3328
A37: Deductions | B37: 0
A38: WH Tax | B38: 0
A40: Net Pay | B40: =SUM(B36:B38) -> 2598.3328

Sheet Cherry
A1: Employee | B1: Shift | C1: Date | D1: Time In | E1: Time Out | F1: Hourly Rate | G1: Total Hours | H1: Regular Hours | I1: Overtime Hours | J1: Regular Pay | K1: Overtime Pay | L1: Total Pay
A2: Cherry | B2: 8:30AM-9:00PM | C2: 2026-02-02 | D2: 08:30 | E2: 21:24 | F2: 33.33 | G2: =(E2-D2)*24 -> 12.9 | H2: =MIN(G2,9) -> 9 | I2: =IF(MAX(G2-9,0) - 1 < 0, 0, MAX(G2-9,0) - 1) -> 2.9 | J2: =H2*F2 -> 299.97 | K2: =I2*F2*1.2 -> 115.9884 | L2: =J2+K2 -> 415.9584
A3: Cherry | B3: 8:30AM-9:00PM | C3: 2026-02-03 | D3: 08:30 | E3: 21:30 | F3: 33.33 | G3: =(E3-D3)*24 -> 13 | H3: =MIN(G3,9) -> 9 | I3: =IF(MAX(G3-9,0) - 1 < 0, 0, MAX(G3-9,0) - 1) -> 3 | J3: =H3*F3 -> 299.97 | K3: =I3*F3*1.2 -> 119.988 | L3: =J3+K3 -> 419.958
A4: Cherry | B4: 8:30AM-9:00PM | C4: 2026-02-04 | D4: 0 | E4: 0 | F4: 33.33 | G4: =(E4-D4)*24 -> 0 | H4: =MIN(G4,9) -> 0 | I4: =IF(MAX(G4-9,0) - 1 < 0, 0, MAX(G4-9,0) - 1) -> 0 | J4: =H4*F4 -> 0 | K4: =I4*F4*1.2 -> 0 | L4: =J4+K4 -> 0
A5: Cherry | B5: 8:30AM-9:00PM | C5: 2026-02-05 | D5: 0 | E5: 0 | F5: 33.33 | G5: =(E5-D5)*24 -> 0 | H5: =MIN(G5,9) -> 0 | I5: =IF(MAX(G5-9,0) - 1 < 0, 0, MAX(G5-9,0) - 1) -> 0 | J5: =H5*F5 -> 0 | K5: =I5*F5*1.2 -> 0 | L5: =J5+K5 -> 0
A6: Cherry | B6: 8:30AM-9:00PM | C6: 2026-02-06 | D6: 08:30 | E6: 21:30 | F6: 33.33 | G6: =(E6-D6)*24 -> 13 | H6: =MIN(G6,9) -> 9 | I6: =IF(MAX(G6-9,0) - 1 < 0, 0, MAX(G6-9,0) - 1) -> 3 | J6: =H6*F6 -> 299.97 | K6: =I6*F6*1.2 -> 119.988 | L6: =J6+K6 -> 419.958
A7: Cherry | B7: 8:30AM-9:00PM | C7: 2026-02-07 | D7: 08:30 | E7: 21:30 | F7: 33.33 | G7: =(E7-D7)*24 -> 13 | H7: =MIN(G7,9) -> 9 | I7: =IF(MAX(G7-9,0) - 1 < 0, 0, MAX(G7-9,0) - 1) -> 3 | J7: =H7*F7 -> 299.97 | K7: =I7*F7*1.2 -> 119.988 | L7: =J7+K7 -> 419.958
A8: Cherry | B8: 8:30AM-9:00PM | C8: 2026-02-08 | D8: 08:30 | E8: 20:49 | F8: 33.33 | G8: =(E8-D8)*24 -> 12.316667 | H8: =MIN(G8,9) -> 9 | I8: =IF(MAX(G8-9,0) - 1 < 0, 0, MAX(G8-9,0) - 1) -> 2.3166667 | J8: =H8*F8 -> 299.97 | K8: =I8*F8*1.2 -> 92.6574 | L8: =J8+K8 -> 392.6274
A14: SUMMARY | B14: REGULAR PAY | C14: OVER TIME PAY | D14: TOTAL PAY
A15: Cherry | B15: =SUM(J2:J13) -> 1499.85 | C15: =SUM(K2:K13) -> 568.6098 | D15: =SUM(L2:L13) -> 2068.4598
A23: PAYROLL SLIP
A24: Name: | B24: =A2 -> Cherry
A25: Job Title: | B25: Staff
A26: Payment Date: | B26: =C8+1 -> 46062
A27: Cut Off Period: | B27: Feb-2 to Feb-08, 2026
A28: Days Worked | B28: =COUNTIF(D2:D8, "*:*") -> 5
A29: Adjustments
A30: Basic Pay | B30: =B15 -> 1499.85
A31: Bonus/Incentives | B31: 0
A32: Overtime Pay | B32: =C15 -> 568.6098
A33: Other Income | B33: 0
A36: Gross Pay | B36: =D15 -> 2068.4598
A37: Deductions | B37: 0
A38: WH Tax | B38: 0
A40: Net Pay | B40: =SUM(B36:B38) -> 2068.4598

Sheet Aldrin
A1: Employee | B1: Shift | C1: Date | D1: Time In | E1: Time Out | F1: Hourly Rate | G1: Total Hours | H1: Regular Hours | I1: Overtime Hours | J1: Regular Pay | K1: Overtime Pay | L1: Total Pay
A2: Aldrin | B2: 10:00AM-9:00PM | C2: 2026-02-02 | D2: 0 | E2: 0 | F2: 27.77 | G2: =(E2-D2)*24 -> 0 | H2: =MIN(G2,8) -> 0 | I2: =IF(MAX(G2-9,0) - 1 < 0, 0, MAX(G2-9,0) - 1) -> 0 | J2: =H2*F2 -> 0 | K2: =I2*F2*1.2 -> 0 | L2: =J2+K2 -> 0
A3: Aldrin | B3: 10:00AM-9:00PM | C3: 2026-02-03 | D3: 0 | E3: 0 | F3: 27.77 | G3: =(E3-D3)*24 -> 0 | H3: =MIN(G3,8) -> 0 | I3: =IF(MAX(G3-9,0) - 1 < 0, 0, MAX(G3-9,0) - 1) -> 0 | J3: =H3*F3 -> 0 | K3: =I3*F3*1.2 -> 0 | L3: =J3+K3 -> 0
A4: Aldrin | B4: 10:00AM-9:00PM | C4: 2026-02-04 | D4: 08:59 | E4: 21:00 | F4: 27.77 | G4: =(E4-D4)*24 -> 12.016667 | H4: =MIN(G4,8) -> 8 | I4: =IF(MAX(G4-9,0) - 1 < 0, 0, MAX(G4-9,0) - 1) -> 2.0166667 | J4: =H4*F4 -> 222.16 | K4: =I4*F4*1.2 -> 67.2034 | L4: =J4+K4 -> 289.3634
A5: Aldrin | B5: 10:00AM-9:00PM | C5: 2026-02-05 | D5: 10:28 | E5: 19:30 | F5: 27.77 | G5: =(E5-D5)*24 -> 9.0333333 | H5: =MIN(G5,8) -> 8 | I5: =IF(MAX(G5-9,0) - 1 < 0, 0, MAX(G5-9,0) - 1) -> 0 | J5: =H5*F5 -> 222.16 | K5: =I5*F5*1.2 -> 0 | L5: =J5+K5 -> 222.16
A6: Aldrin | B6: 10:00AM-9:00PM | C6: 2026-02-06 | D6: 0 | E6: 0 | F6: 27.77 | G6: =(E6-D6)*24 -> 0 | H6: =MIN(G6,8) -> 0 | I6: =IF(MAX(G6-9,0) - 1 < 0, 0, MAX(G6-9,0) - 1) -> 0 | J6: =H6*F6 -> 0 | K6: =I6*F6*1.2 -> 0 | L6: =J6+K6 -> 0
A7: Aldrin | B7: 10:00AM-9:00PM | C7: 2026-02-07 | D7: 08:35 | E7: 21:00 | F7: 27.77 | G7: =(E7-D7)*24 -> 12.416667 | H7: =MIN(G7,9) -> 9 | I7: =IF(MAX(G7-9,0) - 1 < 0, 0, MAX(G7-9,0) - 1) -> 2.4166667 | J7: =H7*F7 -> 249.93 | K7: =I7*F7*1.2 -> 80.533 | L7: =J7+K7 -> 330.463
A8: Aldrin | B8: 10:00AM-9:00PM | C8: 2026-02-08 | D8: 10:37 | E8: 17:00 | F8: 27.77 | G8: =(E8-D8)*24 -> 6.3833333 | H8: =MIN(G8,9) -> 6.3833333 | I8: =IF(MAX(G8-9,0) - 1 < 0, 0, MAX(G8-9,0) - 1) -> 0 | J8: =H8*F8 -> 177.26517 | K8: =I8*F8*1.2 -> 0 | L8: =J8+K8 -> 177.26517
A14: SUMMARY | B14: REGULAR PAY | C14: OVER TIME PAY | D14: TOTAL PAY
A15: Aldrin | B15: =SUM(J2:J13) -> 871.51517 | C15: =SUM(K2:K13) -> 147.7364 | D15: =SUM(L2:L13) -> 1019.2516
A23: PAYROLL SLIP
A24: Name: | B24: =A2 -> Aldrin
A25: Job Title: | B25: Staff
A26: Payment Date: | B26: =C8+1 -> 46062
A27: Cut Off Period: | B27: Feb-2 to Feb-08, 2026 | H27: 1460.8871
A28: Days Worked | B28: =COUNTIF(D2:D8, "*:*") -> 4 | H28: 1168.9201
A29: Adjustments | H29: =H27-H28 -> 291.967
A30: Basic Pay | B30: =B15 -> 871.51517
A31: Bonus/Incentives | B31: 0
A32: Overtime Pay | B32: =C15 -> 147.7364
A33: Other Income | B33: 0
A36: Gross Pay | B36: =D15 -> 1019.2516
A37: Deductions | B37: 0
A38: WH Tax | B38: 0
A40: Net Pay | B40: =SUM(B36:B38) -> 1019.2516

Sheet Mark
A1: Employee | B1: Shift | C1: Date | D1: Time In | E1: Time Out | F1: Hourly Rate | G1: Total Hours | H1: Regular Hours | I1: Overtime Hours | J1: Regular Pay | K1: Overtime Pay | L1: Total Pay
A2: Mark | B2: 10:00AM-9:00PM | C2: 2026-02-02 | D2: 8:30 | E2: 15:00 | F2: 27.77 | G2: =(E2-D2)*24 -> 6.5 | H2: =MIN(G2,9) -> 6.5 | I2: =IF(MAX(G2-9,0) - 1 < 0, 0, MAX(G2-9,0) - 1) -> 0 | J2: =H2*F2 -> 180.505 | K2: =I2*F2*1.2 -> 0 | L2: =J2+K2 -> 180.505
A3: Mark | B3: 10:00AM-9:00PM | C3: 2026-02-03 | D3: 17:00 | E3: 22:00 | F3: 27.77 | G3: =(E3-D3)*24 -> 5 | H3: =MIN(G3,9) -> 5 | I3: =IF(MAX(G3-9,0) - 1 < 0, 0, MAX(G3-9,0) - 1) -> 0 | J3: =H3*F3 -> 138.85 | K3: =I3*F3*1.2 -> 0 | L3: =J3+K3 -> 138.85
A4: Mark | B4: 10:00AM-9:00PM | C4: 2026-02-04 | D4: 08:50 | E4: 20:00 | F4: 27.77 | G4: =(E4-D4)*24 -> 11.166667 | H4: =MIN(G4,9) -> 9 | I4: =IF(MAX(G4-9,0) - 1 < 0, 0, MAX(G4-9,0) - 1) -> 1.1666667 | J4: =H4*F4 -> 249.93 | K4: =I4*F4*1.2 -> 38.878 | L4: =J4+K4 -> 288.808
A5: Mark | B5: 10:00AM-9:00PM | C5: 2026-02-05 | D5: 09:00 | E5: 18:00 | F5: 27.77 | G5: =(E5-D5)*24 -> 9 | H5: =MIN(G5,9) -> 9 | I5: =IF(MAX(G5-9,0) - 1 < 0, 0, MAX(G5-9,0) - 1) -> 0 | J5: =H5*F5 -> 249.93 | K5: =I5*F5*1.2 -> 0 | L5: =J5+K5 -> 249.93
A6: Mark | B6: 10:00AM-9:00PM | C6: 2026-02-06 | D6: 0 | E6: 0 | F6: 27.77 | G6: =(E6-D6)*24 -> 0 | H6: =MIN(G6,9) -> 0 | I6: =IF(MAX(G6-9,0) - 1 < 0, 0, MAX(G6-9,0) - 1) -> 0 | J6: =H6*F6 -> 0 | K6: =I6*F6*1.2 -> 0 | L6: =J6+K6 -> 0
A7: Mark | B7: 10:00AM-9:00PM | C7: 2026-02-07 | D7: 0 | E7: 0 | F7: 27.77 | G7: =(E7-D7)*24 -> 0 | H7: =MIN(G7,9) -> 0 | I7: =IF(MAX(G7-9,0) - 1 < 0, 0, MAX(G7-9,0) - 1) -> 0 | J7: =H7*F7 -> 0 | K7: =I7*F7*1.2 -> 0 | L7: =J7+K7 -> 0
A8: Mark | B8: 10:00AM-9:00PM | C8: 2026-02-08 | D8: 09:00 | E8: 22:00 | F8: 27.77 | G8: =(E8-D8)*24 -> 13 | H8: =MIN(G8,9) -> 9 | I8: =IF(MAX(G8-9,0) - 1 < 0, 0, MAX(G8-9,0) - 1) -> 3 | J8: =H8*F8 -> 249.93 | K8: =I8*F8*1.2 -> 99.972 | L8: =J8+K8 -> 349.902
A14: SUMMARY | B14: REGULAR PAY | C14: OVER TIME PAY | D14: TOTAL PAY
A15: Mark | B15: =SUM(J2:J13) -> 1069.145 | C15: =SUM(K2:K13) -> 138.85 | D15: =SUM(L2:L13) -> 1207.995
A23: PAYROLL SLIP
A24: Name: | B24: =A2 -> Mark
A25: Job Title: | B25: Staff
A26: Payment Date: | B26: =C8+1 -> 46062
A27: Cut Off Period: | B27: Feb-2 to Feb-08, 2026
A28: Days Worked | B28: =COUNTIF(D2:D8, "*:*") -> 5
A29: Adjustments
A30: Basic Pay | B30: =B15 -> 1069.145
A31: Bonus/Incentives | B31: 0
A32: Overtime Pay | B32: =C15 -> 138.85
A33: Other Income | B33: 0
A36: Gross Pay | B36: =D15 -> 1207.995
A37: Deductions | B37: 0
A38: WH Tax | B38: 0
A40: Net Pay | B40: =SUM(B36:B38) -> 1207.995

Sheet Lenard
A1: Employee | B1: Shift | C1: Date | D1: Time In | E1: Time Out | F1: Hourly Rate | G1: Total Hours | H1: Regular Hours | I1: Overtime Hours | J1: Regular Pay | K1: Overtime Pay | L1: Total Pay
A2: Lenard | B2: 5:00PM-10:00PM | C2: 2026-01-26 | D2: 0 | E2: 0 | F2: 22.22 | G2: =(E2-D2)*24 -> 0 | H2: =MIN(G2,9) -> 0 | I2: =IF(MAX(G2-9,0) - 1 < 0, 0, MAX(G2-9,0) - 1) -> 0 | J2: =H2*F2 -> 0 | K2: =I2*F2*1.2 -> 0 | L2: =J2+K2 -> 0
A3: Lenard | B3: 5:00PM-10:00PM | C3: 2026-01-27 | D3: 0 | E3: 0 | F3: 22.22 | G3: =(E3-D3)*24 -> 0 | H3: =MIN(G3,9) -> 0 | I3: =IF(MAX(G3-9,0) - 1 < 0, 0, MAX(G3-9,0) - 1) -> 0 | J3: =H3*F3 -> 0 | K3: =I3*F3*1.2 -> 0 | L3: =J3+K3 -> 0
A4: Lenard | B4: 5:00PM-10:00PM | C4: 2026-01-28 | D4: 0 | E4: 0 | F4: 22.22 | G4: =(E4-D4)*24 -> 0 | H4: =MIN(G4,9) -> 0 | I4: =IF(MAX(G4-9,0) - 1 < 0, 0, MAX(G4-9,0) - 1) -> 0 | J4: =H4*F4 -> 0 | K4: =I4*F4*1.2 -> 0 | L4: =J4+K4 -> 0
A5: Lenard | B5: 5:00PM-10:00PM | C5: 2026-01-29 | D5: 0 | E5: 0 | F5: 22.22 | G5: =(E5-D5)*24 -> 0 | H5: =MIN(G5,9) -> 0 | I5: =IF(MAX(G5-9,0) - 1 < 0, 0, MAX(G5-9,0) - 1) -> 0 | J5: =H5*F5 -> 0 | K5: =I5*F5*1.2 -> 0 | L5: =J5+K5 -> 0
A6: Lenard | B6: 5:00PM-10:00PM | C6: 2026-01-30 | D6: 0 | E6: 0 | F6: 22.22 | G6: =(E6-D6)*24 -> 0 | H6: =MIN(G6,9) -> 0 | I6: =IF(MAX(G6-9,0) - 1 < 0, 0, MAX(G6-9,0) - 1) -> 0 | J6: =H6*F6 -> 0 | K6: =I6*F6*1.2 -> 0 | L6: =J6+K6 -> 0
A7: Lenard | B7: 9:30AM-10:00PM | C7: 2026-01-31 | D7: 0 | E7: 0 | F7: 22.22 | G7: =(E7-D7)*24 -> 0 | H7: =MIN(G7,9) -> 0 | I7: =IF(MAX(G7-9,0) - 1 < 0, 0, MAX(G7-9,0) - 1) -> 0 | J7: =H7*F7 -> 0 | K7: =I7*F7*1.2 -> 0 | L7: =J7+K7 -> 0
A8: Lenard | B8: 9:30AM-10:00PM | C8: 2026-02-01 | D8: 0 | E8: 0 | F8: 22.22 | G8: =(E8-D8)*24 -> 0 | H8: =MIN(G8,9) -> 0 | I8: =IF(MAX(G8-9,0) - 1 < 0, 0, MAX(G8-9,0) - 1) -> 0 | J8: =H8*F8 -> 0 | K8: =I8*F8*1.2 -> 0 | L8: =J8+K8 -> 0
A14: SUMMARY | B14: REGULAR PAY | C14: OVER TIME PAY | D14: TOTAL PAY
A15: Lenard | B15: =SUM(J2:J13) -> 0 | C15: =SUM(K2:K13) -> 0 | D15: =SUM(L2:L13) -> 0
A23: PAYROLL SLIP
A24: Name: | B24: =A2 -> Lenard
A25: Job Title: | B25: Staff
A26: Payment Date: | B26: =C8+1 -> 46055
A27: Cut Off Period: | B27: Feb-2 to Feb-08, 2026
A28: Days Worked | B28: =COUNTIF(D2:D8, "*:*") -> 0
A29: Adjustments
A30: Basic Pay | B30: =B15 -> 0
A31: Bonus/Incentives | B31: 0
A32: Overtime Pay | B32: =C15 -> 0
A33: Other Income | B33: 0
A36: Gross Pay | B36: =D15 -> 0
A37: Deductions | B37: 0
A38: WH Tax | B38: 0
A40: Net Pay | B40: =SUM(B36:B38) -> 0

Sheet Chadiyah
A1: Employee | B1: Shift | C1: Date | D1: Time In | E1: Time Out | F1: Hourly Rate | G1: Total Hours | H1: Regular Hours | I1: Overtime Hours | J1: Regular Pay | K1: Overtime Pay | L1: Total Pay
A2: Chadiyah | B2: 8:30AM-9:00PM | C2: 2026-02-02 | D2: 08:30 | E2: 15:00 | F2: 34.18 | G2: =(E2-D2)*24 -> 6.5 | H2: =MIN(G2,9) -> 6.5 | I2: =IF(MAX(G2-9,0) - 1 < 0, 0, MAX(G2-9,0) - 1) -> 0 | J2: =H2*F2 -> 222.17 | K2: =I2*F2*1.2 -> 0 | L2: =J2+K2 -> 222.17
A3: Chadiyah | B3: 8:30AM-9:00PM | C3: 2026-02-03 | D3: 08:30 | E3: 18:30 | F3: 34.18 | G3: =(E3-D3)*24 -> 10 | H3: =MIN(G3,9) -> 9 | I3: =IF(MAX(G3-9,0) - 1 < 0, 0, MAX(G3-9,0) - 1) -> 0 | J3: =H3*F3 -> 307.62 | K3: =I3*F3*1.2 -> 0 | L3: =J3+K3 -> 307.62
A4: Chadiyah | B4: 8:30AM-9:00PM | C4: 2026-02-04 | D4: 08:30 | E4: 20:00 | F4: 34.18 | G4: =(E4-D4)*24 -> 11.5 | H4: =MIN(G4,9) -> 9 | I4: =IF(MAX(G4-9,0) - 1 < 0, 0, MAX(G4-9,0) - 1) -> 1.5 | J4: =H4*F4 -> 307.62 | K4: =I4*F4*1.2 -> 61.524 | L4: =J4+K4 -> 369.144
A5: Chadiyah | B5: 8:30AM-9:00PM | C5: 2026-02-05 | D5: 08:30 | E5: 18:00 | F5: 34.18 | G5: =(E5-D5)*24 -> 9.5 | H5: =MIN(G5,9) -> 9 | I5: =IF(MAX(G5-9,0) - 1 < 0, 0, MAX(G5-9,0) - 1) -> 0 | J5: =H5*F5 -> 307.62 | K5: =I5*F5*1.2 -> 0 | L5: =J5+K5 -> 307.62
A6: Chadiyah | B6: 8:30AM-9:00PM | C6: 2026-02-06 | D6: 08:30 | E6: 17:30 | F6: 34.18 | G6: =(E6-D6)*24 -> 9 | H6: =MIN(G6,9) -> 9 | I6: =IF(MAX(G6-9,0) - 1 < 0, 0, MAX(G6-9,0) - 1) -> 0 | J6: =H6*F6 -> 307.62 | K6: =I6*F6*1.2 -> 0 | L6: =J6+K6 -> 307.62
A7: Chadiyah | B7: 8:30AM-9:00PM | C7: 2026-02-07 | D7: 08:30 | E7: 17:00 | F7: 34.18 | G7: =(E7-D7)*24 -> 8.5 | H7: =MIN(G7,9) -> 8.5 | I7: =IF(MAX(G7-9,0) - 1 < 0, 0, MAX(G7-9,0) - 1) -> 0 | J7: =H7*F7 -> 290.53 | K7: =I7*F7*1.2 -> 0 | L7: =J7+K7 -> 290.53
A8: Chadiyah | B8: 8:30AM-9:00PM | C8: 2026-02-08 | D8: 0 | E8: 0 | F8: 34.18 | G8: =(E8-D8)*24 -> 0 | H8: =MIN(G8,9) -> 0 | I8: =IF(MAX(G8-9,0) - 1 < 0, 0, MAX(G8-9,0) - 1) -> 0 | J8: =H8*F8 -> 0 | K8: =I8*F8*1.2 -> 0 | L8: =J8+K8 -> 0
A14: SUMMARY | B14: REGULAR PAY | C14: OVER TIME PAY | D14: TOTAL PAY
A15: Chadiyah | B15: =SUM(J2:J13) -> 1743.18 | C15: =SUM(K2:K13) -> 61.524 | D15: =SUM(L2:L13) -> 1804.704
A23: PAYROLL SLIP
A24: Name: | B24: =A2 -> Chadiyah
A25: Job Title: | B25: Staff
A26: Payment Date: | B26: =C8+1 -> 46062
A27: Cut Off Period: | B27: Jan-26 to Feb-01, 2026
A28: Days Worked | B28: =COUNTIF(D2:D8, "*:*") -> 6
A29: Adjustments
A30: Basic Pay | B30: =B15 -> 1743.18
A31: Bonus/Incentives | B31: 0
A32: Overtime Pay | B32: =C15 -> 61.524
A33: Other Income | B33: 0
A36: Gross Pay | B36: =D15 -> 1804.704
A37: Deductions | B37: 0
A38: WH Tax | B38: 0
A40: Net Pay | B40: =SUM(B36:B38) -> 1804.704

Sheet Template
A1: Employee | B1: Shift | C1: Date | D1: Time In | E1: Time Out | F1: Hourly Rate | G1: Total Hours | H1: Regular Hours | I1: Overtime Hours | J1: Regular Pay | K1: Overtime Pay | L1: Total Pay
A2: Name | B2: 8:30AM-9:00PM | C2: 2026-01-12 | D2: 08:30 | E2: 22:00 | F2: 38.46 | G2: =(E2-D2)*24 -> 13.5 | H2: =MIN(G2,10) -> 10 | I2: =MAX(G2-10,0) - 1 -> 2.5 | J2: =H2*F2 -> 384.6 | K2: =I2*F2*1.2 -> 115.38 | L2: =J2+K2 -> 499.98
A3: Name | B3: 8:30AM-9:00PM | C3: 2026-01-13 | D3: 08:30 | E3: 22:00 | F3: 38.46 | G3: =(E3-D3)*24 -> 13.5 | H3: =MIN(G3,10) -> 10 | I3: =MAX(G3-10,0) - 1 -> 2.5 | J3: =H3*F3 -> 384.6 | K3: =I3*F3*1.2 -> 115.38 | L3: =J3+K3 -> 499.98
A4: Name | B4: 8:30AM-9:00PM | C4: 2026-01-14 | D4: 08:30 | E4: 22:00 | F4: 38.46 | G4: =(E4-D4)*24 -> 13.5 | H4: =MIN(G4,10) -> 10 | I4: =MAX(G4-10,0) - 1 -> 2.5 | J4: =H4*F4 -> 384.6 | K4: =I4*F4*1.2 -> 115.38 | L4: =J4+K4 -> 499.98
A5: Name | B5: 8:30AM-9:00PM | C5: 2026-01-15 | D5: 08:30 | E5: 22:00 | F5: 38.46 | G5: =(E5-D5)*24 -> 13.5 | H5: =MIN(G5,10) -> 10 | I5: =MAX(G5-10,0) - 1 -> 2.5 | J5: =H5*F5 -> 384.6 | K5: =I5*F5*1.2 -> 115.38 | L5: =J5+K5 -> 499.98
A6: Name | B6: 8:30AM-9:00PM | C6: 2026-01-16 | D6: 08:30 | E6: 22:00 | F6: 38.46 | G6: =(E6-D6)*24 -> 13.5 | H6: =MIN(G6,10) -> 10 | I6: =MAX(G6-10,0) - 1 -> 2.5 | J6: =H6*F6 -> 384.6 | K6: =I6*F6*1.2 -> 115.38 | L6: =J6+K6 -> 499.98
A7: Name | B7: 8:30AM-9:00PM | C7: 2026-01-17 | D7: 08:30 | E7: 22:00 | F7: 38.46 | G7: =(E7-D7)*24 -> 13.5 | H7: =MIN(G7,10) -> 10 | I7: =MAX(G7-10,0) - 1 -> 2.5 | J7: =H7*F7 -> 384.6 | K7: =I7*F7*1.2 -> 115.38 | L7: =J7+K7 -> 499.98
A8: Name | B8: 8:30AM-9:00PM | C8: 2026-01-18 | D8: 08:30 | E8: 22:00 | F8: 38.46 | G8: =(E8-D8)*24 -> 13.5 | H8: =MIN(G8,10) -> 10 | I8: =MAX(G8-10,0) - 1 -> 2.5 | J8: =H8*F8 -> 384.6 | K8: =I8*F8*1.2 -> 115.38 | L8: =J8+K8 -> 499.98
A14: SUMMARY | B14: REGULAR PAY | C14: OVER TIME PAY | D14: TOTAL PAY
A15: Rhea Mae | B15: =SUM(J2:J13) -> 2692.2 | C15: =SUM(K2:K13) -> 807.66 | D15: =SUM(L2:L13) -> 3499.86
A23: PAYROLL SLIP
A24: Name: | B24: =A2 -> Name
A25: Job Title: | B25: Store Manager
A26: Payment Date: | B26: 46041
A27: Cut Off Period: | B27: Jan-12 to Jan-28, 2026
A29: Adjustments
A30: Basic Pay | B30: =B15 -> 2692.2
A31: Bonus/Incentives | B31: 0
A32: Overtime Pay | B32: =C15 -> 807.66
A33: Other Income | B33: 0
A36: Gross Pay | B36: =D15 -> 3499.86
A37: Deductions | B37: 0
A38: WH Tax | B38: 0
A40: Net Pay | B40: =SUM(B36:B38) -> 3499.86

Sheet Rhoda
A1: Employee | B1: Date | C1: Shift | D1: Time In | E1: Time Out | F1: Hourly Rate | G1: Total Hours | H1: Regular Hours | I1: Overtime Hours | J1: Regular Pay | K1: Overtime Pay | L1: Total Pay
A2: Rhoda | B2: 46021 | C2: 9:00AM-7:00PM | D2: 0.45833333 | E2: 0.99930556 | F2: 29.91 | G2: 15 | H2: =MIN(G2,9) -> 9 | I2: =MAX(G2-9,0) - 1 -> 5 | J2: =H2*F2 -> 269.19 | K2: =I2*F2*1.2 -> 179.46 | L2: =J2+K2 -> 448.65
A3: Rhoda | B3: 46022 | C3: 9:00AM-7:00PM | D3: 0.41666667 | E3: 0.8125 | F3: 29.91 | G3: =(E3-D3)*24 -> 9.5 | H3: =MIN(G3,9) -> 9 | I3: =MAX(G3-9,0) - 1 -> -0.5 | J3: =H3*F3 -> 269.19 | L3: 538 | M3: doublepay
A4: Rhoda | B4: 46027 | C4: 9:00AM-7:00PM | D4: 0.375 | E4: 0.91666667 | F4: 29.91 | G4: =(E4-D4)*24 -> 13 | H4: =MIN(G4,9) -> 9 | I4: =MAX(G4-9,0) - 1 -> 3 | J4: =H4*F4 -> 269.19 | K4: =I4*F4*1.2 -> 107.676 | L4: =J4+K4 -> 376.866
A5: Rhoda | B5: 46028 | C5: 9:00AM-7:00PM | D5: 0.375 | E5: 0.875 | F5: 29.91 | G5: =(E5-D5)*24 -> 12 | H5: =MIN(G5,9) -> 9 | I5: =MAX(G5-9,0) - 1 -> 2 | J5: =H5*F5 -> 269.19 | K5: =I5*F5*1.2 -> 71.784 | L5: =J5+K5 -> 340.974
A6: Rhoda | B6: 46029 | C6: 9:00AM-7:00PM | D6: 0.375 | E6: 0.9375 | F6: 29.91 | G6: =(E6-D6)*24 -> 13.5 | H6: =MIN(G6,9) -> 9 | I6: =MAX(G6-9,0) - 1 -> 3.5 | J6: =H6*F6 -> 269.19 | K6: =I6*F6*1.2 -> 125.622 | L6: =J6+K6 -> 394.812
A7: Rhoda | B7: 46030 | C7: 9:00AM-7:00PM | D7: 0.375 | E7: 0.99930556 | F7: 29.91 | G7: 15 | H7: =MIN(G7,9) -> 9 | I7: =MAX(G7-9,0) - 1 -> 5 | J7: =H7*F7 -> 269.19 | K7: =I7*F7*1.2 -> 179.46 | L7: =J7+K7 -> 448.65
A8: Rhoda | B8: 46031 | C8: 9:00AM-7:00PM | D8: 0.51041667 | E8: 0.91805556 | F8: 29.91 | G8: =(E8-D8)*24 -> 9.7833333 | H8: =MIN(G8,9) -> 9 | I8: =MAX(G8-9,0) - 1 -> -0.21666667 | J8: =H8*F8 -> 269.19 | L8: =J8+K8 -> 269.19
A9: Rhoda | B9: 46032 | C9: 9:00AM-7:00PM | D9: 0.43402778 | E9: 0.90625 | F9: 29.91 | G9: =(E9-D9)*24 -> 11.333333 | H9: =MIN(G9,9) -> 9 | I9: =MAX(G9-9,0) - 1 -> 1.3333333 | J9: =H9*F9 -> 269.19 | K9: =I9*F9*1.2 -> 47.856 | L9: =J9+K9 -> 317.046
J10: =SUM(J2:J9) -> 2153.52 | K10: =SUM(K2:K9) -> 711.858 | L10: =SUM(L2:L9) -> 3134.188

Sheet Kenneth
A1: Employee | B1: Date | C1: Shift | D1: Time In | E1: Time Out | F1: Hourly Rate | G1: Total Hours | H1: Regular Hours | I1: Overtime Hours | J1: Regular Pay | K1: Overtime Pay | L1: Total Pay
A2: Kenneth | B2: 46027
A3: Kenneth | B3: 46028
A4: Kenneth | B4: 46029
A5: Kenneth | B5: 46030
A6: Kenneth | B6: 46031 | D6: 0.70833333 | E6: 0.9375 | F6: 22.22 | G6: =(E6-D6)*24 -> 5.5 | H6: =MIN(G6,9) -> 5.5 | I6: =MAX(G6-9,0) - 1 -> -1 | J6: =H6*F6 -> 122.21 | L6: =J6+K6 -> 122.21
A7: Kenneth | B7: 46032 | D7: 0.70833333 | E7: 0.91666667 | F7: 22.22 | G7: =(E7-D7)*24 -> 5 | H7: =MIN(G7,9) -> 5 | I7: =MAX(G7-9,0) - 1 -> -1 | J7: =H7*F7 -> 111.1 | L7: =J7+K7 -> 111.1
A8: Kenneth | B8: 46033 | D8: 0.72986111 | E8: 0.91666667 | F8: 22.22 | G8: =(E8-D8)*24 -> 4.4833333 | H8: =MIN(G8,9) -> 4.4833333 | I8: =MAX(G8-9,0) - 1 -> -1 | J8: =H8*F8 -> 99.619667 | L8: =J8+K8 -> 99.619667
L9: =SUM(L6:L8) -> 332.92967
