Workbook

Sheet Payslip
A1: PAYROLL SLIP | D1: PAYROLL SLIP
A2: ='Rhea Mae'!A24 -> Name: | B2: ='Rhea Mae'!B24 -> Rhea Mae | D2: ='Jay Anne'!A24 -> Name: | E2: ='Jay Anne'!B24 -> Jay Anne
A3: ='Rhea Mae'!A25 -> Job Title: | B3: ='Rhea Mae'!B25 -> Store Manager | D3: ='Jay Anne'!A25 -> Job Title: | E3: ='Jay Anne'!B25 -> Cashier
A4: ='Rhea Mae'!A26 -> Payment Date: | B4: ='Rhea Mae'!B26 -> 46069 | D4: ='Jay Anne'!A26 -> Payment Date: | E4: ='Jay Anne'!B26 -> 46076
A5: ='Rhea Mae'!A27 -> Cut Off Period: | B5: ='Rhea Mae'!B27 -> Feb-9 to Feb-15, 2026 | D5: ='Jay Anne'!A27 -> Cut Off Period: | E5: ='Jay Anne'!B27 -> Feb-9 to Feb-15, 2026
A6: ='Rhea Mae'!A28 -> Days Worked | B6: ='Rhea Mae'!B28 -> 5 | D6: ='Jay Anne'!A28 -> Days Worked | E6: ='Jay Anne'!B28 -> 5
A7: ='Rhea Mae'!A29 -> Adjustments | D7: ='Jay Anne'!A29 -> Adjustments
A8: ='Rhea Mae'!A30 -> Basic Pay | B8: ='Rhea Mae'!B30 -> 1730.7 | D8: ='Jay Anne'!A30 -> Basic Pay | E8: ='Jay Anne'!B30 -> 1345.95
A9: ='Rhea Mae'!A31 -> Bonus/Incentives | B9: ='Rhea Mae'!B31 -> 0 | D9: ='Jay Anne'!A31 -> Bonus/Incentives | E9: ='Jay Anne'!B31 -> 0
A10: ='Rhea Mae'!A32 -> Overtime Pay | B10: ='Rhea Mae'!B32 -> 759.2004 | D10: ='Jay Anne'!A32 -> Overtime Pay | E10: ='Jay Anne'!B32 -> 236.289
A11: ='Rhea Mae'!A33 -> Other Income | B11: ='Rhea Mae'!B33 -> 0 | D11: ='Jay Anne'!A33 -> Other Income | E11: ='Jay Anne'!B33 -> 0
A14: ='Rhea Mae'!A36 -> Gross Pay | B14: ='Rhea Mae'!B36 -> 2489.9004 | D14: ='Jay Anne'!A36 -> Gross Pay | E14: ='Jay Anne'!B36 -> 1582.239
A15: ='Rhea Mae'!A37 -> Deductions | B15: ='Rhea Mae'!B37 -> 0 | D15: ='Jay Anne'!A37 -> Deductions | E15: ='Jay Anne'!B37 -> 0
A16: ='Rhea Mae'!A38 -> WH Tax | B16: ='Rhea Mae'!B38 -> 0 | D16: ='Jay Anne'!A38 -> WH Tax | E16: ='Jay Anne'!B38 -> 0
A18: ='Rhea Mae'!A40 -> Net Pay | B18: ='Rhea Mae'!B40 -> 2489.9004 | D18: ='Jay Anne'!A40 -> Net Pay | E18: ='Jay Anne'!B40 -> 1582.239
A21: PAYROLL SLIP | D21: PAYROLL SLIP
A22: =Kris!A24 -> Name: | B22: =Kris!B24 -> Kris Naynayan | D22: =Christian!A24 -> Name: | E22: =Christian!B24 -> Christian
A23: =Kris!A25 -> Job Title: | B23: =Kris!B25 -> Staff | D23: =Christian!A25 -> Job Title: | E23: =Christian!B25 -> Staff
A24: =Kris!A26 -> Payment Date: | B24: =Kris!B26 -> 46076 | D24: =Christian!A26 -> Payment Date: | E24: =Christian!B26 -> 46076
A25: =Kris!A27 -> Cut Off Period: | B25: =Kris!B27 -> Feb-9 to Feb-15, 2026 | D25: =Christian!A27 -> Cut Off Period: | E25: =Christian!B27 -> Feb-9 to Feb-15, 2026
A26: =Kris!A28 -> Days Worked | B26: =Kris!B28 -> 5 | D26: =Christian!A28 -> Days Worked | E26: =Christian!B28 -> 5
A27: =Kris!A29 -> Adjustments | D27: =Christian!A29 -> Adjustments
A28: =Kris!A30 -> Basic Pay | B28: =Kris!B30 -> 1634.4 | D28: =Christian!A30 -> Basic Pay | E28: =Christian!B30 -> 1634.4
A29: =Kris!A31 -> Bonus/Incentives | B29: =Kris!B31 -> 0 | D29: =Christian!A31 -> Bonus/Incentives | E29: =Christian!B31 -> 0
A30: =Kris!A32 -> Overtime Pay | B30: =Kris!B32 -> 536.8096 | D30: =Christian!A32 -> Overtime Pay | E30: =Christian!B32 -> 524.4608
A31: =Kris!A33 -> Other Income | B31: =Kris!B33 -> 0 | D31: =Christian!A33 -> Other Income | E31: =Christian!B33 -> 0
A34: =Kris!A36 -> Gross Pay | B34: =Kris!B36 -> 2171.2096 | D34: =Christian!A36 -> Gross Pay | E34: =Christian!B36 -> 2158.8608
A35: =Kris!A37 -> Deductions | B35: =Kris!B37 -> 0 | D35: =Christian!A37 -> Deductions | E35: =Christian!B37 -> 0
A36: =Kris!A38 -> WH Tax | B36: =Kris!B38 -> 0 | D36: =Christian!A38 -> WH Tax | E36: =Christian!B38 -> 0
A38: =Kris!A40 -> Net Pay | B38: =Kris!B40 -> 2171.2096 | D38: =Christian!A40 -> Net Pay | E38: =Christian!B40 -> 2158.8608
A42: PAYROLL SLIP | D42: PAYROLL SLIP
A43: =Cherry!A24 -> Name: | B43: =Cherry!B24 -> Cherry | D43: =Aldrin!A24 -> Name: | E43: =Aldrin!B24 -> Aldrin
A44: =Cherry!A25 -> Job Title: | B44: =Cherry!B25 -> Staff | D44: =Aldrin!A25 -> Job Title: | E44: =Aldrin!B25 -> Staff
A45: =Cherry!A26 -> Payment Date: | B45: =Cherry!B26 -> 46076 | D45: =Aldrin!A26 -> Payment Date: | E45: =Aldrin!B26 -> 46076
A46: =Cherry!A27 -> Cut Off Period: | B46: =Cherry!B27 -> Feb-9 to Feb-15, 2026 | D46: =Aldrin!A27 -> Cut Off Period: | E46: =Aldrin!B27 -> Feb-9 to Feb-15, 2026
A47: =Cherry!A28 -> Days Worked | B47: =Cherry!B28 -> 5 | D47: =Aldrin!A28 -> Days Worked | E47: =Aldrin!B28 -> 5
A48: =Cherry!A29 -> Adjustments | D48: =Aldrin!A29 -> Adjustments
A49: =Cherry!A30 -> Basic Pay | B49: =Cherry!B30 -> 1499.85 | D49: =Aldrin!A30 -> Basic Pay | E49: =Aldrin!B30 -> 1138.57
A50: =Cherry!A31 -> Bonus/Incentives | B50: =Cherry!B31 -> 0 | D50: =Aldrin!A31 -> Bonus/Incentives | E50: =Aldrin!B31 -> 0
A51: =Cherry!A32 -> Overtime Pay | B51: =Cherry!B32 -> 599.94 | D51: =Aldrin!A32 -> Overtime Pay | E51: =Aldrin!B32 -> 166.62
...

Sheet Summary
A1: lenard lagrimas | B1: Not Set1 | C1: 2026-02-16 | D1: Missed | E1: Missed | F1: Missed
A2: lenard lagrimas | B2: Not Set1 | C2: 2026-02-17 | D2: Missed | E2: Missed | F2: Missed
A3: lenard lagrimas | B3: Not Set1 | C3: 2026-02-18 | D3: Missed | E3: 21:47 | F3: Missed
A4: lenard lagrimas | B4: Not Set1 | C4: 2026-02-19 | D4: Missed | E4: 16:21 | F4: Missed
A5: lenard lagrimas | B5: Not Set1 | C5: 2026-02-20 | D5: Missed | E5: 16:23 | F5: Missed
A6: lenard lagrimas | B6: Not Set1 | C6: 2026-02-21 | D6: 08:57 | E6: 21:09 | F6: Missed
A7: lenard lagrimas | B7: Not Set1 | C7: 2026-02-22 | D7: 12:23 | E7: 21:11 | F7: Missed
A8: jay ann | B8: Not Set1 | C8: 2026-02-16 | D8: Missed | E8: Missed | F8: Missed
A9: jay ann | B9: Not Set1 | C9: 2026-02-17 | D9: 09:15 | E9: 21:01 | F9: Missed
A10: jay ann | B10: Not Set1 | C10: 2026-02-18 | D10: 09:37 | E10: 21:15 | F10: Missed
A11: jay ann | B11: Not Set1 | C11: 2026-02-19 | D11: 09:45 | E11: 21:13 | F11: Missed
A12: jay ann | B12: Not Set1 | C12: 2026-02-20 | D12: 09:51 | E12: 21:16 | F12: Missed
... A56: mark agire | B56: Not Set1 | C56: 2026-02-22 | D56: Missed | E56: Missed | F56: Missed

Sheet Jay Anne
A1: Employee | B1: Shift | C1: Date | D1: Time In | E1: Time Out | F1: Hourly Rate | G1: Total Hours | H1: Regular Hours | I1: Overtime Hours | J1: Regular Pay | K1: Overtime Pay | L1: Total Pay
A2: Jay Anne | B2: 10:00AM-9:00PM | C2: 2026-02-16 | D2: 0 | E2: 0 | F2: 29.91 | G2: =(E2-D2)*24 -> 0 | H2: =MIN(G2,9) -> 0 | I2: =IF(MAX(G2-9,0) - 1 < 0, 0, MAX(G2-9,0) - 1) -> 0 | J2: =H2*F2 -> 0 | K2: =I2*F2*1.2 -> 0 | L2: =J2+K2 -> 0
A3: Jay Anne | B3: 10:00AM-9:00PM | C3: 2026-02-17 | D3: 09:30 | E3: 21:00. | F3: 29.91 | G3: =(E3-D3)*24 -> 11.5 | H3: =MIN(G3,9) -> 9 | I3: =IF(MAX(G3-9,0) - 1 < 0, 0, MAX(G3-9,0) - 1) -> 1.5 | J3: =H3*F3 -> 269.19 | K3: =I3*F3*1.2 -> 53.838 | L3: =J3+K3 -> 323.028
A4: Jay Anne | B4: 10:00AM-9:00PM | C4: 2026-02-18 | D4: 09:30 | E4: 21:00. | F4: 29.91 | G4: =(E4-D4)*24 -> 11.5 | H4: =MIN(G4,9) -> 9 | I4: =IF(MAX(G4-9,0) - 1 < 0, 0, MAX(G4-9,0) - 1) -> 1.5 | J4: =H4*F4 -> 269.19 | K4: =I4*F4*1.2 -> 53.838 | L4: =J4+K4 -> 323.028
A5: Jay Anne | B5: 10:00AM-9:00PM | C5: 2026-02-19 | D5: 09:30 | E5: 21:00. | F5: 29.91 | G5: =(E5-D5)*24 -> 11.5 | H5: =MIN(G5,9) -> 9 | I5: =IF(MAX(G5-9,0) - 1 < 0, 0, MAX(G5-9,0) - 1) -> 1.5 | J5: =H5*F5 -> 269.19 | K5: =I5*F5*1.2 -> 53.838 | L5: =J5+K5 -> 323.028
A6: Jay Anne | B6: 10:00AM-9:00PM | C6: 2026-02-20 | D6: 09:51 | E6: 21:00. | F6: 29.91 | G6: =(E6-D6)*24 -> 11.15 | H6: =MIN(G6,9) -> 9 | I6: =IF(MAX(G6-9,0) - 1 < 0, 0, MAX(G6-9,0) - 1) -> 1.15 | J6: =H6*F6 -> 269.19 | K6: =I6*F6*1.2 -> 41.2758 | L6: =J6+K6 -> 310.4658
A7: Jay Anne | B7: 10:00AM-9:00PM | C7: 2026-02-21 | D7: 10:04 | E7: 21:00. | F7: 29.91 | G7: =(E7-D7)*24 -> 10.933333 | H7: =MIN(G7,9) -> 9 | I7: =IF(MAX(G7-9,0) - 1 < 0, 0, MAX(G7-9,0) - 1) -> 0.93333333 | J7: =H7*F7 -> 269.19 | K7: =I7*F7*1.2 -> 33.4992 | L7: =J7+K7 -> 302.6892
A8: Jay Anne | B8: 10:00AM-9:00PM | C8: 2026-02-22 | D8: 0 | E8: 0 | F8: 29.91 | G8: =(E8-D8)*24 -> 0 | H8: =MIN(G8,9) -> 0 | I8: =IF(MAX(G8-9,0) - 1 < 0, 0, MAX(G8-9,0) - 1) -> 0 | J8: =H8*F8 -> 0 | K8: =I8*F8*1.2 -> 0 | L8: =J8+K8 -> 0
A14: SUMMARY | B14: REGULAR PAY | C14: OVER TIME PAY | D14: TOTAL PAY
A15: Jay Anne | B15: =SUM(J2:J13) -> 1345.95 | C15: =SUM(K2:K13) -> 236.289 | D15: =SUM(L2:L13) -> 1582.239
A23: PAYROLL SLIP
A24: Name: | B24: =A2 -> Jay Anne
A25: Job Title: | B25: Cashier
A26: Payment Date: | B26: =C8+1 -> 46076
A27: Cut Off Period: | B27: ='Rhea Mae'!B27 -> Feb-9 to Feb-15, 2026
A28: Days Worked | B28: =COUNTIF(D2:D8, "*:*") -> 5
A29: Adjustments
A30: Basic Pay | B30: =B15 -> 1345.95
A31: Bonus/Incentives | B31: 0
A32: Overtime Pay | B32: =C15 -> 236.289
A33: Other Income | B33: 0
A36: Gross Pay | B36: =D15 -> 1582.239
A37: Deductions | B37: 0
A38: WH Tax | B38: 0
A40: Net Pay | B40: =SUM(B36:B38) -> 1582.239

Sheet Kris
A1: Employee | B1: Shift | C1: Date | D1: Time In | E1: Time Out | F1: Hourly Rate | G1: Total Hours | H1: Regular Hours | I1: Overtime Hours | J1: Regular Pay | K1: Overtime Pay | L1: Total Pay
A2: Kris Naynayan | B2: 8:30AM-9:00PM | C2: 2026-02-16 | D2: 08:30 | E2: 21:30 | F2: 36.32 | G2: =(E2-D2)*24 -> 13 | H2: =MIN(G2,9) -> 9 | I2: =IF(MAX(G2-9,0) - 1 < 0, 0, MAX(G2-9,0) - 1) -> 3 | J2: =H2*F2 -> 326.88 | K2: =I2*F2*1.2 -> 130.752 | L2: =J2+K2 -> 457.632
A3: Kris Naynayan | B3: 8:30AM-9:00PM | C3: 2026-02-17 | D3: 10:11 | E3: 21:30 | F3: 36.32 | G3: =(E3-D3)*24 -> 11.316667 | H3: =MIN(G3,9) -> 9 | I3: =IF(MAX(G3-9,0) - 1 < 0, 0, MAX(G3-9,0) - 1) -> 1.3166667 | J3: =H3*F3 -> 326.88 | K3: =I3*F3*1.2 -> 57.3856 | L3: =J3+K3 -> 384.2656
A4: Kris Naynayan | B4: 8:30AM-9:00PM | C4: 2026-02-18 | D4: 0 | E4: 0 | F4: 36.32 | G4: =(E4-D4)*24 -> 0 | H4: =MIN(G4,9) -> 0 | I4: =IF(MAX(G4-9,0) - 1 < 0, 0, MAX(G4-9,0) - 1) -> 0 | J4: =H4*F4 -> 0 | K4: =I4*F4*1.2 -> 0 | L4: =J4+K4 -> 0
A5: Kris Naynayan | B5: 8:30AM-9:00PM | C5: 2026-02-19 | D5: 08:30 | E5: 21:00 | F5: 36.32 | G5: =(E5-D5)*24 -> 12.5 | H5: =MIN(G5,9) -> 9 | I5: =IF(MAX(G5-9,0) - 1 < 0, 0, MAX(G5-9,0) - 1) -> 2.5 | J5: =H5*F5 -> 326.88 | K5: =I5*F5*1.2 -> 108.96 | L5: =J5+K5 -> 435.84
A6: Kris Naynayan | B6: 8:30AM-9:00PM | C6: 2026-02-20 | D6: 08:30 | E6: 21:30 | F6: 36.32 | G6: =(E6-D6)*24 -> 13 | H6: =MIN(G6,9) -> 9 | I6: =IF(MAX(G6-9,0) - 1 < 0, 0, MAX(G6-9,0) - 1) -> 3 | J6: =H6*F6 -> 326.88 | K6: =I6*F6*1.2 -> 130.752 | L6: =J6+K6 -> 457.632
A7: Kris Naynayan | B7: 8:30AM-9:00PM | C7: 2026-02-21 | D7: 0 | E7: 0 | F7: 36.32 | G7: =(E7-D7)*24 -> 0 | H7: =MIN(G7,9) -> 0 | I7: =IF(MAX(G7-9,0) - 1 < 0, 0, MAX(G7-9,0) - 1) -> 0 | J7: =H7*F7 -> 0 | K7: =I7*F7*1.2 -> 0 | L7: =J7+K7 -> 0
A8: Kris Naynayan | B8: 8:30AM-9:00PM | C8: 2026-02-22 | D8: 08:30 | E8: 21:00 | F8: 36.32 | G8: =(E8-D8)*24 -> 12.5 | H8: =MIN(G8,9) -> 9 | I8: =IF(MAX(G8-9,0) - 1 < 0, 0, MAX(G8-9,0) - 1) -> 2.5 | J8: =H8*F8 -> 326.88 | K8: =I8*F8*1.2 -> 108.96 | L8: =J8+K8 -> 435.84
A14: SUMMARY | B14: REGULAR PAY | C14: OVER TIME PAY | D14: TOTAL PAY
A15: Kris Naynayan | B15: =SUM(J2:J13) -> 1634.4 | C15: =SUM(K2:K13) -> 536.8096 | D15: =SUM(L2:L13) -> 2171.2096
A23: PAYROLL SLIP
A24: Name: | B24: =A2 -> Kris Naynayan
A25: Job Title: | B25: Staff
A26: Payment Date: | B26: =C8+1 -> 46076
A27: Cut Off Period: | B27: ='Rhea Mae'!B27 -> Feb-9 to Feb-15, 2026
A28: Days Worked | B28: =COUNTIF(D2:D8, "*:*") -> 5
A29: Adjustments
A30: Basic Pay | B30: =B15 -> 1634.4
A31: Bonus/Incentives | B31: 0
A32: Overtime Pay | B32: =C15 -> 536.8096
A33: Other Income | B33: 0
A36: Gross Pay | B36: =D15 -> 2171.2096
A37: Deductions | B37: 0
A38: WH Tax | B38: 0
A40: Net Pay | B40: =SUM(B36:B38) -> 2171.2096

Sheet Christian
A1: Employee | B1: Shift | C1: Date | D1: Time In | E1: Time Out | F1: Hourly Rate | G1: Total Hours | H1: Regular Hours | I1: Overtime Hours | J1: Regular Pay | K1: Overtime Pay | L1: Total Pay
A2: Christian | B2: 8:30AM-9:00PM | C2: 2026-02-16 | D2: 0 | E2: 0 | F2: 36.32 | G2: =(E2-D2)*24 -> 0 | H2: =MIN(G2,9) -> 0 | I2: =IF(MAX(G2-9,0) - 1 < 0, 0, MAX(G2-9,0) - 1) -> 0 | J2: =H2*F2 -> 0 | K2: =I2*F2*1.2 -> 0 | L2: =J2+K2 -> 0
A3: Christian | B3: 8:30AM-9:00PM | C3: 2026-02-17 | D3: 08:30 | E3: 21:00 | F3: 36.32 | G3: =(E3-D3)*24 -> 12.5 | H3: =MIN(G3,9) -> 9 | I3: =IF(MAX(G3-9,0) - 1 < 0, 0, MAX(G3-9,0) - 1) -> 2.5 | J3: =H3*F3 -> 326.88 | K3: =I3*F3*1.2 -> 108.96 | L3: =J3+K3 -> 435.84
A4: Christian | B4: 8:30AM-9:00PM | C4: 2026-02-18 | D4: 08:30 | E4: 21:00 | F4: 36.32 | G4: =(E4-D4)*24 -> 12.5 | H4: =MIN(G4,9) -> 9 | I4: =IF(MAX(G4-9,0) - 1 < 0, 0, MAX(G4-9,0) - 1) -> 2.5 | J4: =H4*F4 -> 326.88 | K4: =I4*F4*1.2 -> 108.96 | L4: =J4+K4 -> 435.84
A5: Christian | B5: 8:30AM-9:00PM | C5: 2026-02-19 | D5: 08:30 | E5: 21:00 | F5: 36.32 | G5: =(E5-D5)*24 -> 12.5 | H5: =MIN(G5,9) -> 9 | I5: =IF(MAX(G5-9,0) - 1 < 0, 0, MAX(G5-9,0) - 1) -> 2.5 | J5: =H5*F5 -> 326.88 | K5: =I5*F5*1.2 -> 108.96 | L5: =J5+K5 -> 435.84
A6: Christian | B6: 8:30AM-9:00PM | C6: 2026-02-20 | D6: 08:30 | E6: 21:00 | F6: 36.32 | G6: =(E6-D6)*24 -> 12.5 | H6: =MIN(G6,9) -> 9 | I6: =IF(MAX(G6-9,0) - 1 < 0, 0, MAX(G6-9,0) - 1) -> 2.5 | J6: =H6*F6 -> 326.88 | K6: =I6*F6*1.2 -> 108.96 | L6: =J6+K6 -> 435.84
A7: Christian | B7: 8:30AM-9:00PM | C7: 2026-02-21 | D7: 08:58 | E7: 21:00 | F7: 36.32 | G7: =(E7-D7)*24 -> 12.033333 | H7: =MIN(G7,9) -> 9 | I7: =IF(MAX(G7-9,0) - 1 < 0, 0, MAX(G7-9,0) - 1) -> 2.0333333 | J7: =H7*F7 -> 326.88 | K7: =I7*F7*1.2 -> 88.6208 | L7: =J7+K7 -> 415.5008
A8: Christian | B8: 8:30AM-9:00PM | C8: 2026-02-22 | D8: 0 | E8: 0 | F8: 36.32 | G8: =(E8-D8)*24 -> 0 | H8: =MIN(G8,9) -> 0 | I8: =IF(MAX(G8-9,0) - 1 < 0, 0, MAX(G8-9,0) - 1) -> 0 | J8: =H8*F8 -> 0 | K8: =I8*F8*1.2 -> 0 | L8: =J8+K8 -> 0
A14: SUMMARY | B14: REGULAR PAY | C14: OVER TIME PAY | D14: TOTAL PAY
A15: Christian | B15: =SUM(J2:J13) -> 1634.4 | C15: =SUM(K2:K13) -> 524.4608 | D15: =SUM(L2:L13) -> 2158.8608
A23: PAYROLL SLIP
A24: Name: | B24: =A2 -> Christian
A25: Job Title: | B25: Staff
A26: Payment Date: | B26: =C8+1 -> 46076
A27: Cut Off Period: | B27: ='Rhea Mae'!B27 -> Feb-9 to Feb-15, 2026
A28: Days Worked | B28: =COUNTIF(D2:D8, "*:*") -> 5
A29: Adjustments
A30: Basic Pay | B30: =B15 -> 1634.4
A31: Bonus/Incentives | B31: 0
A32: Overtime Pay | B32: =C15 -> 524.4608
A33: Other Income | B33: 0
A36: Gross Pay | B36: =D15 -> 2158.8608
A37: Deductions | B37: 0
A38: WH Tax | B38: 0
A40: Net Pay | B40: =SUM(B36:B38) -> 2158.8608

Sheet Cherry
A1: Employee | B1: Shift | C1: Date | D1: Time In | E1: Time Out | F1: Hourly Rate | G1: Total Hours | H1: Regular Hours | I1: Overtime Hours | J1: Regular Pay | K1: Overtime Pay | L1: Total Pay
A2: Cherry | B2: 8:30AM-9:00PM | C2: 2026-02-16 | D2: 08:30 | E2: 21:30 | F2: 33.33 | G2: =(E2-D2)*24 -> 13 | H2: =MIN(G2,9) -> 9 | I2: =IF(MAX(G2-9,0) - 1 < 0, 0, MAX(G2-9,0) - 1) -> 3 | J2: =H2*F2 -> 299.97 | K2: =I2*F2*1.2 -> 119.988 | L2: =J2+K2 -> 419.958
A3: Cherry | B3: 8:30AM-9:00PM | C3: 2026-02-17 | D3: 08:30 | E3: 21:30 | F3: 33.33 | G3: =(E3-D3)*24 -> 13 | H3: =MIN(G3,9) -> 9 | I3: =IF(MAX(G3-9,0) - 1 < 0, 0, MAX(G3-9,0) - 1) -> 3 | J3: =H3*F3 -> 299.97 | K3: =I3*F3*1.2 -> 119.988 | L3: =J3+K3 -> 419.958
A4: Cherry | B4: 8:30AM-9:00PM | C4: 2026-02-18 | D4: 08:30 | E4: 21:30 | F4: 33.33 | G4: =(E4-D4)*24 -> 13 | H4: =MIN(G4,9) -> 9 | I4: =IF(MAX(G4-9,0) - 1 < 0, 0, MAX(G4-9,0) - 1) -> 3 | J4: =H4*F4 -> 299.97 | K4: =I4*F4*1.2 -> 119.988 | L4: =J4+K4 -> 419.958
A5: Cherry | B5: 8:30AM-9:00PM | C5: 2026-02-19 | D5: 0 | E5: 0 | F5: 33.33 | G5: =(E5-D5)*24 -> 0 | H5: =MIN(G5,9) -> 0 | I5: =IF(MAX(G5-9,0) - 1 < 0, 0, MAX(G5-9,0) - 1) -> 0 | J5: =H5*F5 -> 0 | K5: =I5*F5*1.2 -> 0 | L5: =J5+K5 -> 0
A6: Cherry | B6: 8:30AM-9:00PM | C6: 2026-02-20 | D6: 0 | E6: 0 | F6: 33.33 | G6: =(E6-D6)*24 -> 0 | H6: =MIN(G6,9) -> 0 | I6: =IF(MAX(G6-9,0) - 1 < 0, 0, MAX(G6-9,0) - 1) -> 0 | J6: =H6*F6 -> 0 | K6: =I6*F6*1.2 -> 0 | L6: =J6+K6 -> 0
A7: Cherry | B7: 8:30AM-9:00PM | C7: 2026-02-21 | D7: 08:30 | E7: 21:30 | F7: 33.33 | G7: =(E7-D7)*24 -> 13 | H7: =MIN(G7,9) -> 9 | I7: =IF(MAX(G7-9,0) - 1 < 0, 0, MAX(G7-9,0) - 1) -> 3 | J7: =H7*F7 -> 299.97 | K7: =I7*F7*1.2 -> 119.988 | L7: =J7+K7 -> 419.958
A8: Cherry | B8: 8:30AM-9:00PM | C8: 2026-02-22 | D8: 08:30 | E8: 21:30 | F8: 33.33 | G8: =(E8-D8)*24 -> 13 | H8: =MIN(G8,9) -> 9 | I8: =IF(MAX(G8-9,0) - 1 < 0, 0, MAX(G8-9,0) - 1) -> 3 | J8: =H8*F8 -> 299.97 | K8: =I8*F8*1.2 -> 119.988 | L8: =J8+K8 -> 419.958
A14: SUMMARY | B14: REGULAR PAY | C14: OVER TIME PAY | D14: TOTAL PAY
A15: Cherry | B15: =SUM(J2:J13) -> 1499.85 | C15: =SUM(K2:K13) -> 599.94 | D15: =SUM(L2:L13) -> 2099.79
A23: PAYROLL SLIP
A24: Name: | B24: =A2 -> Cherry
A25: Job Title: | B25: Staff
A26: Payment Date: | B26: =C8+1 -> 46076
A27: Cut Off Period: | B27: ='Rhea Mae'!B27 -> Feb-9 to Feb-15, 2026
A28: Days Worked | B28: =COUNTIF(D2:D8, "*:*") -> 5
A29: Adjustments
A30: Basic Pay | B30: =B15 -> 1499.85
A31: Bonus/Incentives | B31: 0
A32: Overtime Pay | B32: =C15 -> 599.94
A33: Other Income | B33: 0
A36: Gross Pay | B36: =D15 -> 2099.79
A37: Deductions | B37: 0
A38: WH Tax | B38: 0
A40: Net Pay | B40: =SUM(B36:B38) -> 2099.79

Sheet Aldrin
A1: Employee | B1: Shift | C1: Date | D1: Time In | E1: Time Out | F1: Hourly Rate | G1: Total Hours | H1: Regular Hours | I1: Overtime Hours | J1: Regular Pay | K1: Overtime Pay | L1: Total Pay
A2: Aldrin | B2: 10:00AM-9:00PM | C2: 2026-02-16 | D2: 10:00 | E2: 21:00 | F2: 27.77 | G2: =(E2-D2)*24 -> 11 | H2: =MIN(G2,8) -> 8 | I2: =IF(MAX(G2-9,0) - 1 < 0, 0, MAX(G2-9,0) - 1) -> 1 | J2: =H2*F2 -> 222.16 | K2: =I2*F2*1.2 -> 33.324 | L2: =J2+K2 -> 255.484
A3: Aldrin | B3: 10:00AM-9:00PM | C3: 2026-02-17 | D3: 0 | E3: 0 | F3: 27.77 | G3: =(E3-D3)*24 -> 0 | H3: =MIN(G3,8) -> 0 | I3: =IF(MAX(G3-9,0) - 1 < 0, 0, MAX(G3-9,0) - 1) -> 0 | J3: =H3*F3 -> 0 | K3: =I3*F3*1.2 -> 0 | L3: =J3+K3 -> 0
A4: Aldrin | B4: 10:00AM-9:00PM | C4: 2026-02-18 | D4: 10:00 | E4: 21:00 | F4: 27.77 | G4: =(E4-D4)*24 -> 11 | H4: =MIN(G4,8) -> 8 | I4: =IF(MAX(G4-9,0) - 1 < 0, 0, MAX(G4-9,0) - 1) -> 1 | J4: =H4*F4 -> 222.16 | K4: =I4*F4*1.2 -> 33.324 | L4: =J4+K4 -> 255.484
A5: Aldrin | B5: 10:00AM-9:00PM | C5: 2026-02-19 | D5: 10:00 | E5: 21:00 | F5: 27.77 | G5: =(E5-D5)*24 -> 11 | H5: =MIN(G5,8) -> 8 | I5: =IF(MAX(G5-9,0) - 1 < 0, 0, MAX(G5-9,0) - 1) -> 1 | J5: =H5*F5 -> 222.16 | K5: =I5*F5*1.2 -> 33.324 | L5: =J5+K5 -> 255.484
A6: Aldrin | B6: 10:00AM-9:00PM | C6: 2026-02-20 | D6: 10:00 | E6: 21:00 | F6: 27.77 | G6: =(E6-D6)*24 -> 11 | H6: =MIN(G6,8) -> 8 | I6: =IF(MAX(G6-9,0) - 1 < 0, 0, MAX(G6-9,0) - 1) -> 1 | J6: =H6*F6 -> 222.16 | K6: =I6*F6*1.2 -> 33.324 | L6: =J6+K6 -> 255.484
A7: Aldrin | B7: 10:00AM-9:00PM | C7: 2026-02-21 | D7: 0 | E7: 0 | F7: 27.77 | G7: =(E7-D7)*24 -> 0 | H7: =MIN(G7,9) -> 0 | I7: =IF(MAX(G7-9,0) - 1 < 0, 0, MAX(G7-9,0) - 1) -> 0 | J7: =H7*F7 -> 0 | K7: =I7*F7*1.2 -> 0 | L7: =J7+K7 -> 0
A8: Aldrin | B8: 10:00AM-9:00PM | C8: 2026-02-22 | D8: 10:00 | E8: 21:00 | F8: 27.77 | G8: =(E8-D8)*24 -> 11 | H8: =MIN(G8,9) -> 9 | I8: =IF(MAX(G8-9,0) - 1 < 0, 0, MAX(G8-9,0) - 1) -> 1 | J8: =H8*F8 -> 249.93 | K8: =I8*F8*1.2 -> 33.324 | L8: =J8+K8 -> 283.254
A14: SUMMARY | B14: REGULAR PAY | C14: OVER TIME PAY | D14: TOTAL PAY
A15: Aldrin | B15: =SUM(J2:J13) -> 1138.57 | C15: =SUM(K2:K13) -> 166.62 | D15: =SUM(L2:L13) -> 1305.19
A23: PAYROLL SLIP
A24: Name: | B24: =A2 -> Aldrin
A25: Job Title: | B25: Staff
A26: Payment Date: | B26: =C8+1 -> 46076
A27: Cut Off Period: | B27: ='Rhea Mae'!B27 -> Feb-9 to Feb-15, 2026
A28: Days Worked | B28: =COUNTIF(D2:D8, "*:*") -> 5
A29: Adjustments
A30: Basic Pay | B30: =B15 -> 1138.57
A31: Bonus/Incentives | B31: 0
A32: Overtime Pay | B32: =C15 -> 166.62
A33: Other Income | B33: 0
A36: Gross Pay | B36: =D15 -> 1305.19
A37: Deductions | B37: 0
A38: WH Tax | B38: 0
A40: Net Pay | B40: =SUM(B36:B38) -> 1305.19

Sheet Mark
A1: Employee | B1: Shift | C1: Date | D1: Time In | E1: Time Out | F1: Hourly Rate | G1: Total Hours | H1: Regular Hours | I1: Overtime Hours | J1: Regular Pay | K1: Overtime Pay | L1: Total Pay
A2: Mark | B2: 9:00AM-9:00PM | C2: 2026-02-16 | D2: 10:00 | E2: 21:30 | F2: 27.77 | G2: =(E2-D2)*24 -> 11.5 | H2: =MIN(G2,9) -> 9 | I2: =IF(MAX(G2-9,0) - 1 < 0, 0, MAX(G2-9,0) - 1) -> 1.5 | J2: =H2*F2 -> 249.93 | K2: =I2*F2*1.2 -> 49.986 | L2: =J2+K2 -> 299.916
A3: Mark | B3: 9:00AM-9:00PM | C3: 2026-02-17 | D3: 08:30 | E3: 21:00 | F3: 27.77 | G3: =(E3-D3)*24 -> 12.5 | H3: =MIN(G3,9) -> 9 | I3: =IF(MAX(G3-9,0) - 1 < 0, 0, MAX(G3-9,0) - 1) -> 2.5 | J3: =H3*F3 -> 249.93 | K3: =I3*F3*1.2 -> 83.31 | L3: =J3+K3 -> 333.24
A4: Mark | B4: 9:00AM-9:00PM | C4: 2026-02-18 | D4: 0 | E4: 0 | F4: 27.77 | G4: =(E4-D4)*24 -> 0 | H4: =MIN(G4,9) -> 0 | I4: =IF(MAX(G4-9,0) - 1 < 0, 0, MAX(G4-9,0) - 1) -> 0 | J4: =H4*F4 -> 0 | K4: =I4*F4*1.2 -> 0 | L4: =J4+K4 -> 0
A5: Mark | B5: 9:00AM-9:00PM | C5: 2026-02-19 | D5: 08:30 | E5: 16:00 | F5: 27.77 | G5: =(E5-D5)*24 -> 7.5 | H5: =MIN(G5,9) -> 7.5 | I5: =IF(MAX(G5-9,0) - 1 < 0, 0, MAX(G5-9,0) - 1) -> 0 | J5: =H5*F5 -> 208.275 | K5: =I5*F5*1.2 -> 0 | L5: =J5+K5 -> 208.275
A6: Mark | B6: 9:00AM-9:00PM | C6: 2026-02-20 | D6: 0 | E6: 0 | F6: 27.77 | G6: =(E6-D6)*24 -> 0 | H6: =MIN(G6,9) -> 0 | I6: =IF(MAX(G6-9,0) - 1 < 0, 0, MAX(G6-9,0) - 1) -> 0 | J6: =H6*F6 -> 0 | K6: =I6*F6*1.2 -> 0 | L6: =J6+K6 -> 0
A7: Mark | B7: 9:00AM-9:00PM | C7: 2026-02-21 | D7: 08:30 | E7: 21:30 | F7: 27.77 | G7: =(E7-D7)*24 -> 13 | H7: =MIN(G7,9) -> 9 | I7: =IF(MAX(G7-9,0) - 1 < 0, 0, MAX(G7-9,0) - 1) -> 3 | J7: =H7*F7 -> 249.93 | K7: =I7*F7*1.2 -> 99.972 | L7: =J7+K7 -> 349.902
A8: Mark | B8: 9:00AM-9:00PM | C8: 2026-02-22 | D8: 09:00 | E8: 21:30 | F8: 27.77 | G8: =(E8-D8)*24 -> 12.5 | H8: =MIN(G8,9) -> 9 | I8: =IF(MAX(G8-9,0) - 1 < 0, 0, MAX(G8-9,0) - 1) -> 2.5 | J8: =H8*F8 -> 249.93 | K8: =I8*F8*1.2 -> 83.31 | L8: =J8+K8 -> 333.24
A14: SUMMARY | B14: REGULAR PAY | C14: OVER TIME PAY | D14: TOTAL PAY
A15: Mark | B15: =SUM(J2:J13) -> 1207.995 | C15: =SUM(K2:K13) -> 316.578 | D15: =SUM(L2:L13) -> 1524.573
A23: PAYROLL SLIP
A24: Name: | B24: =A2 -> Mark
A25: Job Title: | B25: Staff
A26: Payment Date: | B26: =C8+1 -> 46076
A27: Cut Off Period: | B27: ='Rhea Mae'!B27 -> Feb-9 to Feb-15, 2026
A28: Days Worked | B28: =COUNTIF(D2:D8, "*:*") -> 5
A29: Adjustments
A30: Basic Pay | B30: =B15 -> 1207.995
A31: Bonus/Incentives | B31: 0
A32: Overtime Pay | B32: =C15 -> 316.578
A33: Other Income | B33: 0
A36: Gross Pay | B36: =D15 -> 1524.573
A37: Deductions | B37: 0
A38: WH Tax | B38: 0
A40: Net Pay | B40: =SUM(B36:B38) -> 1524.573

Sheet Chadiyah
A1: Employee | B1: Shift | C1: Date | D1: Time In | E1: Time Out | F1: Hourly Rate | G1: Total Hours | H1: Regular Hours | I1: Overtime Hours | J1: Regular Pay | K1: Overtime Pay | L1: Total Pay
A2: Chadiyah | B2: 8:30AM-9:00PM | C2: 2026-02-16 | D2: 08:30 | E2: 19:00 | F2: 34.18 | G2: =(E2-D2)*24 -> 10.5 | H2: =MIN(G2,9) -> 9 | I2: =IF(MAX(G2-9,0) - 1 < 0, 0, MAX(G2-9,0) - 1) -> 0.5 | J2: =H2*F2 -> 307.62 | K2: =I2*F2*1.2 -> 20.508 | L2: =J2+K2 -> 328.128
A3: Chadiyah | B3: 8:30AM-9:00PM | C3: 2026-02-17 | D3: 08:30 | E3: 21:00 | F3: 34.18 | G3: =(E3-D3)*24 -> 12.5 | H3: =MIN(G3,9) -> 9 | I3: =IF(MAX(G3-9,0) - 1 < 0, 0, MAX(G3-9,0) - 1) -> 2.5 | J3: =H3*F3 -> 307.62 | K3: =I3*F3*1.2 -> 102.54 | L3: =J3+K3 -> 410.16
A4: Chadiyah | B4: 8:30AM-9:00PM | C4: 2026-02-18 | D4: 08:30 | E4: 18:00 | F4: 34.18 | G4: =(E4-D4)*24 -> 9.5 | H4: =MIN(G4,9) -> 9 | I4: =IF(MAX(G4-9,0) - 1 < 0, 0, MAX(G4-9,0) - 1) -> 0 | J4: =H4*F4 -> 307.62 | K4: =I4*F4*1.2 -> 0 | L4: =J4+K4 -> 307.62
A5: Chadiyah | B5: 8:30AM-9:00PM | C5: 2026-02-19 | D5: 08:30 | E5: 16:00 | F5: 34.18 | G5: =(E5-D5)*24 -> 7.5 | H5: =MIN(G5,9) -> 7.5 | I5: =IF(MAX(G5-9,0) - 1 < 0, 0, MAX(G5-9,0) - 1) -> 0 | J5: =H5*F5 -> 256.35 | K5: =I5*F5*1.2 -> 0 | L5: =J5+K5 -> 256.35
A6: Chadiyah | B6: 8:30AM-9:00PM | C6: 2026-02-20 | D6: 08:30 | E6: 20:30 | F6: 34.18 | G6: =(E6-D6)*24 -> 12 | H6: =MIN(G6,9) -> 9 | I6: =IF(MAX(G6-9,0) - 1 < 0, 0, MAX(G6-9,0) - 1) -> 2 | J6: =H6*F6 -> 307.62 | K6: =I6*F6*1.2 -> 82.032 | L6: =J6+K6 -> 389.652
A7: Chadiyah | B7: 8:30AM-9:00PM | C7: 2026-02-21 | D7: 0 | E7: 0 | F7: 34.18 | G7: =(E7-D7)*24 -> 0 | H7: =MIN(G7,9) -> 0 | I7: =IF(MAX(G7-9,0) - 1 < 0, 0, MAX(G7-9,0) - 1) -> 0 | J7: =H7*F7 -> 0 | K7: =I7*F7*1.2 -> 0 | L7: =J7+K7 -> 0
A8: Chadiyah | B8: 8:30AM-9:00PM | C8: 2026-02-22 | D8: 0 | E8: 0 | F8: 34.18 | G8: =(E8-D8)*24 -> 0 | H8: =MIN(G8,9) -> 0 | I8: =IF(MAX(G8-9,0) - 1 < 0, 0, MAX(G8-9,0) - 1) -> 0 | J8: =H8*F8 -> 0 | K8: =I8*F8*1.2 -> 0 | L8: =J8+K8 -> 0
A14: SUMMARY | B14: REGULAR PAY | C14: OVER TIME PAY | D14: TOTAL PAY
A15: Chadiyah | B15: =SUM(J2:J13) -> 1486.83 | C15: =SUM(K2:K13) -> 205.08 | D15: =SUM(L2:L13) -> 1691.91
A23: PAYROLL SLIP
A24: Name: | B24: =A2 -> Chadiyah
A25: Job Title: | B25: Staff
A26: Payment Date: | B26: =C8+1 -> 46076
A27: Cut Off Period: | B27: ='Rhea Mae'!B27 -> Feb-9 to Feb-15, 2026
A28: Days Worked | B28: =COUNTIF(D2:D8, "*:*") -> 5
A29: Adjustments
A30: Basic Pay | B30: =B15 -> 1486.83
A31: Bonus/Incentives | B31: 0
A32: Overtime Pay | B32: =C15 -> 205.08
A33: Other Income | B33: 0
A36: Gross Pay | B36: =D15 -> 1691.91
A37: Deductions | B37: 0
A38: WH Tax | B38: 0
A40: Net Pay | B40: =SUM(B36:B38) -> 1691.91
B41: -367
B42: =SUM(B40:B41) -> 1324.91

Sheet Lenard
A1: Employee | B1: Shift | C1: Date | D1: Time In | E1: Time Out | F1: Hourly Rate | G1: Total Hours | H1: Regular Hours | I1: Overtime Hours | J1: Regular Pay | K1: Overtime Pay | L1: Total Pay
A2: Lenard | B2: 5:00PM-10:00PM | C2: 2026-02-16 | D2: 0 | E2: 0 | F2: 22.22 | G2: =(E2-D2)*24 -> 0 | H2: =MIN(G2,9) -> 0 | I2: =IF(MAX(G2-9,0) - 1 < 0, 0, MAX(G2-9,0) - 1) -> 0 | J2: =H2*F2 -> 0 | K2: =I2*F2*1.2 -> 0 | L2: =J2+K2 -> 0
A3: Lenard | B3: 5:00PM-10:00PM | C3: 2026-02-17 | D3: 0 | E3: 0 | F3: 22.22 | G3: =(E3-D3)*24 -> 0 | H3: =MIN(G3,9) -> 0 | I3: =IF(MAX(G3-9,0) - 1 < 0, 0, MAX(G3-9,0) - 1) -> 0 | J3: =H3*F3 -> 0 | K3: =I3*F3*1.2 -> 0 | L3: =J3+K3 -> 0
A4: Lenard | B4: 5:00PM-10:00PM | C4: 2026-02-18 | D4: 17:00 | E4: 21:00 | F4: 22.22 | G4: =(E4-D4)*24 -> 4 | H4: =MIN(G4,9) -> 4 | I4: =IF(MAX(G4-9,0) - 1 < 0, 0, MAX(G4-9,0) - 1) -> 0 | J4: =H4*F4 -> 88.88 | K4: =I4*F4*1.2 -> 0 | L4: 100
A5: Lenard | B5: 5:00PM-10:00PM | C5: 2026-02-19 | D5: 17:00 | E5: 21:00 | F5: 22.22 | G5: =(E5-D5)*24 -> 4 | H5: =MIN(G5,9) -> 4 | I5: =IF(MAX(G5-9,0) - 1 < 0, 0, MAX(G5-9,0) - 1) -> 0 | J5: =H5*F5 -> 88.88 | K5: =I5*F5*1.2 -> 0 | L5: 100
A6: Lenard | B6: 5:00PM-10:00PM | C6: 2026-02-20 | D6: 17:00 | E6: 21:00 | F6: 22.22 | G6: =(E6-D6)*24 -> 4 | H6: =MIN(G6,9) -> 4 | I6: =IF(MAX(G6-9,0) - 1 < 0, 0, MAX(G6-9,0) - 1) -> 0 | J6: =H6*F6 -> 88.88 | K6: =I6*F6*1.2 -> 0 | L6: 100
A7: Lenard | B7: 9:30AM-10:00PM | C7: 2026-02-21 | D7: 08:57 | E7: 21:00 | F7: 22.22 | G7: =(E7-D7)*24 -> 12.05 | H7: =MIN(G7,9) -> 9 | I7: =IF(MAX(G7-9,0) - 1 < 0, 0, MAX(G7-9,0) - 1) -> 2.05 | J7: =H7*F7 -> 199.98 | K7: =I7*F7*1.2 -> 54.6612 | L7: =J7+K7 -> 254.6412
A8: Lenard | B8: 9:30AM-10:00PM | C8: 2026-02-22 | D8: 12:23 | E8: 21:00 | F8: 22.22 | G8: =(E8-D8)*24 -> 8.6166667 | H8: =MIN(G8,9) -> 8.6166667 | I8: =IF(MAX(G8-9,0) - 1 < 0, 0, MAX(G8-9,0) - 1) -> 0 | J8: =H8*F8 -> 191.46233 | K8: =I8*F8*1.2 -> 0 | L8: =J8+K8 -> 191.46233
A14: SUMMARY | B14: REGULAR PAY | C14: OVER TIME PAY | D14: TOTAL PAY
A15: Lenard | B15: =SUM(J2:J13) -> 658.08233 | C15: =SUM(K2:K13) -> 54.6612 | D15: =SUM(L2:L13) -> 746.10353
A23: PAYROLL SLIP
A24: Name: | B24: =A2 -> Lenard
A25: Job Title: | B25: Staff
A26: Payment Date: | B26: =C8+1 -> 46076
A27: Cut Off Period: | B27: ='Rhea Mae'!B27 -> Feb-9 to Feb-15, 2026
A28: Days Worked | B28: =COUNTIF(D2:D8, "*:*") -> 5
A29: Adjustments
A30: Basic Pay | B30: =B15 -> 658.08233
A31: Bonus/Incentives | B31: 0
A32: Overtime Pay | B32: =C15 -> 54.6612
A33: Other Income | B33: 0
A36: Gross Pay | B36: =D15 -> 746.10353
A37: Deductions | B37: 0
A38: WH Tax | B38: 0
A40: Net Pay | B40: =SUM(B36:B38) -> 746.10353

Sheet Rhea Mae
A1: Employee | B1: Shift | C1: Date | D1: Time In | E1: Time Out | F1: Hourly Rate | G1: Total Hours | H1: Regular Hours | I1: Overtime Hours | J1: Regular Pay | K1: Overtime Pay | L1: Total Pay
A2: Rhea Mae | B2: 8:30AM-9:00PM | C2: 2026-02-09 | D2: 08:32 | E2: 21:30 | F2: 38.46 | G2: =(E2-D2)*24 -> 12.966667 | H2: =MIN(G2,9) -> 9 | I2: =IF(MAX(G2-9,0) - 1 < 0, 0, MAX(G2-9,0) - 1) -> 2.9666667 | J2: =H2*F2 -> 346.14 | K2: =I2*F2*1.2 -> 136.9176 | L2: =J2+K2 -> 483.0576
A3: Rhea Mae | B3: 8:30AM-9:00PM | C3: 2026-02-10 | D3: 08:30 | E3: 22:00 | F3: 38.46 | G3: =(E3-D3)*24 -> 13.5 | H3: =MIN(G3,9) -> 9 | I3: =IF(MAX(G3-9,0) - 1 < 0, 0, MAX(G3-9,0) - 1) -> 3.5 | J3: =H3*F3 -> 346.14 | K3: =I3*F3*1.2 -> 161.532 | L3: =J3+K3 -> 507.672
A4: Rhea Mae | B4: 8:30AM-9:00PM | C4: 2026-02-11 | D4: 08:30 | E4: 21:30 | F4: 38.46 | G4: =(E4-D4)*24 -> 13 | H4: =MIN(G4,9) -> 9 | I4: =IF(MAX(G4-9,0) - 1 < 0, 0, MAX(G4-9,0) - 1) -> 3 | J4: =H4*F4 -> 346.14 | K4: =I4*F4*1.2 -> 138.456 | L4: =J4+K4 -> 484.596
A5: Rhea Mae | B5: 8:30AM-9:00PM | C5: 2026-02-12 | D5: 08:30 | E5: 22:00 | F5: 38.46 | G5: =(E5-D5)*24 -> 13.5 | H5: =MIN(G5,9) -> 9 | I5: =IF(MAX(G5-9,0) - 1 < 0, 0, MAX(G5-9,0) - 1) -> 3.5 | J5: =H5*F5 -> 346.14 | K5: =I5*F5*1.2 -> 161.532 | L5: =J5+K5 -> 507.672
A6: Rhea Mae | B6: 8:30AM-9:00PM | C6: 2026-02-13 | D6: 0 | E6: 0 | F6: 38.46 | G6: =(E6-D6)*24 -> 0 | H6: =MIN(G6,9) -> 0 | I6: =IF(MAX(G6-9,0) - 1 < 0, 0, MAX(G6-9,0) - 1) -> 0 | J6: =H6*F6 -> 0 | K6: =I6*F6*1.2 -> 0 | L6: =J6+K6 -> 0
A7: Rhea Mae | B7: 8:30AM-9:00PM | C7: 2026-02-14 | D7: 08:31 | E7: 22:00 | F7: 38.46 | G7: =(E7-D7)*24 -> 13.483333 | H7: =MIN(G7,9) -> 9 | I7: =IF(MAX(G7-9,0) - 1 < 0, 0, MAX(G7-9,0) - 1) -> 3.4833333 | J7: =H7*F7 -> 346.14 | K7: =I7*F7*1.2 -> 160.7628 | L7: =J7+K7 -> 506.9028
A8: Rhea Mae | B8: 8:30AM-9:00PM | C8: 2026-02-15 | D8: 0 | E8: 0 | F8: 38.46 | G8: =(E8-D8)*24 -> 0 | H8: =MIN(G8,9) -> 0 | I8: =IF(MAX(G8-9,0) - 1 < 0, 0, MAX(G8-9,0) - 1) -> 0 | J8: =H8*F8 -> 0 | K8: =I8*F8*1.2 -> 0 | L8: =J8+K8 -> 0
A14: SUMMARY | B14: REGULAR PAY | C14: OVER TIME PAY | D14: TOTAL PAY
A15: Rhea Mae | B15: =SUM(J2:J13) -> 1730.7 | C15: =SUM(K2:K13) -> 759.2004 | D15: =SUM(L2:L13) -> 2489.9004
A23: PAYROLL SLIP
A24: Name: | B24: =A2 -> Rhea Mae
A25: Job Title: | B25: Store Manager
A26: Payment Date: | B26: =C8+1 -> 46069
A27: Cut Off Period: | B27: Feb-9 to Feb-15, 2026
A28: Days Worked | B28: =COUNTIF(D2:D8, "*:*") -> 5
A29: Adjustments
A30: Basic Pay | B30: =B15 -> 1730.7
A31: Bonus/Incentives | B31: 0
A32: Overtime Pay | B32: =C15 -> 759.2004
A33: Other Income | B33: 0
A36: Gross Pay | B36: =D15 -> 2489.9004
A37: Deductions | B37: 0
A38: WH Tax | B38: 0
A40: Net Pay | B40: =SUM(B36:B38) -> 2489.9004

Sheet David
A1: Employee | B1: Shift | C1: Date | D1: Time In | E1: Time Out | F1: Hourly Rate | G1: Total Hours | H1: Regular Hours | I1: Overtime Hours | J1: Regular Pay | K1: Overtime Pay | L1: Total Pay
A2: David | B2: 5:00PM-10:00PM | C2: 2026-02-09 | D2: 09:00 | E2: 0 | L2: 420
A3: David | B3: 5:00PM-10:00PM | C3: 2026-02-10 | D3: 09:01 | E3: 0 | L3: 520
A4: David | B4: 5:00PM-10:00PM | C4: 2026-02-11 | D4: 09:02 | E4: 0 | L4: 400
A5: David | B5: 5:00PM-10:00PM | C5: 2026-02-12 | D5: 09:03 | E5: 0 | L5: 400
A6: David | B6: 5:00PM-10:00PM | C6: 2026-02-13 | D6: 09:04 | E6: 0 | L6: 400
A7: David | B7: 9:30AM-10:00PM | C7: 2026-02-14 | D7: 09:05 | E7: 0 | L7: 430
A8: David | B8: 9:30AM-10:00PM | C8: 2026-02-15 | D8: 0 | E8: 0 | L8: 0
A14: SUMMARY | B14: REGULAR PAY | C14: OVER TIME PAY | D14: TOTAL PAY
A15: Lenard | B15: =SUM(J2:J13) -> 0 | C15: =SUM(K2:K13) -> 0 | D15: =SUM(L2:L13) -> 2570
A23: PAYROLL SLIP
A24: Name: | B24: =A2 -> David
A25: Job Title: | B25: Staff
A26: Payment Date: | B26: =C8+1 -> 46069
A27: Cut Off Period: | B27: ='Rhea Mae'!B27 -> Feb-9 to Feb-15, 2026
A28: Days Worked | B28: =COUNTIF(D2:D8, "*:*") -> 6
A29: Adjustments
A30: Basic Pay | B30: =B15 -> 0
A31: Bonus/Incentives | B31: 0
A32: Overtime Pay | B32: =C15 -> 0
A33: Other Income | B33: 0
A36: Gross Pay | B36: =D15 -> 2570
A37: Deductions | B37: 0
A38: WH Tax | B38: 0
A40: Net Pay | B40: =SUM(B36:B38) -> 2570

Sheet Template
A1: Employee | B1: Shift | C1: Date | D1: Time In | E1: Time Out | F1: Hourly Rate | G1: Total Hours | H1: Regular Hours | I1: Overtime Hours | J1: Regular Pay | K1: Overtime Pay | L1: Total Pay
A2: Name | B2: 8:30AM-9:00PM | C2: 2026-01-12 | D2: 08:30 | E2: 22:00 | F2: 38.46 | G2: =(E2-D2)*24 -> 13.5 | H2: =MIN(G2,10) -> 10 | I2: =MAX(G2-10,0) - 1 -> 2.5 | J2: =H2*F2 -> 384.6 | K2: =I2*F2*1.2 -> 115.38 | L2: =J2+K2 -> 499.98
A3: Name | B3: 8:30AM-9:00PM | C3: 2026-01-13 | D3: 08:30 | E3: 22:00 | F3: 38.46 | G3: =(E3-D3)*24 -> 13.5 | H3: =MIN(G3,10) -> 10 | I3: =MAX(G3-10,0) - 1 -> 2.5 | J3: =H3*F3 -> 384.6 | K3: =I3*F3*1.2 -> 115.38 | L3: =J3+K3 -> 499.98
A4: Name | B4: 8:30AM-9:00PM | C4: 2026-01-14 | D4: 08:30 | E4: 22:00 | F4: 38.46 | G4: =(E4-D4)*24 -> 13.5 | H4: =MIN(G4,10) -> 10 | I4: =MAX(G4-10,0) - 1 -> 2.5 | J4: =H4*F4 -> 384.6 | K4: =I4*F4*1.2 -> 115.38 | L4: =J4+K4 -> 499.98
A5: Name | B5: 8:30AM-9:00PM | C5: 2026-01-15 | D5: 08:30 | E5: 22:00 | F5: 38.46 | G5: =(E5-D5)*24 -> 13.5 | H5: =MIN(G5,10) -> 10 | I5: =MAX(G5-10,0) - 1 -> 2.5 | J5: =H5*F5 -> 384.6 | K5: =I5*F5*1.2 -> 115.38 | L5: =J5+K5 -> 499.98
A6: Name | B6: 8:30AM-9:00PM | C6: 2026-01-16 | D6: 08:30 | E6: 22:00 | F6: 38.46 | G6: =(E6-D6)*24 -> 13.5 | H6: =MIN(G6,10) -> 10 | I6: =MAX(G6-10,0) - 1 -> 2.5 | J6: =H6*F6 -> 384.6 | K6: =I6*F6*1.2 -> 115.38 | L6: =J6+K6 -> 499.98
A7: Name | B7: 8:30AM-9:00PM | C7: 2026-01-17 | D7: 08:30 | E7: 22:00 | F7: 38.46 | G7: =(E7-D7)*24 -> 13.5 | H7: =MIN(G7,10) -> 10 | I7: =MAX(G7-10,0) - 1 -> 2.5 | J7: =H7*F7 -> 384.6 | K7: =I7*F7*1.2 -> 115.38 | L7: =J7+K7 -> 499.98
A8: Name | B8: 8:30AM-9:00PM | C8: 2026-01-18 | D8: 08:30 | E8: 22:00 | F8: 38.46 | G8: =(E8-D8)*24 -> 13.5 | H8: =MIN(G8,10) -> 10 | I8: =MAX(G8-10,0) - 1 -> 2.5 | J8: =H8*F8 -> 384.6 | K8: =I8*F8*1.2 -> 115.38 | L8: =J8+K8 -> 499.98
A14: SUMMARY | B14: REGULAR PAY | C14: OVER TIME PAY | D14: TOTAL PAY
A15: Rhea Mae | B15: =SUM(J2:J13) -> 2692.2 | C15: =SUM(K2:K13) -> 807.66 | D15: =SUM(L2:L13) -> 3499.86
A23: PAYROLL SLIP
A24: Name: | B24: =A2 -> Name
A25: Job Title: | B25: Store Manager
A26: Payment Date: | B26: 46041
A27: Cut Off Period: | B27: Jan-12 to Jan-28, 2026
A29: Adjustments
A30: Basic Pay | B30: =B15 -> 2692.2
A31: Bonus/Incentives | B31: 0
A32: Overtime Pay | B32: =C15 -> 807.66
A33: Other Income | B33: 0
A36: Gross Pay | B36: =D15 -> 3499.86
A37: Deductions | B37: 0
A38: WH Tax | B38: 0
A40: Net Pay | B40: =SUM(B36:B38) -> 3499.86

Sheet Rhoda
A1: Employee | B1: Date | C1: Shift | D1: Time In | E1: Time Out | F1: Hourly Rate | G1: Total Hours | H1: Regular Hours | I1: Overtime Hours | J1: Regular Pay | K1: Overtime Pay | L1: Total Pay
A2: Rhoda | B2: 46021 | C2: 9:00AM-7:00PM | D2: 0.45833333 | E2: 0.99930556 | F2: 29.91 | G2: 15 | H2: =MIN(G2,9) -> 9 | I2: =MAX(G2-9,0) - 1 -> 5 | J2: =H2*F2 -> 269.19 | K2: =I2*F2*1.2 -> 179.46 | L2: =J2+K2 -> 448.65
A3: Rhoda | B3: 46022 | C3: 9:00AM-7:00PM | D3: 0.41666667 | E3: 0.8125 | F3: 29.91 | G3: =(E3-D3)*24 -> 9.5 | H3: =MIN(G3,9) -> 9 | I3: =MAX(G3-9,0) - 1 -> -0.5 | J3: =H3*F3 -> 269.19 | L3: 538 | M3: doublepay
A4: Rhoda | B4: 46027 | C4: 9:00AM-7:00PM | D4: 0.375 | E4: 0.91666667 | F4: 29.91 | G4: =(E4-D4)*24 -> 13 | H4: =MIN(G4,9) -> 9 | I4: =MAX(G4-9,0) - 1 -> 3 | J4: =H4*F4 -> 269.19 | K4: =I4*F4*1.2 -> 107.676 | L4: =J4+K4 -> 376.866
A5: Rhoda | B5: 46028 | C5: 9:00AM-7:00PM | D5: 0.375 | E5: 0.875 | F5: 29.91 | G5: =(E5-D5)*24 -> 12 | H5: =MIN(G5,9) -> 9 | I5: =MAX(G5-9,0) - 1 -> 2 | J5: =H5*F5 -> 269.19 | K5: =I5*F5*1.2 -> 71.784 | L5: =J5+K5 -> 340.974
A6: Rhoda | B6: 46029 | C6: 9:00AM-7:00PM | D6: 0.375 | E6: 0.9375 | F6: 29.91 | G6: =(E6-D6)*24 -> 13.5 | H6: =MIN(G6,9) -> 9 | I6: =MAX(G6-9,0) - 1 -> 3.5 | J6: =H6*F6 -> 269.19 | K6: =I6*F6*1.2 -> 125.622 | L6: =J6+K6 -> 394.812
A7: Rhoda | B7: 46030 | C7: 9:00AM-7:00PM | D7: 0.375 | E7: 0.99930556 | F7: 29.91 | G7: 15 | H7: =MIN(G7,9) -> 9 | I7: =MAX(G7-9,0) - 1 -> 5 | J7: =H7*F7 -> 269.19 | K7: =I7*F7*1.2 -> 179.46 | L7: =J7+K7 -> 448.65
A8: Rhoda | B8: 46031 | C8: 9:00AM-7:00PM | D8: 0.51041667 | E8: 0.91805556 | F8: 29.91 | G8: =(E8-D8)*24 -> 9.7833333 | H8: =MIN(G8,9) -> 9 | I8: =MAX(G8-9,0) - 1 -> -0.21666667 | J8: =H8*F8 -> 269.19 | L8: =J8+K8 -> 269.19
A9: Rhoda | B9: 46032 | C9: 9:00AM-7:00PM | D9: 0.43402778 | E9: 0.90625 | F9: 29.91 | G9: =(E9-D9)*24 -> 11.333333 | H9: =MIN(G9,9) -> 9 | I9: =MAX(G9-9,0) - 1 -> 1.3333333 | J9: =H9*F9 -> 269.19 | K9: =I9*F9*1.2 -> 47.856 | L9: =J9+K9 -> 317.046
J10: =SUM(J2:J9) -> 2153.52 | K10: =SUM(K2:K9) -> 711.858 | L10: =SUM(L2:L9) -> 3134.188

Sheet Kenneth
A1: Employee | B1: Date | C1: Shift | D1: Time In | E1: Time Out | F1: Hourly Rate | G1: Total Hours | H1: Regular Hours | I1: Overtime Hours | J1: Regular Pay | K1: Overtime Pay | L1: Total Pay
A2: Kenneth | B2: 46027
A3: Kenneth | B3: 46028
A4: Kenneth | B4: 46029
A5: Kenneth | B5: 46030
A6: Kenneth | B6: 46031 | D6: 0.70833333 | E6: 0.9375 | F6: 22.22 | G6: =(E6-D6)*24 -> 5.5 | H6: =MIN(G6,9) -> 5.5 | I6: =MAX(G6-9,0) - 1 -> -1 | J6: =H6*F6 -> 122.21 | L6: =J6+K6 -> 122.21
A7: Kenneth | B7: 46032 | D7: 0.70833333 | E7: 0.91666667 | F7: 22.22 | G7: =(E7-D7)*24 -> 5 | H7: =MIN(G7,9) -> 5 | I7: =MAX(G7-9,0) - 1 -> -1 | J7: =H7*F7 -> 111.1 | L7: =J7+K7 -> 111.1
A8: Kenneth | B8: 46033 | D8: 0.72986111 | E8: 0.91666667 | F8: 22.22 | G8: =(E8-D8)*24 -> 4.4833333 | H8: =MIN(G8,9) -> 4.4833333 | I8: =MAX(G8-9,0) - 1 -> -1 | J8: =H8*F8 -> 99.619667 | L8: =J8+K8 -> 99.619667
L9: =SUM(L6:L8) -> 332.92967
